<?xml version="1.0" ?>
<robot name="humanoidrightleg" xmlns:xacro="http://www.ros.org/wiki/xacro">

<xacro:include filename="$(find humanoidrightleg_description)/urdf/materials.xacro" />
<xacro:include filename="$(find humanoidrightleg_description)/urdf/humanoidrightleg.trans" />
<link name="base_link">
  <inertial>
    <origin xyz="0.05188138159181946 -0.14811953716387727 -0.36480937032331195" rpy="0 0 0"/>
    <mass value="0.010267975341980594"/>
    <inertia ixx="1e-06" iyy="3e-06" izz="2e-06" ixy="0.0" iyz="0.0" ixz="-0.0"/>
  </inertial>
  <visual>
    <origin xyz="0 0 0" rpy="0 0 0"/>
    <geometry>
      <mesh filename="package://humanoidrightleg_description/meshes/base_link.stl" scale="0.001 0.001 0.001"/>
    </geometry>
    <material name="opaque2550255"/>
  </visual>
  <collision>
    <origin xyz="0 0 0" rpy="0 0 0"/>
    <geometry>
      <mesh filename="package://humanoidrightleg_description/meshes/base_link.stl" scale="0.001 0.001 0.001"/>
    </geometry>
  </collision>
</link>

<link name="RMD-X10-S2_MIR4__3_Rotor_1">
  <inertial>
    <origin xyz="2.696980783381542e-06 -0.010998754176837128 -0.0019232081983001637" rpy="0 0 0"/>
    <mass value="0.23611227463741877"/>
    <inertia ixx="5.7e-05" iyy="7.4e-05" izz="5.8e-05" ixy="-0.0" iyz="3e-06" ixz="0.0"/>
  </inertial>
  <visual>
    <origin xyz="-0.051881 0.150582 0.365243" rpy="0 0 0"/>
    <geometry>
      <mesh filename="package://humanoidrightleg_description/meshes/RMD-X10-S2_MIR4__3_Rotor_1.stl" scale="0.001 0.001 0.001"/>
    </geometry>
    <material name="opaque727161"/>
  </visual>
  <collision>
    <origin xyz="-0.051881 0.150582 0.365243" rpy="0 0 0"/>
    <geometry>
      <mesh filename="package://humanoidrightleg_description/meshes/RMD-X10-S2_MIR4__3_Rotor_1.stl" scale="0.001 0.001 0.001"/>
    </geometry>
  </collision>
</link>

<link name="RMD-X10-S2_MIR4__3_Stator_1">
  <inertial>
    <origin xyz="3.700318167501604e-07 -0.031475688771329474 -0.004738563365506709" rpy="0 0 0"/>
    <mass value="1.553069048444254"/>
    <inertia ixx="0.002856" iyy="0.00368" izz="0.002945" ixy="-0.0" iyz="0.000116" ixz="-0.0"/>
  </inertial>
  <visual>
    <origin xyz="-0.051881 0.150582 0.365243" rpy="0 0 0"/>
    <geometry>
      <mesh filename="package://humanoidrightleg_description/meshes/RMD-X10-S2_MIR4__3_Stator_1.stl" scale="0.001 0.001 0.001"/>
    </geometry>
    <material name="opaque727161"/>
  </visual>
  <collision>
    <origin xyz="-0.051881 0.150582 0.365243" rpy="0 0 0"/>
    <geometry>
      <mesh filename="package://humanoidrightleg_description/meshes/RMD-X10-S2_MIR4__3_Stator_1.stl" scale="0.001 0.001 0.001"/>
    </geometry>
  </collision>
</link>

<link name="leg-pitch-elastic__1__1">
  <inertial>
    <origin xyz="0.004333556518131467 -0.028078860808509853 -0.003821660219459122" rpy="0 0 0"/>
    <mass value="0.024529104276010374"/>
    <inertia ixx="1e-05" iyy="3e-06" izz="8e-06" ixy="-0.0" iyz="-1e-06" ixz="0.0"/>
  </inertial>
  <visual>
    <origin xyz="0.019257 0.150579 0.376773" rpy="0 0 0"/>
    <geometry>
      <mesh filename="package://humanoidrightleg_description/meshes/leg-pitch-elastic__1__1.stl" scale="0.001 0.001 0.001"/>
    </geometry>
    <material name="opaque191191191"/>
  </visual>
  <collision>
    <origin xyz="0.019257 0.150579 0.376773" rpy="0 0 0"/>
    <geometry>
      <mesh filename="package://humanoidrightleg_description/meshes/leg-pitch-elastic__1__1.stl" scale="0.001 0.001 0.001"/>
    </geometry>
  </collision>
</link>

<link name="leg-pitch-elastic__3__1">
  <inertial>
    <origin xyz="0.00028100000359344846 -0.029442836370255993 -0.009725738836664666" rpy="0 0 0"/>
    <mass value="0.024529104276010374"/>
    <inertia ixx="8e-06" iyy="3e-06" izz="1e-05" ixy="0.0" iyz="-1e-06" ixz="-0.0"/>
  </inertial>
  <visual>
    <origin xyz="0.031012 0.14777 0.392707" rpy="0 0 0"/>
    <geometry>
      <mesh filename="package://humanoidrightleg_description/meshes/leg-pitch-elastic__3__1.stl" scale="0.001 0.001 0.001"/>
    </geometry>
    <material name="opaque191191191"/>
  </visual>
  <collision>
    <origin xyz="0.031012 0.14777 0.392707" rpy="0 0 0"/>
    <geometry>
      <mesh filename="package://humanoidrightleg_description/meshes/leg-pitch-elastic__3__1.stl" scale="0.001 0.001 0.001"/>
    </geometry>
  </collision>
</link>

<link name="leg-pitch-elastic__2__1">
  <inertial>
    <origin xyz="-0.0002810375968801404 -0.030994150752103905 -0.000931059155583891" rpy="0 0 0"/>
    <mass value="0.024529104276010374"/>
    <inertia ixx="8e-06" iyy="3e-06" izz="1e-05" ixy="-0.0" iyz="-1e-06" ixz="-0.0"/>
  </inertial>
  <visual>
    <origin xyz="-0.063065 0.140193 0.435675" rpy="0 0 0"/>
    <geometry>
      <mesh filename="package://humanoidrightleg_description/meshes/leg-pitch-elastic__2__1.stl" scale="0.001 0.001 0.001"/>
    </geometry>
    <material name="opaque191191191"/>
  </visual>
  <collision>
    <origin xyz="-0.063065 0.140193 0.435675" rpy="0 0 0"/>
    <geometry>
      <mesh filename="package://humanoidrightleg_description/meshes/leg-pitch-elastic__2__1.stl" scale="0.001 0.001 0.001"/>
    </geometry>
  </collision>
</link>

<link name="leg-pitch-elastic_1">
  <inertial>
    <origin xyz="-0.004333594111423367 -0.02769196677363589 -0.006012367949384867" rpy="0 0 0"/>
    <mass value="0.024529104276010374"/>
    <inertia ixx="1e-05" iyy="3e-06" izz="8e-06" ixy="0.0" iyz="-1e-06" ixz="0.0"/>
  </inertial>
  <visual>
    <origin xyz="-0.05131 0.137384 0.451609" rpy="0 0 0"/>
    <geometry>
      <mesh filename="package://humanoidrightleg_description/meshes/leg-pitch-elastic_1.stl" scale="0.001 0.001 0.001"/>
    </geometry>
    <material name="opaque191191191"/>
  </visual>
  <collision>
    <origin xyz="-0.05131 0.137384 0.451609" rpy="0 0 0"/>
    <geometry>
      <mesh filename="package://humanoidrightleg_description/meshes/leg-pitch-elastic_1.stl" scale="0.001 0.001 0.001"/>
    </geometry>
  </collision>
</link>

<link name="hip-motor-bracket-v5-right_MIR_1">
  <inertial>
    <origin xyz="0.017145481203306456 0.013001009926072976 -0.047818668498474826" rpy="0 0 0"/>
    <mass value="0.06299639046400377"/>
    <inertia ixx="4.2e-05" iyy="0.000103" izz="6.4e-05" ixy="-6e-06" iyz="7e-06" ixz="3.2e-05"/>
  </inertial>
  <visual>
    <origin xyz="0.001119 0.152551 0.365591" rpy="0 0 0"/>
    <geometry>
      <mesh filename="package://humanoidrightleg_description/meshes/hip-motor-bracket-v5-right_MIR_1.stl" scale="0.001 0.001 0.001"/>
    </geometry>
    <material name="opaque245245245"/>
  </visual>
  <collision>
    <origin xyz="0.001119 0.152551 0.365591" rpy="0 0 0"/>
    <geometry>
      <mesh filename="package://humanoidrightleg_description/meshes/hip-motor-bracket-v5-right_MIR_1.stl" scale="0.001 0.001 0.001"/>
    </geometry>
  </collision>
</link>

<link name="innner-thigh-magnet-encoder__1__1">
  <inertial>
    <origin xyz="0.0183850319620484 0.027805202197414627 0.0022944532272266005" rpy="0 0 0"/>
    <mass value="0.027890405556868676"/>
    <inertia ixx="1.8e-05" iyy="1.3e-05" izz="1.4e-05" ixy="-4e-06" iyz="-7e-06" ixz="-3e-06"/>
  </inertial>
  <visual>
    <origin xyz="-0.009003 0.138278 0.394707" rpy="0 0 0"/>
    <geometry>
      <mesh filename="package://humanoidrightleg_description/meshes/innner-thigh-magnet-encoder__1__1.stl" scale="0.001 0.001 0.001"/>
    </geometry>
    <material name="opaque191191191"/>
  </visual>
  <collision>
    <origin xyz="-0.009003 0.138278 0.394707" rpy="0 0 0"/>
    <geometry>
      <mesh filename="package://humanoidrightleg_description/meshes/innner-thigh-magnet-encoder__1__1.stl" scale="0.001 0.001 0.001"/>
    </geometry>
  </collision>
</link>

<link name="knee-bend-motor-bracket-hip_1">
  <inertial>
    <origin xyz="-0.0038107628515755 0.011125365002244786 -0.014267217734475313" rpy="0 0 0"/>
    <mass value="0.010727755883908778"/>
    <inertia ixx="2e-06" iyy="2e-06" izz="1e-06" ixy="0.0" iyz="0.0" ixz="-0.0"/>
  </inertial>
  <visual>
    <origin xyz="-0.104881 0.152551 0.365591" rpy="0 0 0"/>
    <geometry>
      <mesh filename="package://humanoidrightleg_description/meshes/knee-bend-motor-bracket-hip_1.stl" scale="0.001 0.001 0.001"/>
    </geometry>
    <material name="opaque191191191"/>
  </visual>
  <collision>
    <origin xyz="-0.104881 0.152551 0.365591" rpy="0 0 0"/>
    <geometry>
      <mesh filename="package://humanoidrightleg_description/meshes/knee-bend-motor-bracket-hip_1.stl" scale="0.001 0.001 0.001"/>
    </geometry>
  </collision>
</link>

<link name="knee-bend-motor-bracket-hip__1__1">
  <inertial>
    <origin xyz="-0.0038106585244156443 -0.005574715341050335 -0.01721186932976221" rpy="0 0 0"/>
    <mass value="0.010727755883908778"/>
    <inertia ixx="2e-06" iyy="2e-06" izz="1e-06" ixy="0.0" iyz="0.0" ixz="-0.0"/>
  </inertial>
  <visual>
    <origin xyz="-0.104881 0.210655 0.375836" rpy="0 0 0"/>
    <geometry>
      <mesh filename="package://humanoidrightleg_description/meshes/knee-bend-motor-bracket-hip__1__1.stl" scale="0.001 0.001 0.001"/>
    </geometry>
    <material name="opaque191191191"/>
  </visual>
  <collision>
    <origin xyz="-0.104881 0.210655 0.375836" rpy="0 0 0"/>
    <geometry>
      <mesh filename="package://humanoidrightleg_description/meshes/knee-bend-motor-bracket-hip__1__1.stl" scale="0.001 0.001 0.001"/>
    </geometry>
  </collision>
</link>

<link name="RMD-X10-S2_MIR4Stator_1">
  <inertial>
    <origin xyz="0.01637759237491974 -0.02012194536169687 -0.05391978287294025" rpy="0 0 0"/>
    <mass value="1.553069048444256"/>
    <inertia ixx="0.002856" iyy="0.003669" izz="0.002957" ixy="-0.0" iyz="0.000147" ixz="-0.0"/>
  </inertial>
  <visual>
    <origin xyz="0.036206 0.144165 0.413151" rpy="0 0 0"/>
    <geometry>
      <mesh filename="package://humanoidrightleg_description/meshes/RMD-X10-S2_MIR4Stator_1.stl" scale="0.001 0.001 0.001"/>
    </geometry>
    <material name="opaque727161"/>
  </visual>
  <collision>
    <origin xyz="0.036206 0.144165 0.413151" rpy="0 0 0"/>
    <geometry>
      <mesh filename="package://humanoidrightleg_description/meshes/RMD-X10-S2_MIR4Stator_1.stl" scale="0.001 0.001 0.001"/>
    </geometry>
  </collision>
</link>

<link name="RMD-X10-S2_MIR4Rotor_1">
  <inertial>
    <origin xyz="-2.7345740462904333e-06 0.010993122126026239 0.00195526149637959" rpy="0 0 0"/>
    <mass value="0.23611227463741877"/>
    <inertia ixx="5.7e-05" iyy="7.4e-05" izz="5.8e-05" ixy="0.0" iyz="3e-06" ixz="-0.0"/>
  </inertial>
  <visual>
    <origin xyz="0.019828 0.195485 0.473384" rpy="0 0 0"/>
    <geometry>
      <mesh filename="package://humanoidrightleg_description/meshes/RMD-X10-S2_MIR4Rotor_1.stl" scale="0.001 0.001 0.001"/>
    </geometry>
    <material name="opaque727161"/>
  </visual>
  <collision>
    <origin xyz="0.019828 0.195485 0.473384" rpy="0 0 0"/>
    <geometry>
      <mesh filename="package://humanoidrightleg_description/meshes/RMD-X10-S2_MIR4Rotor_1.stl" scale="0.001 0.001 0.001"/>
    </geometry>
  </collision>
</link>

<link name="thigh-outer-encoder-mount__1__1">
  <inertial>
    <origin xyz="0.012347236227326808 -0.03396158860338411 0.0074245890264908465" rpy="0 0 0"/>
    <mass value="0.029809543133691427"/>
    <inertia ixx="1.9e-05" iyy="1.3e-05" izz="2.3e-05" ixy="8e-06" iyz="-5e-06" ixz="3e-06"/>
  </inertial>
  <visual>
    <origin xyz="0.072828 0.193516 0.473037" rpy="0 0 0"/>
    <geometry>
      <mesh filename="package://humanoidrightleg_description/meshes/thigh-outer-encoder-mount__1__1.stl" scale="0.001 0.001 0.001"/>
    </geometry>
    <material name="opaque191191191"/>
  </visual>
  <collision>
    <origin xyz="0.072828 0.193516 0.473037" rpy="0 0 0"/>
    <geometry>
      <mesh filename="package://humanoidrightleg_description/meshes/thigh-outer-encoder-mount__1__1.stl" scale="0.001 0.001 0.001"/>
    </geometry>
  </collision>
</link>

<link name="limit-bracket-knee_1">
  <inertial>
    <origin xyz="0.03808685877334085 -0.0033767465363864213 0.007602782393038021" rpy="0 0 0"/>
    <mass value="0.01114960941353449"/>
    <inertia ixx="2e-06" iyy="1e-05" izz="7e-06" ixy="1e-06" iyz="0.0" ixz="-3e-06"/>
  </inertial>
  <visual>
    <origin xyz="0.036206 0.184763 0.522677" rpy="0 0 0"/>
    <geometry>
      <mesh filename="package://humanoidrightleg_description/meshes/limit-bracket-knee_1.stl" scale="0.001 0.001 0.001"/>
    </geometry>
    <material name="opaque191191191"/>
  </visual>
  <collision>
    <origin xyz="0.036206 0.184763 0.522677" rpy="0 0 0"/>
    <geometry>
      <mesh filename="package://humanoidrightleg_description/meshes/limit-bracket-knee_1.stl" scale="0.001 0.001 0.001"/>
    </geometry>
  </collision>
</link>

<link name="hip-motor-bracket-v5-right_MIR__1__1">
  <inertial>
    <origin xyz="0.02831948061075123 0.003830082849485883 -0.04763874492407999" rpy="0 0 0"/>
    <mass value="0.06299639046400377"/>
    <inertia ixx="4.2e-05" iyy="0.000103" izz="6.4e-05" ixy="-6e-06" iyz="7e-06" ixz="3.2e-05"/>
  </inertial>
  <visual>
    <origin xyz="0.012293 0.210347 0.377579" rpy="0 0 0"/>
    <geometry>
      <mesh filename="package://humanoidrightleg_description/meshes/hip-motor-bracket-v5-right_MIR__1__1.stl" scale="0.001 0.001 0.001"/>
    </geometry>
    <material name="opaque245245245"/>
  </visual>
  <collision>
    <origin xyz="0.012293 0.210347 0.377579" rpy="0 0 0"/>
    <geometry>
      <mesh filename="package://humanoidrightleg_description/meshes/hip-motor-bracket-v5-right_MIR__1__1.stl" scale="0.001 0.001 0.001"/>
    </geometry>
  </collision>
</link>

<link name="NO-NC_Bump_Switch__1__1">
  <inertial>
    <origin xyz="0.0006092413015359871 -0.0023076459167730434 -0.006099102234956022" rpy="0 0 0"/>
    <mass value="0.0015503940654034828"/>
    <inertia ixx="0.0" iyy="0.0" izz="0.0" ixy="0.0" iyz="0.0" ixz="-0.0"/>
  </inertial>
  <visual>
    <origin xyz="-0.040559 0.186668 0.499258" rpy="0 0 0"/>
    <geometry>
      <mesh filename="package://humanoidrightleg_description/meshes/NO-NC_Bump_Switch__1__1.stl" scale="0.001 0.001 0.001"/>
    </geometry>
    <material name="opaque252525"/>
  </visual>
  <collision>
    <origin xyz="-0.040559 0.186668 0.499258" rpy="0 0 0"/>
    <geometry>
      <mesh filename="package://humanoidrightleg_description/meshes/NO-NC_Bump_Switch__1__1.stl" scale="0.001 0.001 0.001"/>
    </geometry>
  </collision>
</link>

<link name="NO-NC_Bump_Switch_1">
  <inertial>
    <origin xyz="0.004176899208126087 -0.002622450146255173 -0.004308927980424149" rpy="0 0 0"/>
    <mass value="0.0015503940654034828"/>
    <inertia ixx="0.0" iyy="0.0" izz="0.0" ixy="-0.0" iyz="-0.0" ixz="0.0"/>
  </inertial>
  <visual>
    <origin xyz="0.033965 0.180131 0.536336" rpy="0 0 0"/>
    <geometry>
      <mesh filename="package://humanoidrightleg_description/meshes/NO-NC_Bump_Switch_1.stl" scale="0.001 0.001 0.001"/>
    </geometry>
    <material name="opaque252525"/>
  </visual>
  <collision>
    <origin xyz="0.033965 0.180131 0.536336" rpy="0 0 0"/>
    <geometry>
      <mesh filename="package://humanoidrightleg_description/meshes/NO-NC_Bump_Switch_1.stl" scale="0.001 0.001 0.001"/>
    </geometry>
  </collision>
</link>

<link name="hip-ex-al-base_MIR_1">
  <inertial>
    <origin xyz="-1.0567741006946296e-05 -0.013195056380295833 -0.002175347416830564" rpy="0 0 0"/>
    <mass value="0.14559026866705457"/>
    <inertia ixx="7.3e-05" iyy="0.000136" izz="8.3e-05" ixy="-0.0" iyz="1.2e-05" ixz="-1e-06"/>
  </inertial>
  <visual>
    <origin xyz="0.019828 0.195485 0.473384" rpy="0 0 0"/>
    <geometry>
      <mesh filename="package://humanoidrightleg_description/meshes/hip-ex-al-base_MIR_1.stl" scale="0.001 0.001 0.001"/>
    </geometry>
    <material name="opaque22122113"/>
  </visual>
  <collision>
    <origin xyz="0.019828 0.195485 0.473384" rpy="0 0 0"/>
    <geometry>
      <mesh filename="package://humanoidrightleg_description/meshes/hip-ex-al-base_MIR_1.stl" scale="0.001 0.001 0.001"/>
    </geometry>
  </collision>
</link>

<link name="motorcap-KNEE_MIR_1">
  <inertial>
    <origin xyz="-0.00010520137576633046 -0.010540497792595221 -0.0002982130697479213" rpy="0 0 0"/>
    <mass value="0.10890019522501011"/>
    <inertia ixx="5.3e-05" iyy="0.000102" izz="5.9e-05" ixy="0.0" iyz="7e-06" ixz="-0.0"/>
  </inertial>
  <visual>
    <origin xyz="0.019828 0.222075 0.478072" rpy="0 0 0"/>
    <geometry>
      <mesh filename="package://humanoidrightleg_description/meshes/motorcap-KNEE_MIR_1.stl" scale="0.001 0.001 0.001"/>
    </geometry>
    <material name="opaque22122113"/>
  </visual>
  <collision>
    <origin xyz="0.019828 0.222075 0.478072" rpy="0 0 0"/>
    <geometry>
      <mesh filename="package://humanoidrightleg_description/meshes/motorcap-KNEE_MIR_1.stl" scale="0.001 0.001 0.001"/>
    </geometry>
  </collision>
</link>

<link name="2020_300mm__1__1">
  <inertial>
    <origin xyz="0.0002255686000470717 0.0359528241097988 -0.14631196131698326" rpy="0 0 0"/>
    <mass value="0.15869315430095224"/>
    <inertia ixx="0.001191" iyy="0.001161" izz="5.4e-05" ixy="-1.4e-05" iyz="0.000201" ixz="7.9e-05"/>
  </inertial>
  <visual>
    <origin xyz="0.011212 0.235506 0.459489" rpy="0 0 0"/>
    <geometry>
      <mesh filename="package://humanoidrightleg_description/meshes/2020_300mm__1__1.stl" scale="0.001 0.001 0.001"/>
    </geometry>
    <material name="opaque727161"/>
  </visual>
  <collision>
    <origin xyz="0.011212 0.235506 0.459489" rpy="0 0 0"/>
    <geometry>
      <mesh filename="package://humanoidrightleg_description/meshes/2020_300mm__1__1.stl" scale="0.001 0.001 0.001"/>
    </geometry>
  </collision>
</link>

<link name="magmount__1__1">
  <inertial>
    <origin xyz="0.0010247264729899182 -0.0031849477507481516 -0.015820120911692104" rpy="0 0 0"/>
    <mass value="0.0025511619258727428"/>
    <inertia ixx="0.0" iyy="0.0" izz="0.0" ixy="-0.0" iyz="0.0" ixz="0.0"/>
  </inertial>
  <visual>
    <origin xyz="0.020487 0.243448 0.472036" rpy="0 0 0"/>
    <geometry>
      <mesh filename="package://humanoidrightleg_description/meshes/magmount__1__1.stl" scale="0.001 0.001 0.001"/>
    </geometry>
    <material name="opaque191191191"/>
  </visual>
  <collision>
    <origin xyz="0.020487 0.243448 0.472036" rpy="0 0 0"/>
    <geometry>
      <mesh filename="package://humanoidrightleg_description/meshes/magmount__1__1.stl" scale="0.001 0.001 0.001"/>
    </geometry>
  </collision>
</link>

<link name="multiplex-stack_1">
  <inertial>
    <origin xyz="-0.007433124523101742 -0.03042141449827196 0.12501514284878423" rpy="0 0 0"/>
    <mass value="0.03127051048143962"/>
    <inertia ixx="4.7e-05" iyy="4.3e-05" izz="7e-06" ixy="-0.0" iyz="7e-06" ixz="3e-06"/>
  </inertial>
  <visual>
    <origin xyz="0.010761 0.165323 0.752417" rpy="0 0 0"/>
    <geometry>
      <mesh filename="package://humanoidrightleg_description/meshes/multiplex-stack_1.stl" scale="0.001 0.001 0.001"/>
    </geometry>
    <material name="opaque191191191"/>
  </visual>
  <collision>
    <origin xyz="0.010761 0.165323 0.752417" rpy="0 0 0"/>
    <geometry>
      <mesh filename="package://humanoidrightleg_description/meshes/multiplex-stack_1.stl" scale="0.001 0.001 0.001"/>
    </geometry>
  </collision>
</link>

<link name="thigh-nub_1">
  <inertial>
    <origin xyz="-0.0002641790130877581 -0.018843217604557122 0.12377909020719158" rpy="0 0 0"/>
    <mass value="0.004721505361821494"/>
    <inertia ixx="1e-06" iyy="1e-06" izz="0.0" ixy="-0.0" iyz="0.0" ixz="0.0"/>
  </inertial>
  <visual>
    <origin xyz="0.009015 0.163621 0.751996" rpy="0 0 0"/>
    <geometry>
      <mesh filename="package://humanoidrightleg_description/meshes/thigh-nub_1.stl" scale="0.001 0.001 0.001"/>
    </geometry>
    <material name="opaque191191191"/>
  </visual>
  <collision>
    <origin xyz="0.009015 0.163621 0.751996" rpy="0 0 0"/>
    <geometry>
      <mesh filename="package://humanoidrightleg_description/meshes/thigh-nub_1.stl" scale="0.001 0.001 0.001"/>
    </geometry>
  </collision>
</link>

<link name="knee-lock-2-b_1">
  <inertial>
    <origin xyz="0.01430567434827851 -0.0032563639449491033 0.03574204866602415" rpy="0 0 0"/>
    <mass value="0.024939662437992272"/>
    <inertia ixx="8e-06" iyy="1e-05" izz="3e-06" ixy="1e-06" iyz="2e-06" ixz="-1e-06"/>
  </inertial>
  <visual>
    <origin xyz="0.009015 0.163621 0.751996" rpy="0 0 0"/>
    <geometry>
      <mesh filename="package://humanoidrightleg_description/meshes/knee-lock-2-b_1.stl" scale="0.001 0.001 0.001"/>
    </geometry>
    <material name="opaque191191191"/>
  </visual>
  <collision>
    <origin xyz="0.009015 0.163621 0.751996" rpy="0 0 0"/>
    <geometry>
      <mesh filename="package://humanoidrightleg_description/meshes/knee-lock-2-b_1.stl" scale="0.001 0.001 0.001"/>
    </geometry>
  </collision>
</link>

<link name="knee-lock-2_1">
  <inertial>
    <origin xyz="0.014305665896650503 -0.009164247858262614 0.03470039476881437" rpy="0 0 0"/>
    <mass value="0.024939652723887113"/>
    <inertia ixx="8e-06" iyy="1e-05" izz="3e-06" ixy="-0.0" iyz="1e-06" ixz="-1e-06"/>
  </inertial>
  <visual>
    <origin xyz="0.009015 0.183317 0.755469" rpy="0 0 0"/>
    <geometry>
      <mesh filename="package://humanoidrightleg_description/meshes/knee-lock-2_1.stl" scale="0.001 0.001 0.001"/>
    </geometry>
    <material name="opaque191191191"/>
  </visual>
  <collision>
    <origin xyz="0.009015 0.183317 0.755469" rpy="0 0 0"/>
    <geometry>
      <mesh filename="package://humanoidrightleg_description/meshes/knee-lock-2_1.stl" scale="0.001 0.001 0.001"/>
    </geometry>
  </collision>
</link>

<link name="bearingstrap__1__1">
  <inertial>
    <origin xyz="-0.0004324784410459162 -0.0011014903242163865 0.006245338862356342" rpy="0 0 0"/>
    <mass value="0.03748820846896381"/>
    <inertia ixx="2.3e-05" iyy="2.8e-05" izz="8e-06" ixy="-0.0" iyz="4e-06" ixz="1e-06"/>
  </inertial>
  <visual>
    <origin xyz="0.000784 0.173566 0.75318" rpy="0 0 0"/>
    <geometry>
      <mesh filename="package://humanoidrightleg_description/meshes/bearingstrap__1__1.stl" scale="0.001 0.001 0.001"/>
    </geometry>
    <material name="opaque245245245"/>
  </visual>
  <collision>
    <origin xyz="0.000784 0.173566 0.75318" rpy="0 0 0"/>
    <geometry>
      <mesh filename="package://humanoidrightleg_description/meshes/bearingstrap__1__1.stl" scale="0.001 0.001 0.001"/>
    </geometry>
  </collision>
</link>

<link name="skateboard-bearing__13__1">
  <inertial>
    <origin xyz="9.155979948727907e-08 -0.0034473261007444134 -0.0006082382821951393" rpy="0 0 0"/>
    <mass value="0.018126204213049595"/>
    <inertia ixx="1e-06" iyy="1e-06" izz="1e-06" ixy="-0.0" iyz="0.0" ixz="0.0"/>
  </inertial>
  <visual>
    <origin xyz="-0.000236 0.161119 0.766181" rpy="0 0 0"/>
    <geometry>
      <mesh filename="package://humanoidrightleg_description/meshes/skateboard-bearing__13__1.stl" scale="0.001 0.001 0.001"/>
    </geometry>
    <material name="opaque191191191"/>
  </visual>
  <collision>
    <origin xyz="-0.000236 0.161119 0.766181" rpy="0 0 0"/>
    <geometry>
      <mesh filename="package://humanoidrightleg_description/meshes/skateboard-bearing__13__1.stl" scale="0.001 0.001 0.001"/>
    </geometry>
  </collision>
</link>

<link name="skateboard-bearing__14__1">
  <inertial>
    <origin xyz="9.155982279529474e-08 0.003447173110170648 0.0006073354077169579" rpy="0 0 0"/>
    <mass value="0.018126204213049595"/>
    <inertia ixx="1e-06" iyy="1e-06" izz="1e-06" ixy="-0.0" iyz="0.0" ixz="0.0"/>
  </inertial>
  <visual>
    <origin xyz="-0.000236 0.180816 0.769654" rpy="0 0 0"/>
    <geometry>
      <mesh filename="package://humanoidrightleg_description/meshes/skateboard-bearing__14__1.stl" scale="0.001 0.001 0.001"/>
    </geometry>
    <material name="opaque191191191"/>
  </visual>
  <collision>
    <origin xyz="-0.000236 0.180816 0.769654" rpy="0 0 0"/>
    <geometry>
      <mesh filename="package://humanoidrightleg_description/meshes/skateboard-bearing__14__1.stl" scale="0.001 0.001 0.001"/>
    </geometry>
  </collision>
</link>

<link name="conjstraint-knee-test-oute_MIR_1">
  <inertial>
    <origin xyz="0.03882319392392993 -0.01579081362118051 -0.000736302109011322" rpy="0 0 0"/>
    <mass value="0.10127313536972944"/>
    <inertia ixx="0.000119" iyy="0.000227" izz="0.000124" ixy="1.4e-05" iyz="2.1e-05" ixz="-7.9e-05"/>
  </inertial>
  <visual>
    <origin xyz="-0.000236 0.180816 0.769654" rpy="0 0 0"/>
    <geometry>
      <mesh filename="package://humanoidrightleg_description/meshes/conjstraint-knee-test-oute_MIR_1.stl" scale="0.001 0.001 0.001"/>
    </geometry>
    <material name="opaque245245245"/>
  </visual>
  <collision>
    <origin xyz="-0.000236 0.180816 0.769654" rpy="0 0 0"/>
    <geometry>
      <mesh filename="package://humanoidrightleg_description/meshes/conjstraint-knee-test-oute_MIR_1.stl" scale="0.001 0.001 0.001"/>
    </geometry>
  </collision>
</link>

<link name="conjstraint-knee-test-oute_1">
  <inertial>
    <origin xyz="0.038811022596126815 0.015063419955485352 0.0047247024113887814" rpy="0 0 0"/>
    <mass value="0.1008282575134409"/>
    <inertia ixx="0.000118" iyy="0.000227" izz="0.000122" ixy="1.4e-05" iyz="1.7e-05" ixz="-7.8e-05"/>
  </inertial>
  <visual>
    <origin xyz="-0.000236 0.161119 0.766181" rpy="0 0 0"/>
    <geometry>
      <mesh filename="package://humanoidrightleg_description/meshes/conjstraint-knee-test-oute_1.stl" scale="0.001 0.001 0.001"/>
    </geometry>
    <material name="opaque191191191"/>
  </visual>
  <collision>
    <origin xyz="-0.000236 0.161119 0.766181" rpy="0 0 0"/>
    <geometry>
      <mesh filename="package://humanoidrightleg_description/meshes/conjstraint-knee-test-oute_1.stl" scale="0.001 0.001 0.001"/>
    </geometry>
  </collision>
</link>

<link name="skateboard-bearing__15__1">
  <inertial>
    <origin xyz="3.7695695560835407e-07 -0.00393900815575432 -0.0006941966589904536" rpy="0 0 0"/>
    <mass value="0.018126204213049595"/>
    <inertia ixx="1e-06" iyy="1e-06" izz="1e-06" ixy="-0.0" iyz="0.0" ixz="-0.0"/>
  </inertial>
  <visual>
    <origin xyz="-0.102287 0.22603 0.395178" rpy="0 0 0"/>
    <geometry>
      <mesh filename="package://humanoidrightleg_description/meshes/skateboard-bearing__15__1.stl" scale="0.001 0.001 0.001"/>
    </geometry>
    <material name="opaque191191191"/>
  </visual>
  <collision>
    <origin xyz="-0.102287 0.22603 0.395178" rpy="0 0 0"/>
    <geometry>
      <mesh filename="package://humanoidrightleg_description/meshes/skateboard-bearing__15__1.stl" scale="0.001 0.001 0.001"/>
    </geometry>
  </collision>
</link>

<link name="bearingstrap_1">
  <inertial>
    <origin xyz="-0.0001487128353834105 -0.006139834752513396 -0.022768390002387062" rpy="0 0 0"/>
    <mass value="0.03748820846896381"/>
    <inertia ixx="2.3e-05" iyy="2.8e-05" izz="8e-06" ixy="0.0" iyz="4e-06" ixz="-0.0"/>
  </inertial>
  <visual>
    <origin xyz="-0.102287 0.226522 0.395264" rpy="0 0 0"/>
    <geometry>
      <mesh filename="package://humanoidrightleg_description/meshes/bearingstrap_1.stl" scale="0.001 0.001 0.001"/>
    </geometry>
    <material name="opaque245245245"/>
  </visual>
  <collision>
    <origin xyz="-0.102287 0.226522 0.395264" rpy="0 0 0"/>
    <geometry>
      <mesh filename="package://humanoidrightleg_description/meshes/bearingstrap_1.stl" scale="0.001 0.001 0.001"/>
    </geometry>
  </collision>
</link>

<link name="skateboard-bearing_1">
  <inertial>
    <origin xyz="3.7695697886752644e-07 0.003446491055138251 0.0006073770310486282" rpy="0 0 0"/>
    <mass value="0.018126204213049595"/>
    <inertia ixx="1e-06" iyy="1e-06" izz="1e-06" ixy="-0.0" iyz="0.0" ixz="0.0"/>
  </inertial>
  <visual>
    <origin xyz="-0.102287 0.246218 0.398737" rpy="0 0 0"/>
    <geometry>
      <mesh filename="package://humanoidrightleg_description/meshes/skateboard-bearing_1.stl" scale="0.001 0.001 0.001"/>
    </geometry>
    <material name="opaque191191191"/>
  </visual>
  <collision>
    <origin xyz="-0.102287 0.246218 0.398737" rpy="0 0 0"/>
    <geometry>
      <mesh filename="package://humanoidrightleg_description/meshes/skateboard-bearing_1.stl" scale="0.001 0.001 0.001"/>
    </geometry>
  </collision>
</link>

<link name="2020_300mm__2__1">
  <inertial>
    <origin xyz="-0.001047530992262763 0.026046992542230113 -0.1477172292134546" rpy="0 0 0"/>
    <mass value="0.15869315430095224"/>
    <inertia ixx="0.001197" iyy="0.001161" izz="4.9e-05" ixy="1e-06" iyz="0.000202" ixz="-8e-06"/>
  </inertial>
  <visual>
    <origin xyz="-0.102183 0.233766 0.411773" rpy="0 0 0"/>
    <geometry>
      <mesh filename="package://humanoidrightleg_description/meshes/2020_300mm__2__1.stl" scale="0.001 0.001 0.001"/>
    </geometry>
    <material name="opaque727161"/>
  </visual>
  <collision>
    <origin xyz="-0.102183 0.233766 0.411773" rpy="0 0 0"/>
    <geometry>
      <mesh filename="package://humanoidrightleg_description/meshes/2020_300mm__2__1.stl" scale="0.001 0.001 0.001"/>
    </geometry>
  </collision>
</link>

<link name="skateboard-bearing__8__1">
  <inertial>
    <origin xyz="3.7695681052996033e-07 0.0031166836831465483 0.0005492175934416754" rpy="0 0 0"/>
    <mass value="0.018126204213049595"/>
    <inertia ixx="1e-06" iyy="1e-06" izz="1e-06" ixy="-0.0" iyz="0.0" ixz="0.0"/>
  </inertial>
  <visual>
    <origin xyz="-0.102287 0.131488 0.378507" rpy="0 0 0"/>
    <geometry>
      <mesh filename="package://humanoidrightleg_description/meshes/skateboard-bearing__8__1.stl" scale="0.001 0.001 0.001"/>
    </geometry>
    <material name="opaque191191191"/>
  </visual>
  <collision>
    <origin xyz="-0.102287 0.131488 0.378507" rpy="0 0 0"/>
    <geometry>
      <mesh filename="package://humanoidrightleg_description/meshes/skateboard-bearing__8__1.stl" scale="0.001 0.001 0.001"/>
    </geometry>
  </collision>
</link>

<link name="bearingstrap-inner-thigh_1">
  <inertial>
    <origin xyz="-0.00015906790297608164 0.008755161592848282 -0.021646496774280988" rpy="0 0 0"/>
    <mass value="0.03925941417972207"/>
    <inertia ixx="2.7e-05" iyy="3.3e-05" izz="8e-06" ixy="-0.0" iyz="-2e-06" ixz="-0.0"/>
  </inertial>
  <visual>
    <origin xyz="-0.102287 0.131818 0.378566" rpy="0 0 0"/>
    <geometry>
      <mesh filename="package://humanoidrightleg_description/meshes/bearingstrap-inner-thigh_1.stl" scale="0.001 0.001 0.001"/>
    </geometry>
    <material name="opaque245245245"/>
  </visual>
  <collision>
    <origin xyz="-0.102287 0.131818 0.378566" rpy="0 0 0"/>
    <geometry>
      <mesh filename="package://humanoidrightleg_description/meshes/bearingstrap-inner-thigh_1.stl" scale="0.001 0.001 0.001"/>
    </geometry>
  </collision>
</link>

<link name="skateboard-bearing__9__1">
  <inertial>
    <origin xyz="3.7695675085547276e-07 -0.0034468155277484896 -0.0006073560965841329" rpy="0 0 0"/>
    <mass value="0.018126204213049595"/>
    <inertia ixx="1e-06" iyy="1e-06" izz="1e-06" ixy="-0.0" iyz="0.0" ixz="0.0"/>
  </inertial>
  <visual>
    <origin xyz="-0.102287 0.112122 0.375093" rpy="0 0 0"/>
    <geometry>
      <mesh filename="package://humanoidrightleg_description/meshes/skateboard-bearing__9__1.stl" scale="0.001 0.001 0.001"/>
    </geometry>
    <material name="opaque191191191"/>
  </visual>
  <collision>
    <origin xyz="-0.102287 0.112122 0.375093" rpy="0 0 0"/>
    <geometry>
      <mesh filename="package://humanoidrightleg_description/meshes/skateboard-bearing__9__1.stl" scale="0.001 0.001 0.001"/>
    </geometry>
  </collision>
</link>

<link name="2020_150mm__1___1__1">
  <inertial>
    <origin xyz="-0.010624357200376494 -0.0031884504296695593 -0.07552596625904107" rpy="0 0 0"/>
    <mass value="0.07934657715047623"/>
    <inertia ixx="0.000152" iyy="0.000148" izz="1.1e-05" ixy="-0.0" iyz="-2.5e-05" ixz="-1e-06"/>
  </inertial>
  <visual>
    <origin xyz="-0.112206 0.129201 0.389933" rpy="0 0 0"/>
    <geometry>
      <mesh filename="package://humanoidrightleg_description/meshes/2020_150mm__1___1__1.stl" scale="0.001 0.001 0.001"/>
    </geometry>
    <material name="opaque727161"/>
  </visual>
  <collision>
    <origin xyz="-0.112206 0.129201 0.389933" rpy="0 0 0"/>
    <geometry>
      <mesh filename="package://humanoidrightleg_description/meshes/2020_150mm__1___1__1.stl" scale="0.001 0.001 0.001"/>
    </geometry>
  </collision>
</link>

<link name="2020_100mm__12__1">
  <inertial>
    <origin xyz="-0.00032838704857045264 -0.00868296969425883 -0.049239116417619355" rpy="0 0 0"/>
    <mass value="0.05289771810031747"/>
    <inertia ixx="4.6e-05" iyy="4.5e-05" izz="6e-06" ixy="-0.0" iyz="-7e-06" ixz="-0.0"/>
  </inertial>
  <visual>
    <origin xyz="-0.10109 0.145413 0.539318" rpy="0 0 0"/>
    <geometry>
      <mesh filename="package://humanoidrightleg_description/meshes/2020_100mm__12__1.stl" scale="0.001 0.001 0.001"/>
    </geometry>
    <material name="opaque727161"/>
  </visual>
  <collision>
    <origin xyz="-0.10109 0.145413 0.539318" rpy="0 0 0"/>
    <geometry>
      <mesh filename="package://humanoidrightleg_description/meshes/2020_100mm__12__1.stl" scale="0.001 0.001 0.001"/>
    </geometry>
  </collision>
</link>

<link name="6band__5__1">
  <inertial>
    <origin xyz="-0.019006017992758625 -0.0005405870475611585 0.05379262354797398" rpy="0 0 0"/>
    <mass value="0.044524736884465024"/>
    <inertia ixx="1.6e-05" iyy="1.4e-05" izz="1.5e-05" ixy="0.0" iyz="0.0" ixz="0.0"/>
  </inertial>
  <visual>
    <origin xyz="-0.10866 0.152921 0.639589" rpy="0 0 0"/>
    <geometry>
      <mesh filename="package://humanoidrightleg_description/meshes/6band__5__1.stl" scale="0.001 0.001 0.001"/>
    </geometry>
    <material name="opaque245245245"/>
  </visual>
  <collision>
    <origin xyz="-0.10866 0.152921 0.639589" rpy="0 0 0"/>
    <geometry>
      <mesh filename="package://humanoidrightleg_description/meshes/6band__5__1.stl" scale="0.001 0.001 0.001"/>
    </geometry>
  </collision>
</link>

<link name="leg-thigh-knee-support-bottom_1">
  <inertial>
    <origin xyz="-0.0001172678534708399 -0.006060093966839597 -0.016955487054829188" rpy="0 0 0"/>
    <mass value="0.020998682573629524"/>
    <inertia ixx="4e-06" iyy="4e-06" izz="2e-06" ixy="0.0" iyz="0.0" ixz="-0.0"/>
  </inertial>
  <visual>
    <origin xyz="-0.100434 0.162779 0.637796" rpy="0 0 0"/>
    <geometry>
      <mesh filename="package://humanoidrightleg_description/meshes/leg-thigh-knee-support-bottom_1.stl" scale="0.001 0.001 0.001"/>
    </geometry>
    <material name="opaque191191191"/>
  </visual>
  <collision>
    <origin xyz="-0.100434 0.162779 0.637796" rpy="0 0 0"/>
    <geometry>
      <mesh filename="package://humanoidrightleg_description/meshes/leg-thigh-knee-support-bottom_1.stl" scale="0.001 0.001 0.001"/>
    </geometry>
  </collision>
</link>

<link name="thigh-bracket_1">
  <inertial>
    <origin xyz="0.0052023480177922216 -0.00435507601523441 0.032878428336749366" rpy="0 0 0"/>
    <mass value="0.038133616798883975"/>
    <inertia ixx="2.4e-05" iyy="1.5e-05" izz="1e-05" ixy="0.0" iyz="2e-06" ixz="-0.0"/>
  </inertial>
  <visual>
    <origin xyz="-0.110287 0.172073 0.660749" rpy="0 0 0"/>
    <geometry>
      <mesh filename="package://humanoidrightleg_description/meshes/thigh-bracket_1.stl" scale="0.001 0.001 0.001"/>
    </geometry>
    <material name="opaque191191191"/>
  </visual>
  <collision>
    <origin xyz="-0.110287 0.172073 0.660749" rpy="0 0 0"/>
    <geometry>
      <mesh filename="package://humanoidrightleg_description/meshes/thigh-bracket_1.stl" scale="0.001 0.001 0.001"/>
    </geometry>
  </collision>
</link>

<link name="double-bracket_1">
  <inertial>
    <origin xyz="-0.02534189091883729 -0.00037315637908857946 0.00211413222769119" rpy="0 0 0"/>
    <mass value="0.1084297628923745"/>
    <inertia ixx="6.2e-05" iyy="0.000122" izz="7e-05" ixy="3e-06" iyz="1e-05" ixz="-1.6e-05"/>
  </inertial>
  <visual>
    <origin xyz="-0.100088 0.181672 0.707208" rpy="0 0 0"/>
    <geometry>
      <mesh filename="package://humanoidrightleg_description/meshes/double-bracket_1.stl" scale="0.001 0.001 0.001"/>
    </geometry>
    <material name="opaque245245245"/>
  </visual>
  <collision>
    <origin xyz="-0.100088 0.181672 0.707208" rpy="0 0 0"/>
    <geometry>
      <mesh filename="package://humanoidrightleg_description/meshes/double-bracket_1.stl" scale="0.001 0.001 0.001"/>
    </geometry>
  </collision>
</link>

<link name="skateboard-bearing__11__1">
  <inertial>
    <origin xyz="-4.389414132999203e-07 0.003446993240224544 0.0006077382320240909" rpy="0 0 0"/>
    <mass value="0.018126204213049595"/>
    <inertia ixx="1e-06" iyy="1e-06" izz="1e-06" ixy="0.0" iyz="0.0" ixz="-0.0"/>
  </inertial>
  <visual>
    <origin xyz="-0.099984 0.188916 0.723716" rpy="0 0 0"/>
    <geometry>
      <mesh filename="package://humanoidrightleg_description/meshes/skateboard-bearing__11__1.stl" scale="0.001 0.001 0.001"/>
    </geometry>
    <material name="opaque191191191"/>
  </visual>
  <collision>
    <origin xyz="-0.099984 0.188916 0.723716" rpy="0 0 0"/>
    <geometry>
      <mesh filename="package://humanoidrightleg_description/meshes/skateboard-bearing__11__1.stl" scale="0.001 0.001 0.001"/>
    </geometry>
  </collision>
</link>

<link name="skateboard-bearing__20__1">
  <inertial>
    <origin xyz="2.321407890221172e-08 0.0034472562537290474 0.0006082501804621776" rpy="0 0 0"/>
    <mass value="0.018126204213049595"/>
    <inertia ixx="1e-06" iyy="1e-06" izz="1e-06" ixy="0.0" iyz="0.0" ixz="-0.0"/>
  </inertial>
  <visual>
    <origin xyz="-0.039985 0.188989 0.723304" rpy="0 0 0"/>
    <geometry>
      <mesh filename="package://humanoidrightleg_description/meshes/skateboard-bearing__20__1.stl" scale="0.001 0.001 0.001"/>
    </geometry>
    <material name="opaque191191191"/>
  </visual>
  <collision>
    <origin xyz="-0.039985 0.188989 0.723304" rpy="0 0 0"/>
    <geometry>
      <mesh filename="package://humanoidrightleg_description/meshes/skateboard-bearing__20__1.stl" scale="0.001 0.001 0.001"/>
    </geometry>
  </collision>
</link>

<link name="skateboard-bearing__10__1">
  <inertial>
    <origin xyz="-4.3894143593459223e-07 -0.0034465059706905166 -0.0006078354578878953" rpy="0 0 0"/>
    <mass value="0.018126204213049595"/>
    <inertia ixx="1e-06" iyy="1e-06" izz="1e-06" ixy="0.0" iyz="0.0" ixz="-0.0"/>
  </inertial>
  <visual>
    <origin xyz="-0.099984 0.16922 0.720243" rpy="0 0 0"/>
    <geometry>
      <mesh filename="package://humanoidrightleg_description/meshes/skateboard-bearing__10__1.stl" scale="0.001 0.001 0.001"/>
    </geometry>
    <material name="opaque191191191"/>
  </visual>
  <collision>
    <origin xyz="-0.099984 0.16922 0.720243" rpy="0 0 0"/>
    <geometry>
      <mesh filename="package://humanoidrightleg_description/meshes/skateboard-bearing__10__1.stl" scale="0.001 0.001 0.001"/>
    </geometry>
  </collision>
</link>

<link name="skateboard-bearing__16__1">
  <inertial>
    <origin xyz="2.321418373502082e-08 -0.003447242957185681 -0.000607323509451696" rpy="0 0 0"/>
    <mass value="0.018126204213049595"/>
    <inertia ixx="1e-06" iyy="1e-06" izz="1e-06" ixy="0.0" iyz="0.0" ixz="-0.0"/>
  </inertial>
  <visual>
    <origin xyz="-0.039985 0.169292 0.719831" rpy="0 0 0"/>
    <geometry>
      <mesh filename="package://humanoidrightleg_description/meshes/skateboard-bearing__16__1.stl" scale="0.001 0.001 0.001"/>
    </geometry>
    <material name="opaque191191191"/>
  </visual>
  <collision>
    <origin xyz="-0.039985 0.169292 0.719831" rpy="0 0 0"/>
    <geometry>
      <mesh filename="package://humanoidrightleg_description/meshes/skateboard-bearing__16__1.stl" scale="0.001 0.001 0.001"/>
    </geometry>
  </collision>
</link>

<link name="dumXrigid_1">
  <inertial>
    <origin xyz="0.0047885000685986695 -0.010767718495096362 0.11276655792524048" rpy="0 0 0"/>
    <mass value="0.0008014552972209"/>
    <inertia ixx="0.0" iyy="0.0" izz="0.0" ixy="-0.0" iyz="-0.0" ixz="0.0"/>
  </inertial>
  <visual>
    <origin xyz="-0.110088 0.189785 0.708709" rpy="0 0 0"/>
    <geometry>
      <mesh filename="package://humanoidrightleg_description/meshes/dumXrigid_1.stl" scale="0.001 0.001 0.001"/>
    </geometry>
    <material name="powder_coat_green"/>
  </visual>
  <collision>
    <origin xyz="-0.110088 0.189785 0.708709" rpy="0 0 0"/>
    <geometry>
      <mesh filename="package://humanoidrightleg_description/meshes/dumXrigid_1.stl" scale="0.001 0.001 0.001"/>
    </geometry>
  </collision>
</link>

<link name="knee-strap-second-test__1__1">
  <inertial>
    <origin xyz="0.022122394386950767 0.002469625670891429 -0.048628987614884545" rpy="0 0 0"/>
    <mass value="0.2504936394183554"/>
    <inertia ixx="0.00032" iyy="0.000386" izz="9.1e-05" ixy="-2.5e-05" iyz="5.6e-05" ixz="0.000137"/>
  </inertial>
  <visual>
    <origin xyz="-0.039985 0.188989 0.723304" rpy="0 0 0"/>
    <geometry>
      <mesh filename="package://humanoidrightleg_description/meshes/knee-strap-second-test__1__1.stl" scale="0.001 0.001 0.001"/>
    </geometry>
    <material name="opaque245245245"/>
  </visual>
  <collision>
    <origin xyz="-0.039985 0.188989 0.723304" rpy="0 0 0"/>
    <geometry>
      <mesh filename="package://humanoidrightleg_description/meshes/knee-strap-second-test__1__1.stl" scale="0.001 0.001 0.001"/>
    </geometry>
  </collision>
</link>

<link name="knee-strap-second-test_1">
  <inertial>
    <origin xyz="0.023668538944879365 0.014897978922971844 -0.04986659046992792" rpy="0 0 0"/>
    <mass value="0.03733472077955106"/>
    <inertia ixx="4.8e-05" iyy="5.7e-05" izz="1.4e-05" ixy="-4e-06" iyz="8e-06" ixz="2e-05"/>
  </inertial>
  <visual>
    <origin xyz="-0.039985 0.169292 0.719831" rpy="0 0 0"/>
    <geometry>
      <mesh filename="package://humanoidrightleg_description/meshes/knee-strap-second-test_1.stl" scale="0.001 0.001 0.001"/>
    </geometry>
    <material name="opaque245245245"/>
  </visual>
  <collision>
    <origin xyz="-0.039985 0.169292 0.719831" rpy="0 0 0"/>
    <geometry>
      <mesh filename="package://humanoidrightleg_description/meshes/knee-strap-second-test_1.stl" scale="0.001 0.001 0.001"/>
    </geometry>
  </collision>
</link>

<link name="skateboard-bearing__19__1">
  <inertial>
    <origin xyz="-5.299518796020308e-09 0.0034468795192271473 0.0006075641240931295" rpy="0 0 0"/>
    <mass value="0.018126204213049595"/>
    <inertia ixx="1e-06" iyy="1e-06" izz="1e-06" ixy="0.0" iyz="0.0" ixz="-0.0"/>
  </inertial>
  <visual>
    <origin xyz="-0.085776 0.171621 0.8218" rpy="0 0 0"/>
    <geometry>
      <mesh filename="package://humanoidrightleg_description/meshes/skateboard-bearing__19__1.stl" scale="0.001 0.001 0.001"/>
    </geometry>
    <material name="opaque191191191"/>
  </visual>
  <collision>
    <origin xyz="-0.085776 0.171621 0.8218" rpy="0 0 0"/>
    <geometry>
      <mesh filename="package://humanoidrightleg_description/meshes/skateboard-bearing__19__1.stl" scale="0.001 0.001 0.001"/>
    </geometry>
  </collision>
</link>

<link name="skateboard-bearing__18__1">
  <inertial>
    <origin xyz="4.264350317306764e-09 -0.003446616064289837 -0.0006080301378160735" rpy="0 0 0"/>
    <mass value="0.018126204213049595"/>
    <inertia ixx="1e-06" iyy="1e-06" izz="1e-06" ixy="0.0" iyz="0.0" ixz="-0.0"/>
  </inertial>
  <visual>
    <origin xyz="-0.085776 0.151925 0.818327" rpy="0 0 0"/>
    <geometry>
      <mesh filename="package://humanoidrightleg_description/meshes/skateboard-bearing__18__1.stl" scale="0.001 0.001 0.001"/>
    </geometry>
    <material name="opaque191191191"/>
  </visual>
  <collision>
    <origin xyz="-0.085776 0.151925 0.818327" rpy="0 0 0"/>
    <geometry>
      <mesh filename="package://humanoidrightleg_description/meshes/skateboard-bearing__18__1.stl" scale="0.001 0.001 0.001"/>
    </geometry>
  </collision>
</link>

<link name="skateboard-bearing__17__1">
  <inertial>
    <origin xyz="5.692452036826223e-08 0.003447195413974702 0.0006076649589171756" rpy="0 0 0"/>
    <mass value="0.018126204213049595"/>
    <inertia ixx="1e-06" iyy="1e-06" izz="1e-06" ixy="-0.0" iyz="0.0" ixz="0.0"/>
  </inertial>
  <visual>
    <origin xyz="-0.025688 0.171381 0.823163" rpy="0 0 0"/>
    <geometry>
      <mesh filename="package://humanoidrightleg_description/meshes/skateboard-bearing__17__1.stl" scale="0.001 0.001 0.001"/>
    </geometry>
    <material name="opaque191191191"/>
  </visual>
  <collision>
    <origin xyz="-0.025688 0.171381 0.823163" rpy="0 0 0"/>
    <geometry>
      <mesh filename="package://humanoidrightleg_description/meshes/skateboard-bearing__17__1.stl" scale="0.001 0.001 0.001"/>
    </geometry>
  </collision>
</link>

<link name="skateboard-bearing__12__1">
  <inertial>
    <origin xyz="5.6924495825394494e-08 -0.0034473037969404152 -0.0006079087309952547" rpy="0 0 0"/>
    <mass value="0.018126204213049595"/>
    <inertia ixx="1e-06" iyy="1e-06" izz="1e-06" ixy="-0.0" iyz="0.0" ixz="0.0"/>
  </inertial>
  <visual>
    <origin xyz="-0.025688 0.151684 0.81969" rpy="0 0 0"/>
    <geometry>
      <mesh filename="package://humanoidrightleg_description/meshes/skateboard-bearing__12__1.stl" scale="0.001 0.001 0.001"/>
    </geometry>
    <material name="opaque191191191"/>
  </visual>
  <collision>
    <origin xyz="-0.025688 0.151684 0.81969" rpy="0 0 0"/>
    <geometry>
      <mesh filename="package://humanoidrightleg_description/meshes/skateboard-bearing__12__1.stl" scale="0.001 0.001 0.001"/>
    </geometry>
  </collision>
</link>

<link name="double-bracket-10deg_MIR_MIR_MIR_1">
  <inertial>
    <origin xyz="-0.02525353901642803 0.01139075957708835 -0.01668469123925398" rpy="0 0 0"/>
    <mass value="0.11406479760790458"/>
    <inertia ixx="6.7e-05" iyy="0.000134" izz="7.4e-05" ixy="-1e-06" iyz="4e-06" ixz="1.7e-05"/>
  </inertial>
  <visual>
    <origin xyz="-0.085776 0.171621 0.8218" rpy="0 0 0"/>
    <geometry>
      <mesh filename="package://humanoidrightleg_description/meshes/double-bracket-10deg_MIR_MIR_MIR_1.stl" scale="0.001 0.001 0.001"/>
    </geometry>
    <material name="opaque245245245"/>
  </visual>
  <collision>
    <origin xyz="-0.085776 0.171621 0.8218" rpy="0 0 0"/>
    <geometry>
      <mesh filename="package://humanoidrightleg_description/meshes/double-bracket-10deg_MIR_MIR_MIR_1.stl" scale="0.001 0.001 0.001"/>
    </geometry>
  </collision>
</link>

<link name="400mmexal_MIR2_MIR3_1">
  <inertial>
    <origin xyz="0.00481220991259769 -1.039480620856903e-05 -0.1999420165682032" rpy="0 0 0"/>
    <mass value="0.43199999999999994"/>
    <inertia ixx="0.005771" iyy="0.005774" izz="3.2e-05" ixy="0.0" iyz="-0.0" ixz="0.000138"/>
  </inertial>
  <visual>
    <origin xyz="-0.086209 0.15892 0.837552" rpy="0 0 0"/>
    <geometry>
      <mesh filename="package://humanoidrightleg_description/meshes/400mmexal_MIR2_MIR3_1.stl" scale="0.001 0.001 0.001"/>
    </geometry>
    <material name="opaque727161"/>
  </visual>
  <collision>
    <origin xyz="-0.086209 0.15892 0.837552" rpy="0 0 0"/>
    <geometry>
      <mesh filename="package://humanoidrightleg_description/meshes/400mmexal_MIR2_MIR3_1.stl" scale="0.001 0.001 0.001"/>
    </geometry>
  </collision>
</link>

<link name="2020_400mm_1">
  <inertial>
    <origin xyz="0.004812209912597759 -1.039480620837474e-05 -0.19994201656820476" rpy="0 0 0"/>
    <mass value="0.21159087240126956"/>
    <inertia ixx="0.002828" iyy="0.00283" izz="1.9e-05" ixy="0.0" iyz="-0.0" ixz="6.8e-05"/>
  </inertial>
  <visual>
    <origin xyz="-0.086209 0.15892 0.837552" rpy="0 0 0"/>
    <geometry>
      <mesh filename="package://humanoidrightleg_description/meshes/2020_400mm_1.stl" scale="0.001 0.001 0.001"/>
    </geometry>
    <material name="opaque727161"/>
  </visual>
  <collision>
    <origin xyz="-0.086209 0.15892 0.837552" rpy="0 0 0"/>
    <geometry>
      <mesh filename="package://humanoidrightleg_description/meshes/2020_400mm_1.stl" scale="0.001 0.001 0.001"/>
    </geometry>
  </collision>
</link>

<link name="motor-calf-exal-mount_4">
  <inertial>
    <origin xyz="-0.0017876435874928098 0.007331270591610345 -0.15087419822992754" rpy="0 0 0"/>
    <mass value="0.016630111988705988"/>
    <inertia ixx="3e-06" iyy="4e-06" izz="2e-06" ixy="0.0" iyz="0.0" ixz="0.0"/>
  </inertial>
  <visual>
    <origin xyz="-0.086251 0.14892 0.837551" rpy="0 0 0"/>
    <geometry>
      <mesh filename="package://humanoidrightleg_description/meshes/motor-calf-exal-mount_4.stl" scale="0.001 0.001 0.001"/>
    </geometry>
    <material name="opaque245245245"/>
  </visual>
  <collision>
    <origin xyz="-0.086251 0.14892 0.837551" rpy="0 0 0"/>
    <geometry>
      <mesh filename="package://humanoidrightleg_description/meshes/motor-calf-exal-mount_4.stl" scale="0.001 0.001 0.001"/>
    </geometry>
  </collision>
</link>

<link name="motor-calf-exal-mount_3">
  <inertial>
    <origin xyz="-0.001850575049447023 -0.007300801298054327 -0.15087496615376816" rpy="0 0 0"/>
    <mass value="0.016630111988705988"/>
    <inertia ixx="3e-06" iyy="4e-06" izz="2e-06" ixy="-0.0" iyz="-0.0" ixz="0.0"/>
  </inertial>
  <visual>
    <origin xyz="-0.086167 0.16892 0.837552" rpy="0 0 0"/>
    <geometry>
      <mesh filename="package://humanoidrightleg_description/meshes/motor-calf-exal-mount_3.stl" scale="0.001 0.001 0.001"/>
    </geometry>
    <material name="opaque245245245"/>
  </visual>
  <collision>
    <origin xyz="-0.086167 0.16892 0.837552" rpy="0 0 0"/>
    <geometry>
      <mesh filename="package://humanoidrightleg_description/meshes/motor-calf-exal-mount_3.stl" scale="0.001 0.001 0.001"/>
    </geometry>
  </collision>
</link>

<link name="RMD-X8-Pro_MIR8_MIR1_2">
  <inertial>
    <origin xyz="-0.04013481113467417 -0.019209868966601096 -0.014028978931785563" rpy="0 0 0"/>
    <mass value="0.5168518474866729"/>
    <inertia ixx="0.000499" iyy="0.000736" izz="0.000507" ixy="-5e-06" iyz="-0.0" ixz="-0.0"/>
  </inertial>
  <visual>
    <origin xyz="-0.070605 0.141347 0.975776" rpy="0 0 0"/>
    <geometry>
      <mesh filename="package://humanoidrightleg_description/meshes/RMD-X8-Pro_MIR8_MIR1_2.stl" scale="0.001 0.001 0.001"/>
    </geometry>
    <material name="opaque13110895"/>
  </visual>
  <collision>
    <origin xyz="-0.070605 0.141347 0.975776" rpy="0 0 0"/>
    <geometry>
      <mesh filename="package://humanoidrightleg_description/meshes/RMD-X8-Pro_MIR8_MIR1_2.stl" scale="0.001 0.001 0.001"/>
    </geometry>
  </collision>
</link>

<link name="calf-skin_1">
  <inertial>
    <origin xyz="0.02622432685929328 -0.0018401195559730188 0.052825020486779506" rpy="0 0 0"/>
    <mass value="0.07036603324557442"/>
    <inertia ixx="6.9e-05" iyy="0.000103" izz="3.8e-05" ixy="-1e-06" iyz="-3e-06" ixz="-3.1e-05"/>
  </inertial>
  <visual>
    <origin xyz="-0.029855 0.176176 0.94781" rpy="0 0 0"/>
    <geometry>
      <mesh filename="package://humanoidrightleg_description/meshes/calf-skin_1.stl" scale="0.001 0.001 0.001"/>
    </geometry>
    <material name="opaque22122113"/>
  </visual>
  <collision>
    <origin xyz="-0.029855 0.176176 0.94781" rpy="0 0 0"/>
    <geometry>
      <mesh filename="package://humanoidrightleg_description/meshes/calf-skin_1.stl" scale="0.001 0.001 0.001"/>
    </geometry>
  </collision>
</link>

<link name="calf-skin_flip_1">
  <inertial>
    <origin xyz="0.02623868122399699 0.0016129564423404963 0.052824752581336676" rpy="0 0 0"/>
    <mass value="0.07036603324520026"/>
    <inertia ixx="6.9e-05" iyy="0.000103" izz="3.8e-05" ixy="2e-06" iyz="3e-06" ixz="-3.1e-05"/>
  </inertial>
  <visual>
    <origin xyz="-0.029915 0.141176 0.94781" rpy="0 0 0"/>
    <geometry>
      <mesh filename="package://humanoidrightleg_description/meshes/calf-skin_flip_1.stl" scale="0.001 0.001 0.001"/>
    </geometry>
    <material name="opaque22122113"/>
  </visual>
  <collision>
    <origin xyz="-0.029915 0.141176 0.94781" rpy="0 0 0"/>
    <geometry>
      <mesh filename="package://humanoidrightleg_description/meshes/calf-skin_flip_1.stl" scale="0.001 0.001 0.001"/>
    </geometry>
  </collision>
</link>

<link name="calf-cover_1">
  <inertial>
    <origin xyz="-0.0568896476708482 -0.0033082970292279135 -0.02624388939261113" rpy="0 0 0"/>
    <mass value="0.06189952945432647"/>
    <inertia ixx="9.7e-05" iyy="0.000122" izz="3.3e-05" ixy="3e-06" iyz="-1e-06" ixz="-2e-06"/>
  </inertial>
  <visual>
    <origin xyz="-0.056363 0.176284 1.023173" rpy="0 0 0"/>
    <geometry>
      <mesh filename="package://humanoidrightleg_description/meshes/calf-cover_1.stl" scale="0.001 0.001 0.001"/>
    </geometry>
    <material name="opaque191191191"/>
  </visual>
  <collision>
    <origin xyz="-0.056363 0.176284 1.023173" rpy="0 0 0"/>
    <geometry>
      <mesh filename="package://humanoidrightleg_description/meshes/calf-cover_1.stl" scale="0.001 0.001 0.001"/>
    </geometry>
  </collision>
</link>

<link name="calf-cover_2">
  <inertial>
    <origin xyz="-0.05733334681789603 0.0037944796043461737 -0.0065562693600986766" rpy="0 0 0"/>
    <mass value="0.06189952945432647"/>
    <inertia ixx="9.6e-05" iyy="0.000122" izz="3.4e-05" ixy="-3e-06" iyz="-2e-06" ixz="5e-06"/>
  </inertial>
  <visual>
    <origin xyz="-0.056582 0.141285 1.023117" rpy="0 0 0"/>
    <geometry>
      <mesh filename="package://humanoidrightleg_description/meshes/calf-cover_2.stl" scale="0.001 0.001 0.001"/>
    </geometry>
    <material name="opaque191191191"/>
  </visual>
  <collision>
    <origin xyz="-0.056582 0.141285 1.023117" rpy="0 0 0"/>
    <geometry>
      <mesh filename="package://humanoidrightleg_description/meshes/calf-cover_2.stl" scale="0.001 0.001 0.001"/>
    </geometry>
  </collision>
</link>

<link name="calf-motor-driver-ext_1">
  <inertial>
    <origin xyz="0.010178246712751336 0.011774874568494048 -0.004428887548508342" rpy="0 0 0"/>
    <mass value="0.04568445868866288"/>
    <inertia ixx="8e-06" iyy="2.1e-05" izz="1.6e-05" ixy="-2e-06" iyz="1e-06" ixz="4e-06"/>
  </inertial>
  <visual>
    <origin xyz="-0.031025 0.138678 0.989796" rpy="0 0 0"/>
    <geometry>
      <mesh filename="package://humanoidrightleg_description/meshes/calf-motor-driver-ext_1.stl" scale="0.001 0.001 0.001"/>
    </geometry>
    <material name="opaque2552550"/>
  </visual>
  <collision>
    <origin xyz="-0.031025 0.138678 0.989796" rpy="0 0 0"/>
    <geometry>
      <mesh filename="package://humanoidrightleg_description/meshes/calf-motor-driver-ext_1.stl" scale="0.001 0.001 0.001"/>
    </geometry>
  </collision>
</link>

<link name="bearing-sensor-adapter_2">
  <inertial>
    <origin xyz="-0.0035468408324215335 0.003354350472426451 -0.009143337585932665" rpy="0 0 0"/>
    <mass value="0.0040402472641540375"/>
    <inertia ixx="0.0" iyy="0.0" izz="0.0" ixy="-0.0" iyz="-0.0" ixz="0.0"/>
  </inertial>
  <visual>
    <origin xyz="-0.019135 0.126125 1.029986" rpy="0 0 0"/>
    <geometry>
      <mesh filename="package://humanoidrightleg_description/meshes/bearing-sensor-adapter_2.stl" scale="0.001 0.001 0.001"/>
    </geometry>
    <material name="opaque191191191"/>
  </visual>
  <collision>
    <origin xyz="-0.019135 0.126125 1.029986" rpy="0 0 0"/>
    <geometry>
      <mesh filename="package://humanoidrightleg_description/meshes/bearing-sensor-adapter_2.stl" scale="0.001 0.001 0.001"/>
    </geometry>
  </collision>
</link>

<link name="bearing-sensor-adapter-arm_2">
  <inertial>
    <origin xyz="0.0011145406161015524 0.004362766849756491 0.011839698114212371" rpy="0 0 0"/>
    <mass value="0.010036001917061667"/>
    <inertia ixx="5e-06" iyy="5e-06" izz="1e-06" ixy="-0.0" iyz="-0.0" ixz="-1e-06"/>
  </inertial>
  <visual>
    <origin xyz="-0.019166 0.118626 1.029986" rpy="0 0 0"/>
    <geometry>
      <mesh filename="package://humanoidrightleg_description/meshes/bearing-sensor-adapter-arm_2.stl" scale="0.001 0.001 0.001"/>
    </geometry>
    <material name="opaque191191191"/>
  </visual>
  <collision>
    <origin xyz="-0.019166 0.118626 1.029986" rpy="0 0 0"/>
    <geometry>
      <mesh filename="package://humanoidrightleg_description/meshes/bearing-sensor-adapter-arm_2.stl" scale="0.001 0.001 0.001"/>
    </geometry>
  </collision>
</link>

<link name="bearing-sensor-adapter_1">
  <inertial>
    <origin xyz="-0.0035744217206321715 -0.003323310110888489 -0.009144720305837462" rpy="0 0 0"/>
    <mass value="0.0040402472641540375"/>
    <inertia ixx="0.0" iyy="0.0" izz="0.0" ixy="0.0" iyz="0.0" ixz="0.0"/>
  </inertial>
  <visual>
    <origin xyz="-0.018788 0.191125 1.030044" rpy="0 0 0"/>
    <geometry>
      <mesh filename="package://humanoidrightleg_description/meshes/bearing-sensor-adapter_1.stl" scale="0.001 0.001 0.001"/>
    </geometry>
    <material name="opaque191191191"/>
  </visual>
  <collision>
    <origin xyz="-0.018788 0.191125 1.030044" rpy="0 0 0"/>
    <geometry>
      <mesh filename="package://humanoidrightleg_description/meshes/bearing-sensor-adapter_1.stl" scale="0.001 0.001 0.001"/>
    </geometry>
  </collision>
</link>

<link name="bearing-sensor-adapter-arm_1">
  <inertial>
    <origin xyz="0.0020816362170101646 -0.00437450811635387 -0.02987945805424741" rpy="0 0 0"/>
    <mass value="0.010036001917061667"/>
    <inertia ixx="5e-06" iyy="5e-06" izz="1e-06" ixy="0.0" iyz="-0.0" ixz="1e-06"/>
  </inertial>
  <visual>
    <origin xyz="-0.018756 0.198625 1.030044" rpy="0 0 0"/>
    <geometry>
      <mesh filename="package://humanoidrightleg_description/meshes/bearing-sensor-adapter-arm_1.stl" scale="0.001 0.001 0.001"/>
    </geometry>
    <material name="opaque191191191"/>
  </visual>
  <collision>
    <origin xyz="-0.018756 0.198625 1.030044" rpy="0 0 0"/>
    <geometry>
      <mesh filename="package://humanoidrightleg_description/meshes/bearing-sensor-adapter-arm_1.stl" scale="0.001 0.001 0.001"/>
    </geometry>
  </collision>
</link>

<link name="RMD-X8-Pro_MIR8_MIR1_1">
  <inertial>
    <origin xyz="-0.024314752863922914 0.01948623946300615 -0.03452531435656758" rpy="0 0 0"/>
    <mass value="0.5168518474866729"/>
    <inertia ixx="0.000499" iyy="0.000736" izz="0.000507" ixy="7e-06" iyz="0.0" ixz="-0.0"/>
  </inertial>
  <visual>
    <origin xyz="-0.057086 0.176286 1.053207" rpy="0 0 0"/>
    <geometry>
      <mesh filename="package://humanoidrightleg_description/meshes/RMD-X8-Pro_MIR8_MIR1_1.stl" scale="0.001 0.001 0.001"/>
    </geometry>
    <material name="opaque13110895"/>
  </visual>
  <collision>
    <origin xyz="-0.057086 0.176286 1.053207" rpy="0 0 0"/>
    <geometry>
      <mesh filename="package://humanoidrightleg_description/meshes/RMD-X8-Pro_MIR8_MIR1_1.stl" scale="0.001 0.001 0.001"/>
    </geometry>
  </collision>
</link>

<link name="motor-calf-exal-mount_1">
  <inertial>
    <origin xyz="0.013858858034007576 -0.0002415459844579415 -0.012649041150384344" rpy="0 0 0"/>
    <mass value="0.016630111988705988"/>
    <inertia ixx="3e-06" iyy="4e-06" izz="2e-06" ixy="0.0" iyz="0.0" ixz="0.0"/>
  </inertial>
  <visual>
    <origin xyz="-0.072919 0.141352 1.073781" rpy="0 0 0"/>
    <geometry>
      <mesh filename="package://humanoidrightleg_description/meshes/motor-calf-exal-mount_1.stl" scale="0.001 0.001 0.001"/>
    </geometry>
    <material name="opaque245245245"/>
  </visual>
  <collision>
    <origin xyz="-0.072919 0.141352 1.073781" rpy="0 0 0"/>
    <geometry>
      <mesh filename="package://humanoidrightleg_description/meshes/motor-calf-exal-mount_1.stl" scale="0.001 0.001 0.001"/>
    </geometry>
  </collision>
</link>

<link name="motor-calf-exal-mount_2">
  <inertial>
    <origin xyz="0.013860307663680502 0.00012526175108293347 -0.01264862389806698" rpy="0 0 0"/>
    <mass value="0.016630111988705988"/>
    <inertia ixx="3e-06" iyy="4e-06" izz="2e-06" ixy="-0.0" iyz="-0.0" ixz="0.0"/>
  </inertial>
  <visual>
    <origin xyz="-0.0728 0.176351 1.073867" rpy="0 0 0"/>
    <geometry>
      <mesh filename="package://humanoidrightleg_description/meshes/motor-calf-exal-mount_2.stl" scale="0.001 0.001 0.001"/>
    </geometry>
    <material name="opaque245245245"/>
  </visual>
  <collision>
    <origin xyz="-0.0728 0.176351 1.073867" rpy="0 0 0"/>
    <geometry>
      <mesh filename="package://humanoidrightleg_description/meshes/motor-calf-exal-mount_2.stl" scale="0.001 0.001 0.001"/>
    </geometry>
  </collision>
</link>

<link name="calf-motor-driver-ext_2">
  <inertial>
    <origin xyz="0.011001235971111425 -0.011865067965070059 0.00026529896732330194" rpy="0 0 0"/>
    <mass value="0.04568445868866288"/>
    <inertia ixx="6e-06" iyy="2.1e-05" izz="1.8e-05" ixy="2e-06" iyz="0.0" ixz="-0.0"/>
  </inertial>
  <visual>
    <origin xyz="-0.03314 0.178682 1.087719" rpy="0 0 0"/>
    <geometry>
      <mesh filename="package://humanoidrightleg_description/meshes/calf-motor-driver-ext_2.stl" scale="0.001 0.001 0.001"/>
    </geometry>
    <material name="opaque2552550"/>
  </visual>
  <collision>
    <origin xyz="-0.03314 0.178682 1.087719" rpy="0 0 0"/>
    <geometry>
      <mesh filename="package://humanoidrightleg_description/meshes/calf-motor-driver-ext_2.stl" scale="0.001 0.001 0.001"/>
    </geometry>
  </collision>
</link>

<link name="calf-lower-bracket_left_1">
  <inertial>
    <origin xyz="0.018451597164535927 0.0016725449161055783 -0.04856092565564363" rpy="0 0 0"/>
    <mass value="0.04075285627251198"/>
    <inertia ixx="3.1e-05" iyy="4.5e-05" izz="1.6e-05" ixy="1e-06" iyz="-1e-06" ixz="1.4e-05"/>
  </inertial>
  <visual>
    <origin xyz="-0.058796 0.141289 1.121092" rpy="0 0 0"/>
    <geometry>
      <mesh filename="package://humanoidrightleg_description/meshes/calf-lower-bracket_left_1.stl" scale="0.001 0.001 0.001"/>
    </geometry>
    <material name="opaque22122113"/>
  </visual>
  <collision>
    <origin xyz="-0.058796 0.141289 1.121092" rpy="0 0 0"/>
    <geometry>
      <mesh filename="package://humanoidrightleg_description/meshes/calf-lower-bracket_left_1.stl" scale="0.001 0.001 0.001"/>
    </geometry>
  </collision>
</link>

<link name="calf-lower-bracket_1">
  <inertial>
    <origin xyz="0.018436633760132708 -0.00182397299207257 -0.04856073634311375" rpy="0 0 0"/>
    <mass value="0.04075285793353643"/>
    <inertia ixx="3.1e-05" iyy="4.5e-05" izz="1.6e-05" ixy="-1e-06" iyz="1e-06" ixz="1.4e-05"/>
  </inertial>
  <visual>
    <origin xyz="-0.058577 0.176289 1.121148" rpy="0 0 0"/>
    <geometry>
      <mesh filename="package://humanoidrightleg_description/meshes/calf-lower-bracket_1.stl" scale="0.001 0.001 0.001"/>
    </geometry>
    <material name="opaque22122113"/>
  </visual>
  <collision>
    <origin xyz="-0.058577 0.176289 1.121148" rpy="0 0 0"/>
    <geometry>
      <mesh filename="package://humanoidrightleg_description/meshes/calf-lower-bracket_1.stl" scale="0.001 0.001 0.001"/>
    </geometry>
  </collision>
</link>

<link name="ankle-thick_1">
  <inertial>
    <origin xyz="-7.54709888720756e-05 5.552384287899059e-07 0.0031526473008398614" rpy="0 0 0"/>
    <mass value="0.08878020853187674"/>
    <inertia ixx="7.3e-05" iyy="9.8e-05" izz="3e-05" ixy="0.0" iyz="-0.0" ixz="1e-06"/>
  </inertial>
  <visual>
    <origin xyz="-0.095833 0.158941 1.237436" rpy="0 0 0"/>
    <geometry>
      <mesh filename="package://humanoidrightleg_description/meshes/ankle-thick_1.stl" scale="0.001 0.001 0.001"/>
    </geometry>
    <material name="opaque191191191"/>
  </visual>
  <collision>
    <origin xyz="-0.095833 0.158941 1.237436" rpy="0 0 0"/>
    <geometry>
      <mesh filename="package://humanoidrightleg_description/meshes/ankle-thick_1.stl" scale="0.001 0.001 0.001"/>
    </geometry>
  </collision>
</link>

<link name="ankle-side-bracket_2">
  <inertial>
    <origin xyz="-0.017568642659005207 0.004971856724086593 -0.01596146780401453" rpy="0 0 0"/>
    <mass value="0.025152752974316673"/>
    <inertia ixx="4e-06" iyy="1.2e-05" izz="9e-06" ixy="0.0" iyz="0.0" ixz="-0.0"/>
  </inertial>
  <visual>
    <origin xyz="-0.113211 0.149016 1.209611" rpy="0 0 0"/>
    <geometry>
      <mesh filename="package://humanoidrightleg_description/meshes/ankle-side-bracket_2.stl" scale="0.001 0.001 0.001"/>
    </geometry>
    <material name="opaque191191191"/>
  </visual>
  <collision>
    <origin xyz="-0.113211 0.149016 1.209611" rpy="0 0 0"/>
    <geometry>
      <mesh filename="package://humanoidrightleg_description/meshes/ankle-side-bracket_2.stl" scale="0.001 0.001 0.001"/>
    </geometry>
  </collision>
</link>

<link name="ankle-side-bracket_1">
  <inertial>
    <origin xyz="-0.017672533036219226 -0.004820854192575524 -0.015963492750493025" rpy="0 0 0"/>
    <mass value="0.025152752974316673"/>
    <inertia ixx="4e-06" iyy="1.2e-05" izz="9e-06" ixy="0.0" iyz="-0.0" ixz="-0.0"/>
  </inertial>
  <visual>
    <origin xyz="-0.113126 0.169015 1.209612" rpy="0 0 0"/>
    <geometry>
      <mesh filename="package://humanoidrightleg_description/meshes/ankle-side-bracket_1.stl" scale="0.001 0.001 0.001"/>
    </geometry>
    <material name="opaque191191191"/>
  </visual>
  <collision>
    <origin xyz="-0.113126 0.169015 1.209612" rpy="0 0 0"/>
    <geometry>
      <mesh filename="package://humanoidrightleg_description/meshes/ankle-side-bracket_1.stl" scale="0.001 0.001 0.001"/>
    </geometry>
  </collision>
</link>

<link name="basis_left_1">
  <inertial>
    <origin xyz="0.0012050375370820376 -0.009832925163153122 -0.021314922307062556" rpy="0 0 0"/>
    <mass value="0.1042453729311296"/>
    <inertia ixx="7.2e-05" iyy="6.3e-05" izz="3.7e-05" ixy="-0.0" iyz="-0.0" ixz="2e-06"/>
  </inertial>
  <visual>
    <origin xyz="-0.096718 0.148942 1.272425" rpy="0 0 0"/>
    <geometry>
      <mesh filename="package://humanoidrightleg_description/meshes/basis_left_1.stl" scale="0.001 0.001 0.001"/>
    </geometry>
    <material name="opaque245245245"/>
  </visual>
  <collision>
    <origin xyz="-0.096718 0.148942 1.272425" rpy="0 0 0"/>
    <geometry>
      <mesh filename="package://humanoidrightleg_description/meshes/basis_left_1.stl" scale="0.001 0.001 0.001"/>
    </geometry>
  </collision>
</link>

<link name="skateboard-bearing_left_2">
  <inertial>
    <origin xyz="-0.0034938677458842132 1.4714674692828389e-05 -0.00020601343618853463" rpy="0 0 0"/>
    <mass value="0.018126204213049595"/>
    <inertia ixx="1e-06" iyy="1e-06" izz="1e-06" ixy="-0.0" iyz="-0.0" ixz="0.0"/>
  </inertial>
  <visual>
    <origin xyz="-0.118998 0.159035 1.311178" rpy="0 0 0"/>
    <geometry>
      <mesh filename="package://humanoidrightleg_description/meshes/skateboard-bearing_left_2.stl" scale="0.001 0.001 0.001"/>
    </geometry>
    <material name="opaque191191191"/>
  </visual>
  <collision>
    <origin xyz="-0.118998 0.159035 1.311178" rpy="0 0 0"/>
    <geometry>
      <mesh filename="package://humanoidrightleg_description/meshes/skateboard-bearing_left_2.stl" scale="0.001 0.001 0.001"/>
    </geometry>
  </collision>
</link>

<link name="skateboard-bearing_left_1">
  <inertial>
    <origin xyz="0.003493790451152834 -1.442349852731617e-05 0.00020610733718329222" rpy="0 0 0"/>
    <mass value="0.018126204213049595"/>
    <inertia ixx="1e-06" iyy="1e-06" izz="1e-06" ixy="-0.0" iyz="-0.0" ixz="0.0"/>
  </inertial>
  <visual>
    <origin xyz="-0.079068 0.158866 1.313535" rpy="0 0 0"/>
    <geometry>
      <mesh filename="package://humanoidrightleg_description/meshes/skateboard-bearing_left_1.stl" scale="0.001 0.001 0.001"/>
    </geometry>
    <material name="opaque191191191"/>
  </visual>
  <collision>
    <origin xyz="-0.079068 0.158866 1.313535" rpy="0 0 0"/>
    <geometry>
      <mesh filename="package://humanoidrightleg_description/meshes/skateboard-bearing_left_1.stl" scale="0.001 0.001 0.001"/>
    </geometry>
  </collision>
</link>

<link name="heel-bracket_left_1">
  <inertial>
    <origin xyz="0.026349960786688734 -0.00011163274587608352 -0.005519189395047253" rpy="0 0 0"/>
    <mass value="0.08751895663212436"/>
    <inertia ixx="3e-05" iyy="2.6e-05" izz="4.3e-05" ixy="-0.0" iyz="-0.0" ixz="0.0"/>
  </inertial>
  <visual>
    <origin xyz="-0.118998 0.159035 1.311178" rpy="0 0 0"/>
    <geometry>
      <mesh filename="package://humanoidrightleg_description/meshes/heel-bracket_left_1.stl" scale="0.001 0.001 0.001"/>
    </geometry>
    <material name="opaque245245245"/>
  </visual>
  <collision>
    <origin xyz="-0.118998 0.159035 1.311178" rpy="0 0 0"/>
    <geometry>
      <mesh filename="package://humanoidrightleg_description/meshes/heel-bracket_left_1.stl" scale="0.001 0.001 0.001"/>
    </geometry>
  </collision>
</link>

<link name="tie-rod-ankle-brackket_left1_1">
  <inertial>
    <origin xyz="-0.00015561619447526653 -0.01474220492829098 -0.01004103770814968" rpy="0 0 0"/>
    <mass value="0.07145651189825321"/>
    <inertia ixx="2.1e-05" iyy="5.8e-05" izz="5.1e-05" ixy="6e-06" iyz="1e-06" ixz="-2e-06"/>
  </inertial>
  <visual>
    <origin xyz="-0.163835 0.179226 1.308527" rpy="0 0 0"/>
    <geometry>
      <mesh filename="package://humanoidrightleg_description/meshes/tie-rod-ankle-brackket_left1_1.stl" scale="0.001 0.001 0.001"/>
    </geometry>
    <material name="opaque245245245"/>
  </visual>
  <collision>
    <origin xyz="-0.163835 0.179226 1.308527" rpy="0 0 0"/>
    <geometry>
      <mesh filename="package://humanoidrightleg_description/meshes/tie-rod-ankle-brackket_left1_1.stl" scale="0.001 0.001 0.001"/>
    </geometry>
  </collision>
</link>

<link name="tie-rod-ankle-brackket_left_1">
  <inertial>
    <origin xyz="0.034983522757448954 0.014648280857203322 -0.00797306302636569" rpy="0 0 0"/>
    <mass value="0.0716558798812961"/>
    <inertia ixx="2.1e-05" iyy="5.8e-05" izz="5.1e-05" ixy="-6e-06" iyz="-1e-06" ixz="-2e-06"/>
  </inertial>
  <visual>
    <origin xyz="-0.129065 0.139078 1.310587" rpy="0 0 0"/>
    <geometry>
      <mesh filename="package://humanoidrightleg_description/meshes/tie-rod-ankle-brackket_left_1.stl" scale="0.001 0.001 0.001"/>
    </geometry>
    <material name="opaque245245245"/>
  </visual>
  <collision>
    <origin xyz="-0.129065 0.139078 1.310587" rpy="0 0 0"/>
    <geometry>
      <mesh filename="package://humanoidrightleg_description/meshes/tie-rod-ankle-brackket_left_1.stl" scale="0.001 0.001 0.001"/>
    </geometry>
  </collision>
</link>

<link name="foot-imu-strap_1">
  <inertial>
    <origin xyz="0.017322571610062898 -7.382323074478503e-05 0.00352722461081445" rpy="0 0 0"/>
    <mass value="0.002277228962795669"/>
    <inertia ixx="0.0" iyy="0.0" izz="0.0" ixy="0.0" iyz="0.0" ixz="-0.0"/>
  </inertial>
  <visual>
    <origin xyz="-0.128221 0.199075 1.300608" rpy="0 0 0"/>
    <geometry>
      <mesh filename="package://humanoidrightleg_description/meshes/foot-imu-strap_1.stl" scale="0.001 0.001 0.001"/>
    </geometry>
    <material name="opaque191191191"/>
  </visual>
  <collision>
    <origin xyz="-0.128221 0.199075 1.300608" rpy="0 0 0"/>
    <geometry>
      <mesh filename="package://humanoidrightleg_description/meshes/foot-imu-strap_1.stl" scale="0.001 0.001 0.001"/>
    </geometry>
  </collision>
</link>

<link name="mpu1_1">
  <inertial>
    <origin xyz="-0.010178984286534215 0.005224552897792528 0.00014883990884850817" rpy="0 0 0"/>
    <mass value="0.0006824542720182738"/>
    <inertia ixx="0.0" iyy="0.0" izz="0.0" ixy="0.0" iyz="0.0" ixz="-0.0"/>
  </inertial>
  <visual>
    <origin xyz="-0.155553 0.199191 1.293985" rpy="0 0 0"/>
    <geometry>
      <mesh filename="package://humanoidrightleg_description/meshes/mpu1_1.stl" scale="0.001 0.001 0.001"/>
    </geometry>
    <material name="opaque0125168"/>
  </visual>
  <collision>
    <origin xyz="-0.155553 0.199191 1.293985" rpy="0 0 0"/>
    <geometry>
      <mesh filename="package://humanoidrightleg_description/meshes/mpu1_1.stl" scale="0.001 0.001 0.001"/>
    </geometry>
  </collision>
</link>

<link name="2020_150mm__6__1">
  <inertial>
    <origin xyz="-0.07486938858053525 0.00031801369258699363 -0.0044201127571279475" rpy="0 0 0"/>
    <mass value="0.07934657715047623"/>
    <inertia ixx="7e-06" iyy="0.000152" izz="0.000152" ixy="1e-06" iyz="0.0" ixz="-9e-06"/>
  </inertial>
  <visual>
    <origin xyz="-0.174322 0.19927 1.317921" rpy="0 0 0"/>
    <geometry>
      <mesh filename="package://humanoidrightleg_description/meshes/2020_150mm__6__1.stl" scale="0.001 0.001 0.001"/>
    </geometry>
    <material name="opaque727161"/>
  </visual>
  <collision>
    <origin xyz="-0.174322 0.19927 1.317921" rpy="0 0 0"/>
    <geometry>
      <mesh filename="package://humanoidrightleg_description/meshes/2020_150mm__6__1.stl" scale="0.001 0.001 0.001"/>
    </geometry>
  </collision>
</link>

<link name="2020_150mm__6__2">
  <inertial>
    <origin xyz="-0.07486898031412768 0.0003182958469043623 -0.004420028894079664" rpy="0 0 0"/>
    <mass value="0.07934657715047623"/>
    <inertia ixx="7e-06" iyy="0.000152" izz="0.000152" ixy="1e-06" iyz="0.0" ixz="-9e-06"/>
  </inertial>
  <visual>
    <origin xyz="-0.174661 0.119271 1.317917" rpy="0 0 0"/>
    <geometry>
      <mesh filename="package://humanoidrightleg_description/meshes/2020_150mm__6__2.stl" scale="0.001 0.001 0.001"/>
    </geometry>
    <material name="opaque727161"/>
  </visual>
  <collision>
    <origin xyz="-0.174661 0.119271 1.317917" rpy="0 0 0"/>
    <geometry>
      <mesh filename="package://humanoidrightleg_description/meshes/2020_150mm__6__2.stl" scale="0.001 0.001 0.001"/>
    </geometry>
  </collision>
</link>

<link name="toes-rotor_1">
  <inertial>
    <origin xyz="0.022060973597910566 -0.029594208215563356 0.0012600647937175413" rpy="0 0 0"/>
    <mass value="0.08400427893658871"/>
    <inertia ixx="2.6e-05" iyy="4.2e-05" izz="5.9e-05" ixy="0.0" iyz="0.0" ixz="-2e-06"/>
  </inertial>
  <visual>
    <origin xyz="-0.190588 0.129838 1.316974" rpy="0 0 0"/>
    <geometry>
      <mesh filename="package://humanoidrightleg_description/meshes/toes-rotor_1.stl" scale="0.001 0.001 0.001"/>
    </geometry>
    <material name="opaque191191191"/>
  </visual>
  <collision>
    <origin xyz="-0.190588 0.129838 1.316974" rpy="0 0 0"/>
    <geometry>
      <mesh filename="package://humanoidrightleg_description/meshes/toes-rotor_1.stl" scale="0.001 0.001 0.001"/>
    </geometry>
  </collision>
</link>

<link name="toes_1">
  <inertial>
    <origin xyz="0.030351241031023823 -0.02876001013942764 -0.001843074602004613" rpy="0 0 0"/>
    <mass value="0.10347990827994236"/>
    <inertia ixx="0.00011" iyy="3.5e-05" izz="0.000131" ixy="-1e-06" iyz="0.0" ixz="-0.0"/>
  </inertial>
  <visual>
    <origin xyz="-0.22153 0.13097 1.315147" rpy="0 0 0"/>
    <geometry>
      <mesh filename="package://humanoidrightleg_description/meshes/toes_1.stl" scale="0.001 0.001 0.001"/>
    </geometry>
    <material name="opaque191191191"/>
  </visual>
  <collision>
    <origin xyz="-0.22153 0.13097 1.315147" rpy="0 0 0"/>
    <geometry>
      <mesh filename="package://humanoidrightleg_description/meshes/toes_1.stl" scale="0.001 0.001 0.001"/>
    </geometry>
  </collision>
</link>

<link name="foot-top_1">
  <inertial>
    <origin xyz="-0.0036927781451750463 1.5642939830057268e-05 0.004560985094389736" rpy="0 0 0"/>
    <mass value="0.04735315584876361"/>
    <inertia ixx="2e-05" iyy="1.6e-05" izz="3.6e-05" ixy="-0.0" iyz="0.0" ixz="-0.0"/>
  </inertial>
  <visual>
    <origin xyz="-0.230802 0.15951 1.304577" rpy="0 0 0"/>
    <geometry>
      <mesh filename="package://humanoidrightleg_description/meshes/foot-top_1.stl" scale="0.001 0.001 0.001"/>
    </geometry>
    <material name="opaque245245245"/>
  </visual>
  <collision>
    <origin xyz="-0.230802 0.15951 1.304577" rpy="0 0 0"/>
    <geometry>
      <mesh filename="package://humanoidrightleg_description/meshes/foot-top_1.stl" scale="0.001 0.001 0.001"/>
    </geometry>
  </collision>
</link>

<link name="wire-clip_1">
  <inertial>
    <origin xyz="-0.07366569080686575 0.0003125955460148433 0.0016777562303902371" rpy="0 0 0"/>
    <mass value="0.000948886394408878"/>
    <inertia ixx="0.0" iyy="0.0" izz="0.0" ixy="-0.0" iyz="-0.0" ixz="0.0"/>
  </inertial>
  <visual>
    <origin xyz="-0.174322 0.19927 1.317921" rpy="0 0 0"/>
    <geometry>
      <mesh filename="package://humanoidrightleg_description/meshes/wire-clip_1.stl" scale="0.001 0.001 0.001"/>
    </geometry>
    <material name="opaque191191191"/>
  </visual>
  <collision>
    <origin xyz="-0.174322 0.19927 1.317921" rpy="0 0 0"/>
    <geometry>
      <mesh filename="package://humanoidrightleg_description/meshes/wire-clip_1.stl" scale="0.001 0.001 0.001"/>
    </geometry>
  </collision>
</link>

<link name="heel-topleft_1">
  <inertial>
    <origin xyz="0.025888909553107214 0.007754754051662233 0.02238331760826262" rpy="0 0 0"/>
    <mass value="0.03465708098965354"/>
    <inertia ixx="6e-06" iyy="8e-06" izz="9e-06" ixy="0.0" iyz="-0.0" ixz="-0.0"/>
  </inertial>
  <visual>
    <origin xyz="-0.024584 0.198634 1.326761" rpy="0 0 0"/>
    <geometry>
      <mesh filename="package://humanoidrightleg_description/meshes/heel-topleft_1.stl" scale="0.001 0.001 0.001"/>
    </geometry>
    <material name="opaque245245245"/>
  </visual>
  <collision>
    <origin xyz="-0.024584 0.198634 1.326761" rpy="0 0 0"/>
    <geometry>
      <mesh filename="package://humanoidrightleg_description/meshes/heel-topleft_1.stl" scale="0.001 0.001 0.001"/>
    </geometry>
  </collision>
</link>

<link name="heel-bracketleft_1">
  <inertial>
    <origin xyz="0.020402751333189625 0.01991424604474068 -0.006186956046189129" rpy="0 0 0"/>
    <mass value="0.08322837820187094"/>
    <inertia ixx="2.9e-05" iyy="2.4e-05" izz="4.1e-05" ixy="-0.0" iyz="0.0" ixz="-2e-06"/>
  </inertial>
  <visual>
    <origin xyz="-0.034062 0.178675 1.316188" rpy="0 0 0"/>
    <geometry>
      <mesh filename="package://humanoidrightleg_description/meshes/heel-bracketleft_1.stl" scale="0.001 0.001 0.001"/>
    </geometry>
    <material name="opaque191191191"/>
  </visual>
  <collision>
    <origin xyz="-0.034062 0.178675 1.316188" rpy="0 0 0"/>
    <geometry>
      <mesh filename="package://humanoidrightleg_description/meshes/heel-bracketleft_1.stl" scale="0.001 0.001 0.001"/>
    </geometry>
  </collision>
</link>

<link name="ankle-motor-driver-bracketleft_1">
  <inertial>
    <origin xyz="0.017154081616141965 -0.010054575237178703 -0.0037974977219004113" rpy="0 0 0"/>
    <mass value="0.02264633041173001"/>
    <inertia ixx="3e-06" iyy="6e-06" izz="8e-06" ixy="0.0" iyz="0.0" ixz="-0.0"/>
  </inertial>
  <visual>
    <origin xyz="-0.03524 0.178679 1.336154" rpy="0 0 0"/>
    <geometry>
      <mesh filename="package://humanoidrightleg_description/meshes/ankle-motor-driver-bracketleft_1.stl" scale="0.001 0.001 0.001"/>
    </geometry>
    <material name="opaque245245245"/>
  </visual>
  <collision>
    <origin xyz="-0.03524 0.178679 1.336154" rpy="0 0 0"/>
    <geometry>
      <mesh filename="package://humanoidrightleg_description/meshes/ankle-motor-driver-bracketleft_1.stl" scale="0.001 0.001 0.001"/>
    </geometry>
  </collision>
</link>

<link name="new-heel_1">
  <inertial>
    <origin xyz="-0.014222865920115606 0.00012512256378766073 -0.013276964732054752" rpy="0 0 0"/>
    <mass value="0.035457108493927005"/>
    <inertia ixx="7e-06" iyy="8e-06" izz="7e-06" ixy="1e-06" iyz="-0.0" ixz="1e-06"/>
  </inertial>
  <visual>
    <origin xyz="-0.023742 0.188631 1.311787" rpy="0 0 0"/>
    <geometry>
      <mesh filename="package://humanoidrightleg_description/meshes/new-heel_1.stl" scale="0.001 0.001 0.001"/>
    </geometry>
    <material name="opaque191191191"/>
  </visual>
  <collision>
    <origin xyz="-0.023742 0.188631 1.311787" rpy="0 0 0"/>
    <geometry>
      <mesh filename="package://humanoidrightleg_description/meshes/new-heel_1.stl" scale="0.001 0.001 0.001"/>
    </geometry>
  </collision>
</link>

<link name="heel-connector_1">
  <inertial>
    <origin xyz="-1.4691914242812801e-05 0.014999911139130656 -0.0005317580245820519" rpy="0 0 0"/>
    <mass value="0.016395256340510117"/>
    <inertia ixx="3e-06" iyy="3e-06" izz="2e-06" ixy="-0.0" iyz="-0.0" ixz="1e-06"/>
  </inertial>
  <visual>
    <origin xyz="0.00244 0.173519 1.325356" rpy="0 0 0"/>
    <geometry>
      <mesh filename="package://humanoidrightleg_description/meshes/heel-connector_1.stl" scale="0.001 0.001 0.001"/>
    </geometry>
    <material name="opaque191191191"/>
  </visual>
  <collision>
    <origin xyz="0.00244 0.173519 1.325356" rpy="0 0 0"/>
    <geometry>
      <mesh filename="package://humanoidrightleg_description/meshes/heel-connector_1.stl" scale="0.001 0.001 0.001"/>
    </geometry>
  </collision>
</link>

<link name="heel-roller_1">
  <inertial>
    <origin xyz="6.334580617755117e-05 0.015000086220057995 9.9846556844696e-07" rpy="0 0 0"/>
    <mass value="0.0038758346823397284"/>
    <inertia ixx="0.0" iyy="0.0" izz="0.0" ixy="-0.0" iyz="-0.0" ixz="-0.0"/>
  </inertial>
  <visual>
    <origin xyz="-0.015529 0.173596 1.324296" rpy="0 0 0"/>
    <geometry>
      <mesh filename="package://humanoidrightleg_description/meshes/heel-roller_1.stl" scale="0.001 0.001 0.001"/>
    </geometry>
    <material name="opaque191191191"/>
  </visual>
  <collision>
    <origin xyz="-0.015529 0.173596 1.324296" rpy="0 0 0"/>
    <geometry>
      <mesh filename="package://humanoidrightleg_description/meshes/heel-roller_1.stl" scale="0.001 0.001 0.001"/>
    </geometry>
  </collision>
</link>

<link name="new-heel-opposing_1">
  <inertial>
    <origin xyz="0.012086588542311618 0.014884864873255743 0.00029380458087047145" rpy="0 0 0"/>
    <mass value="0.03545739064624023"/>
    <inertia ixx="7e-06" iyy="8e-06" izz="7e-06" ixy="-1e-06" iyz="0.0" ixz="1e-06"/>
  </inertial>
  <visual>
    <origin xyz="0.002313 0.14352 1.325355" rpy="0 0 0"/>
    <geometry>
      <mesh filename="package://humanoidrightleg_description/meshes/new-heel-opposing_1.stl" scale="0.001 0.001 0.001"/>
    </geometry>
    <material name="opaque191191191"/>
  </visual>
  <collision>
    <origin xyz="0.002313 0.14352 1.325355" rpy="0 0 0"/>
    <geometry>
      <mesh filename="package://humanoidrightleg_description/meshes/new-heel-opposing_1.stl" scale="0.001 0.001 0.001"/>
    </geometry>
  </collision>
</link>

<link name="heel-top_MIRleft_1">
  <inertial>
    <origin xyz="0.026748510497060198 0.002020611964698077 0.007409601203546279" rpy="0 0 0"/>
    <mass value="0.034657089982925555"/>
    <inertia ixx="6e-06" iyy="8e-06" izz="9e-06" ixy="0.0" iyz="0.0" ixz="-0.0"/>
  </inertial>
  <visual>
    <origin xyz="-0.023997 0.128632 1.311784" rpy="0 0 0"/>
    <geometry>
      <mesh filename="package://humanoidrightleg_description/meshes/heel-top_MIRleft_1.stl" scale="0.001 0.001 0.001"/>
    </geometry>
    <material name="opaque245245245"/>
  </visual>
  <collision>
    <origin xyz="-0.023997 0.128632 1.311784" rpy="0 0 0"/>
    <geometry>
      <mesh filename="package://humanoidrightleg_description/meshes/heel-top_MIRleft_1.stl" scale="0.001 0.001 0.001"/>
    </geometry>
  </collision>
</link>

<link name="ankle-motor-driver-bracket_left_1">
  <inertial>
    <origin xyz="0.026883486994891338 -0.00013165307081677846 0.0017835640372623196" rpy="0 0 0"/>
    <mass value="0.02264633041173002"/>
    <inertia ixx="3e-06" iyy="6e-06" izz="8e-06" ixy="0.0" iyz="0.0" ixz="-0.0"/>
  </inertial>
  <visual>
    <origin xyz="-0.025765 0.128638 1.341732" rpy="0 0 0"/>
    <geometry>
      <mesh filename="package://humanoidrightleg_description/meshes/ankle-motor-driver-bracket_left_1.stl" scale="0.001 0.001 0.001"/>
    </geometry>
    <material name="opaque191191191"/>
  </visual>
  <collision>
    <origin xyz="-0.025765 0.128638 1.341732" rpy="0 0 0"/>
    <geometry>
      <mesh filename="package://humanoidrightleg_description/meshes/ankle-motor-driver-bracket_left_1.stl" scale="0.001 0.001 0.001"/>
    </geometry>
  </collision>
</link>

<link name="210mm-tie-rod_v1_1">
  <inertial>
    <origin xyz="-0.011689506216356893 -0.008945060214517103 -0.10435198667575407" rpy="0 0 0"/>
    <mass value="0.08376049108111246"/>
    <inertia ixx="0.000443" iyy="0.000449" izz="8e-06" ixy="0.0" iyz="0.0" ixz="-4.9e-05"/>
  </inertial>
  <visual>
    <origin xyz="-0.073013 0.205852 1.086758" rpy="0 0 0"/>
    <geometry>
      <mesh filename="package://humanoidrightleg_description/meshes/210mm-tie-rod_v1_1.stl" scale="0.001 0.001 0.001"/>
    </geometry>
    <material name="opaque191191191"/>
  </visual>
  <collision>
    <origin xyz="-0.073013 0.205852 1.086758" rpy="0 0 0"/>
    <geometry>
      <mesh filename="package://humanoidrightleg_description/meshes/210mm-tie-rod_v1_1.stl" scale="0.001 0.001 0.001"/>
    </geometry>
  </collision>
</link>

<link name="290mm-tie-rod_v1_1">
  <inertial>
    <origin xyz="-0.008615579140272889 0.008994003849486426 -0.14474127646108226" rpy="0 0 0"/>
    <mass value="0.31671295572679664"/>
    <inertia ixx="0.00297" iyy="0.002983" izz="1.9e-05" ixy="0.0" iyz="1e-06" ixz="-0.000177"/>
  </inertial>
  <visual>
    <origin xyz="-0.067788 0.111833 1.005822" rpy="0 0 0"/>
    <geometry>
      <mesh filename="package://humanoidrightleg_description/meshes/290mm-tie-rod_v1_1.stl" scale="0.001 0.001 0.001"/>
    </geometry>
    <material name="opaque191191191"/>
  </visual>
  <collision>
    <origin xyz="-0.067788 0.111833 1.005822" rpy="0 0 0"/>
    <geometry>
      <mesh filename="package://humanoidrightleg_description/meshes/290mm-tie-rod_v1_1.stl" scale="0.001 0.001 0.001"/>
    </geometry>
  </collision>
</link>

<link name="DumX290mm_1">
  <inertial>
    <origin xyz="1.0419206712013185e-05 0.0024995291390909197 2.824488207764375e-07" rpy="0 0 0"/>
    <mass value="0.0015849694957623514"/>
    <inertia ixx="0.0" iyy="0.0" izz="0.0" ixy="0.0" iyz="0.0" ixz="-0.0"/>
  </inertial>
  <visual>
    <origin xyz="-0.0504 0.108744 1.295203" rpy="0 0 0"/>
    <geometry>
      <mesh filename="package://humanoidrightleg_description/meshes/DumX290mm_1.stl" scale="0.001 0.001 0.001"/>
    </geometry>
    <material name="powder_coat_green"/>
  </visual>
  <collision>
    <origin xyz="-0.0504 0.108744 1.295203" rpy="0 0 0"/>
    <geometry>
      <mesh filename="package://humanoidrightleg_description/meshes/DumX290mm_1.stl" scale="0.001 0.001 0.001"/>
    </geometry>
  </collision>
</link>

<link name="DumX210mm_1">
  <inertial>
    <origin xyz="-1.1054059686599338e-05 -0.0024995255150774 -7.880524033332392e-08" rpy="0 0 0"/>
    <mass value="0.00158496949576234"/>
    <inertia ixx="0.0" iyy="0.0" izz="0.0" ixy="0.0" iyz="0.0" ixz="0.0"/>
  </inertial>
  <visual>
    <origin xyz="-0.049976 0.208744 1.295208" rpy="0 0 0"/>
    <geometry>
      <mesh filename="package://humanoidrightleg_description/meshes/DumX210mm_1.stl" scale="0.001 0.001 0.001"/>
    </geometry>
    <material name="powder_coat_green"/>
  </visual>
  <collision>
    <origin xyz="-0.049976 0.208744 1.295208" rpy="0 0 0"/>
    <geometry>
      <mesh filename="package://humanoidrightleg_description/meshes/DumX210mm_1.stl" scale="0.001 0.001 0.001"/>
    </geometry>
  </collision>
</link>

<link name="flank-front_1">
  <inertial>
    <origin xyz="-0.01791657845352637 0.002155213376527576 -0.14018258163442304" rpy="0 0 0"/>
    <mass value="0.12933273136842205"/>
    <inertia ixx="0.000362" iyy="0.000452" izz="0.00025" ixy="7.7e-05" iyz="-4.9e-05" ixz="3.9e-05"/>
  </inertial>
  <visual>
    <origin xyz="-0.112081 0.122308 0.391148" rpy="0 0 0"/>
    <geometry>
      <mesh filename="package://humanoidrightleg_description/meshes/flank-front_1.stl" scale="0.001 0.001 0.001"/>
    </geometry>
    <material name="opaque191191191"/>
  </visual>
  <collision>
    <origin xyz="-0.112081 0.122308 0.391148" rpy="0 0 0"/>
    <geometry>
      <mesh filename="package://humanoidrightleg_description/meshes/flank-front_1.stl" scale="0.001 0.001 0.001"/>
    </geometry>
  </collision>
</link>

<link name="flank-front-flipped_1">
  <inertial>
    <origin xyz="-0.03036859549211453 -0.01483033130427247 0.12998692203809636" rpy="0 0 0"/>
    <mass value="0.08003832707286182"/>
    <inertia ixx="0.000155" iyy="0.000137" izz="7.9e-05" ixy="2.4e-05" iyz="-7e-06" ixz="1.4e-05"/>
  </inertial>
  <visual>
    <origin xyz="0.003777 0.183379 0.755117" rpy="0 0 0"/>
    <geometry>
      <mesh filename="package://humanoidrightleg_description/meshes/flank-front-flipped_1.stl" scale="0.001 0.001 0.001"/>
    </geometry>
    <material name="opaque191191191"/>
  </visual>
  <collision>
    <origin xyz="0.003777 0.183379 0.755117" rpy="0 0 0"/>
    <geometry>
      <mesh filename="package://humanoidrightleg_description/meshes/flank-front-flipped_1.stl" scale="0.001 0.001 0.001"/>
    </geometry>
  </collision>
</link>

<link name="flank_1">
  <inertial>
    <origin xyz="0.008778737665157726 -0.025797935947712514 0.1263369038901916" rpy="0 0 0"/>
    <mass value="0.07685908937851611"/>
    <inertia ixx="0.000124" iyy="0.000118" izz="5.4e-05" ixy="1e-05" iyz="1.2e-05" ixz="7e-06"/>
  </inertial>
  <visual>
    <origin xyz="-0.002209 0.163754 0.751243" rpy="0 0 0"/>
    <geometry>
      <mesh filename="package://humanoidrightleg_description/meshes/flank_1.stl" scale="0.001 0.001 0.001"/>
    </geometry>
    <material name="opaque191191191"/>
  </visual>
  <collision>
    <origin xyz="-0.002209 0.163754 0.751243" rpy="0 0 0"/>
    <geometry>
      <mesh filename="package://humanoidrightleg_description/meshes/flank_1.stl" scale="0.001 0.001 0.001"/>
    </geometry>
  </collision>
</link>

<link name="flank__1__1">
  <inertial>
    <origin xyz="-0.02619092786075346 -0.025383598932329193 0.12398642101127921" rpy="0 0 0"/>
    <mass value="0.07685908937851611"/>
    <inertia ixx="0.000124" iyy="0.000118" izz="5.4e-05" ixy="-1.2e-05" iyz="1.1e-05" ixz="3e-06"/>
  </inertial>
  <visual>
    <origin xyz="0.003777 0.163683 0.751645" rpy="0 0 0"/>
    <geometry>
      <mesh filename="package://humanoidrightleg_description/meshes/flank__1__1.stl" scale="0.001 0.001 0.001"/>
    </geometry>
    <material name="opaque191191191"/>
  </visual>
  <collision>
    <origin xyz="0.003777 0.163683 0.751645" rpy="0 0 0"/>
    <geometry>
      <mesh filename="package://humanoidrightleg_description/meshes/flank__1__1.stl" scale="0.001 0.001 0.001"/>
    </geometry>
  </collision>
</link>

<link name="flank-front__1__1">
  <inertial>
    <origin xyz="0.019703071523969287 0.03667495694103595 -0.11038674044034041" rpy="0 0 0"/>
    <mass value="0.12933273136842205"/>
    <inertia ixx="0.000462" iyy="0.000376" izz="0.000226" ixy="-6.6e-05" iyz="-2.8e-05" ixz="-2.5e-05"/>
  </inertial>
  <visual>
    <origin xyz="-0.105183 0.24361 0.41353" rpy="0 0 0"/>
    <geometry>
      <mesh filename="package://humanoidrightleg_description/meshes/flank-front__1__1.stl" scale="0.001 0.001 0.001"/>
    </geometry>
    <material name="opaque191191191"/>
  </visual>
  <collision>
    <origin xyz="-0.105183 0.24361 0.41353" rpy="0 0 0"/>
    <geometry>
      <mesh filename="package://humanoidrightleg_description/meshes/flank-front__1__1.stl" scale="0.001 0.001 0.001"/>
    </geometry>
  </collision>
</link>

<joint name="Rigid 1" type="fixed">
  <origin xyz="0.051881 -0.150582 -0.365243" rpy="0 0 0"/>
  <parent link="base_link"/>
  <child link="RMD-X10-S2_MIR4__3_Rotor_1"/>
</joint>

<joint name="Revolute 2" type="continuous">
  <origin xyz="0.0 0.0 0.0" rpy="0 0 0"/>
  <parent link="RMD-X10-S2_MIR4__3_Rotor_1"/>
  <child link="RMD-X10-S2_MIR4__3_Stator_1"/>
  <axis xyz="-0.0 0.984808 0.173648"/>
</joint>

<joint name="Rigid 3" type="fixed">
  <origin xyz="-0.018138 0.001972 -0.011182" rpy="0 0 0"/>
  <parent link="hip-motor-bracket-v5-right_MIR_1"/>
  <child link="leg-pitch-elastic__1__1"/>
</joint>

<joint name="Rigid 4" type="fixed">
  <origin xyz="-0.029893 0.004781 -0.027116" rpy="0 0 0"/>
  <parent link="hip-motor-bracket-v5-right_MIR_1"/>
  <child link="leg-pitch-elastic__3__1"/>
</joint>

<joint name="Rigid 6" type="fixed">
  <origin xyz="0.064184 0.012358 -0.070084" rpy="0 0 0"/>
  <parent link="hip-motor-bracket-v5-right_MIR_1"/>
  <child link="leg-pitch-elastic__2__1"/>
</joint>

<joint name="Rigid 7" type="fixed">
  <origin xyz="0.052429 0.015167 -0.086018" rpy="0 0 0"/>
  <parent link="hip-motor-bracket-v5-right_MIR_1"/>
  <child link="leg-pitch-elastic_1"/>
</joint>

<joint name="Rigid 8" type="fixed">
  <origin xyz="-0.053 -0.001969 -0.000348" rpy="0 0 0"/>
  <parent link="RMD-X10-S2_MIR4__3_Stator_1"/>
  <child link="hip-motor-bracket-v5-right_MIR_1"/>
</joint>

<joint name="Rigid 9" type="fixed">
  <origin xyz="0.010122 0.014273 -0.029116" rpy="0 0 0"/>
  <parent link="hip-motor-bracket-v5-right_MIR_1"/>
  <child link="innner-thigh-magnet-encoder__1__1"/>
</joint>

<joint name="Rigid 10" type="fixed">
  <origin xyz="0.053 -0.001969 -0.000348" rpy="0 0 0"/>
  <parent link="RMD-X10-S2_MIR4__3_Stator_1"/>
  <child link="knee-bend-motor-bracket-hip_1"/>
</joint>

<joint name="Rigid 11" type="fixed">
  <origin xyz="0.053 -0.060073 -0.010593" rpy="0 0 0"/>
  <parent link="RMD-X10-S2_MIR4__3_Stator_1"/>
  <child link="knee-bend-motor-bracket-hip__1__1"/>
</joint>

<joint name="Rigid 12" type="fixed">
  <origin xyz="-0.035087 0.008386 -0.04756" rpy="0 0 0"/>
  <parent link="hip-motor-bracket-v5-right_MIR_1"/>
  <child link="RMD-X10-S2_MIR4Stator_1"/>
</joint>

<joint name="Revolute 13" type="continuous">
  <origin xyz="0.016378 -0.05132 -0.060233" rpy="0 0 0"/>
  <parent link="RMD-X10-S2_MIR4Stator_1"/>
  <child link="RMD-X10-S2_MIR4Rotor_1"/>
  <axis xyz="0.0 -0.984808 -0.173648"/>
</joint>

<joint name="Rigid 14" type="fixed">
  <origin xyz="-0.036622 -0.049351 -0.059886" rpy="0 0 0"/>
  <parent link="RMD-X10-S2_MIR4Stator_1"/>
  <child link="thigh-outer-encoder-mount__1__1"/>
</joint>

<joint name="Rigid 15" type="fixed">
  <origin xyz="0.0 -0.040598 -0.109526" rpy="0 0 0"/>
  <parent link="RMD-X10-S2_MIR4Stator_1"/>
  <child link="limit-bracket-knee_1"/>
</joint>

<joint name="Rigid 16" type="fixed">
  <origin xyz="0.006964 -0.059768 -0.000806" rpy="0 0 0"/>
  <parent link="leg-pitch-elastic__1__1"/>
  <child link="hip-motor-bracket-v5-right_MIR__1__1"/>
</joint>

<joint name="Rigid 17" type="fixed">
  <origin xyz="0.076765 -0.001905 0.023419" rpy="0 0 0"/>
  <parent link="limit-bracket-knee_1"/>
  <child link="NO-NC_Bump_Switch__1__1"/>
</joint>

<joint name="Rigid 18" type="fixed">
  <origin xyz="0.002241 0.004632 -0.013659" rpy="0 0 0"/>
  <parent link="limit-bracket-knee_1"/>
  <child link="NO-NC_Bump_Switch_1"/>
</joint>

<joint name="Rigid 19" type="fixed">
  <origin xyz="0.0 0.0 0.0" rpy="0 0 0"/>
  <parent link="RMD-X10-S2_MIR4Rotor_1"/>
  <child link="hip-ex-al-base_MIR_1"/>
</joint>

<joint name="Rigid 20" type="fixed">
  <origin xyz="0.0 -0.02659 -0.004688" rpy="0 0 0"/>
  <parent link="hip-ex-al-base_MIR_1"/>
  <child link="motorcap-KNEE_MIR_1"/>
</joint>

<joint name="Rigid 21" type="fixed">
  <origin xyz="0.008616 -0.013431 0.018583" rpy="0 0 0"/>
  <parent link="motorcap-KNEE_MIR_1"/>
  <child link="2020_300mm__1__1"/>
</joint>

<joint name="Rigid 22" type="fixed">
  <origin xyz="-0.000659 -0.021373 0.006036" rpy="0 0 0"/>
  <parent link="motorcap-KNEE_MIR_1"/>
  <child link="magmount__1__1"/>
</joint>

<joint name="Rigid 23" type="fixed">
  <origin xyz="0.000451 0.070183 -0.292928" rpy="0 0 0"/>
  <parent link="2020_300mm__1__1"/>
  <child link="multiplex-stack_1"/>
</joint>

<joint name="Rigid 24" type="fixed">
  <origin xyz="0.002197 0.071885 -0.292507" rpy="0 0 0"/>
  <parent link="2020_300mm__1__1"/>
  <child link="thigh-nub_1"/>
</joint>

<joint name="Rigid 25" type="fixed">
  <origin xyz="0.002197 0.071885 -0.292507" rpy="0 0 0"/>
  <parent link="2020_300mm__1__1"/>
  <child link="knee-lock-2-b_1"/>
</joint>

<joint name="Rigid 26" type="fixed">
  <origin xyz="0.002197 0.052189 -0.29598" rpy="0 0 0"/>
  <parent link="2020_300mm__1__1"/>
  <child link="knee-lock-2_1"/>
</joint>

<joint name="Rigid 27" type="fixed">
  <origin xyz="0.010428 0.06194 -0.293691" rpy="0 0 0"/>
  <parent link="2020_300mm__1__1"/>
  <child link="bearingstrap__1__1"/>
</joint>

<joint name="Revolute 28" type="continuous">
  <origin xyz="0.00102 0.012447 -0.013001" rpy="0 0 0"/>
  <parent link="bearingstrap__1__1"/>
  <child link="skateboard-bearing__13__1"/>
  <axis xyz="-0.0 0.984808 0.173648"/>
</joint>

<joint name="Revolute 29" type="continuous">
  <origin xyz="0.00102 -0.00725 -0.016474" rpy="0 0 0"/>
  <parent link="bearingstrap__1__1"/>
  <child link="skateboard-bearing__14__1"/>
  <axis xyz="0.0 -0.984808 -0.173648"/>
</joint>

<joint name="Rigid 30" type="fixed">
  <origin xyz="0.0 0.0 0.0" rpy="0 0 0"/>
  <parent link="skateboard-bearing__14__1"/>
  <child link="conjstraint-knee-test-oute_MIR_1"/>
</joint>

<joint name="Rigid 31" type="fixed">
  <origin xyz="0.0 0.0 0.0" rpy="0 0 0"/>
  <parent link="skateboard-bearing__13__1"/>
  <child link="conjstraint-knee-test-oute_1"/>
</joint>

<joint name="Rigid 32" type="fixed">
  <origin xyz="-0.002594 -0.015375 -0.019342" rpy="0 0 0"/>
  <parent link="knee-bend-motor-bracket-hip__1__1"/>
  <child link="skateboard-bearing__15__1"/>
</joint>

<joint name="Revolute 33" type="continuous">
  <origin xyz="0.0 -0.000492 -8.6e-05" rpy="0 0 0"/>
  <parent link="skateboard-bearing__15__1"/>
  <child link="bearingstrap_1"/>
  <axis xyz="-0.0 0.984808 0.173648"/>
</joint>

<joint name="Revolute 34" type="continuous">
  <origin xyz="0.0 -0.019696 -0.003473" rpy="0 0 0"/>
  <parent link="bearingstrap_1"/>
  <child link="skateboard-bearing_1"/>
  <axis xyz="0.0 -0.984808 -0.173648"/>
</joint>

<joint name="Rigid 35" type="fixed">
  <origin xyz="-0.000104 -0.007244 -0.016509" rpy="0 0 0"/>
  <parent link="bearingstrap_1"/>
  <child link="2020_300mm__2__1"/>
</joint>

<joint name="Rigid 36" type="fixed">
  <origin xyz="-0.002594 0.021063 -0.012916" rpy="0 0 0"/>
  <parent link="knee-bend-motor-bracket-hip_1"/>
  <child link="skateboard-bearing__8__1"/>
</joint>

<joint name="Revolute 37" type="continuous">
  <origin xyz="0.0 -0.00033 -5.9e-05" rpy="0 0 0"/>
  <parent link="skateboard-bearing__8__1"/>
  <child link="bearingstrap-inner-thigh_1"/>
  <axis xyz="0.0 -0.984808 -0.173648"/>
</joint>

<joint name="Revolute 38" type="continuous">
  <origin xyz="0.0 0.019696 0.003473" rpy="0 0 0"/>
  <parent link="bearingstrap-inner-thigh_1"/>
  <child link="skateboard-bearing__9__1"/>
  <axis xyz="-0.0 0.984808 0.173648"/>
</joint>

<joint name="Rigid 40" type="fixed">
  <origin xyz="0.009919 0.002617 -0.011367" rpy="0 0 0"/>
  <parent link="bearingstrap-inner-thigh_1"/>
  <child link="2020_150mm__1___1__1"/>
</joint>

<joint name="Rigid 41" type="fixed">
  <origin xyz="-0.011116 -0.016212 -0.149385" rpy="0 0 0"/>
  <parent link="2020_150mm__1___1__1"/>
  <child link="2020_100mm__12__1"/>
</joint>

<joint name="Rigid 42" type="fixed">
  <origin xyz="0.00757 -0.007508 -0.100271" rpy="0 0 0"/>
  <parent link="2020_100mm__12__1"/>
  <child link="6band__5__1"/>
</joint>

<joint name="Rigid 43" type="fixed">
  <origin xyz="-0.000656 -0.017366 -0.098478" rpy="0 0 0"/>
  <parent link="2020_100mm__12__1"/>
  <child link="leg-thigh-knee-support-bottom_1"/>
</joint>

<joint name="Rigid 44" type="fixed">
  <origin xyz="0.009853 -0.009294 -0.022953" rpy="0 0 0"/>
  <parent link="leg-thigh-knee-support-bottom_1"/>
  <child link="thigh-bracket_1"/>
</joint>

<joint name="Rigid 45" type="fixed">
  <origin xyz="-0.002095 0.052094 -0.295435" rpy="0 0 0"/>
  <parent link="2020_300mm__2__1"/>
  <child link="double-bracket_1"/>
</joint>

<joint name="Revolute 46" type="continuous">
  <origin xyz="-0.000104 -0.007244 -0.016508" rpy="0 0 0"/>
  <parent link="double-bracket_1"/>
  <child link="skateboard-bearing__11__1"/>
  <axis xyz="0.0 -0.984808 -0.173648"/>
</joint>

<joint name="Revolute 47" type="continuous">
  <origin xyz="-0.060103 -0.007317 -0.016096" rpy="0 0 0"/>
  <parent link="double-bracket_1"/>
  <child link="skateboard-bearing__20__1"/>
  <axis xyz="0.0 -0.984808 -0.173648"/>
</joint>

<joint name="Revolute 48" type="continuous">
  <origin xyz="-0.000104 0.012452 -0.013035" rpy="0 0 0"/>
  <parent link="double-bracket_1"/>
  <child link="skateboard-bearing__10__1"/>
  <axis xyz="-0.0 0.984808 0.173648"/>
</joint>

<joint name="Revolute 49" type="continuous">
  <origin xyz="-0.060103 0.01238 -0.012623" rpy="0 0 0"/>
  <parent link="double-bracket_1"/>
  <child link="skateboard-bearing__16__1"/>
  <axis xyz="-0.0 0.984808 0.173648"/>
</joint>

<joint name="Rigid 50" type="fixed">
  <origin xyz="0.007905 0.043981 -0.296936" rpy="0 0 0"/>
  <parent link="2020_300mm__2__1"/>
  <child link="dumXrigid_1"/>
</joint>

<joint name="Rigid 51" type="fixed">
  <origin xyz="0.0 0.0 0.0" rpy="0 0 0"/>
  <parent link="skateboard-bearing__20__1"/>
  <child link="knee-strap-second-test__1__1"/>
</joint>

<joint name="Rigid 52" type="fixed">
  <origin xyz="0.0 0.0 0.0" rpy="0 0 0"/>
  <parent link="skateboard-bearing__16__1"/>
  <child link="knee-strap-second-test_1"/>
</joint>

<joint name="Rigid 53" type="fixed">
  <origin xyz="0.045791 0.017368 -0.098496" rpy="0 0 0"/>
  <parent link="knee-strap-second-test__1__1"/>
  <child link="skateboard-bearing__19__1"/>
</joint>

<joint name="Rigid 54" type="fixed">
  <origin xyz="0.045791 0.017367 -0.098496" rpy="0 0 0"/>
  <parent link="knee-strap-second-test_1"/>
  <child link="skateboard-bearing__18__1"/>
</joint>

<joint name="Rigid 55" type="fixed">
  <origin xyz="0.025452 0.009435 -0.053509" rpy="0 0 0"/>
  <parent link="conjstraint-knee-test-oute_MIR_1"/>
  <child link="skateboard-bearing__17__1"/>
</joint>

<joint name="Rigid 56" type="fixed">
  <origin xyz="0.025452 0.009435 -0.053509" rpy="0 0 0"/>
  <parent link="conjstraint-knee-test-oute_1"/>
  <child link="skateboard-bearing__12__1"/>
</joint>

<joint name="Revolute 57" type="continuous">
  <origin xyz="0.0 0.0 0.0" rpy="0 0 0"/>
  <parent link="skateboard-bearing__19__1"/>
  <child link="double-bracket-10deg_MIR_MIR_MIR_1"/>
  <axis xyz="0.0 -0.984808 -0.173648"/>
</joint>

<joint name="Rigid 58" type="fixed">
  <origin xyz="0.000433 0.012701 -0.015752" rpy="0 0 0"/>
  <parent link="double-bracket-10deg_MIR_MIR_MIR_1"/>
  <child link="400mmexal_MIR2_MIR3_1"/>
</joint>

<joint name="Rigid 59" type="fixed">
  <origin xyz="0.0 0.0 0.0" rpy="0 0 0"/>
  <parent link="400mmexal_MIR2_MIR3_1"/>
  <child link="2020_400mm_1"/>
</joint>

<joint name="Rigid 60" type="fixed">
  <origin xyz="4.2e-05 0.01 1e-06" rpy="0 0 0"/>
  <parent link="400mmexal_MIR2_MIR3_1"/>
  <child link="motor-calf-exal-mount_4"/>
</joint>

<joint name="Rigid 61" type="fixed">
  <origin xyz="-4.2e-05 -0.01 0.0" rpy="0 0 0"/>
  <parent link="400mmexal_MIR2_MIR3_1"/>
  <child link="motor-calf-exal-mount_3"/>
</joint>

<joint name="Rigid 62" type="fixed">
  <origin xyz="-0.015646 0.007573 -0.138225" rpy="0 0 0"/>
  <parent link="motor-calf-exal-mount_4"/>
  <child link="RMD-X8-Pro_MIR8_MIR1_2"/>
</joint>

<joint name="Rigid 63" type="fixed">
  <origin xyz="-0.04075 -0.034829 0.027966" rpy="0 0 0"/>
  <parent link="RMD-X8-Pro_MIR8_MIR1_2"/>
  <child link="calf-skin_1"/>
</joint>

<joint name="Rigid 64" type="fixed">
  <origin xyz="-0.04069 0.000171 0.027966" rpy="0 0 0"/>
  <parent link="RMD-X8-Pro_MIR8_MIR1_2"/>
  <child link="calf-skin_flip_1"/>
</joint>

<joint name="Rigid 65" type="fixed">
  <origin xyz="-0.014242 -0.034937 -0.047397" rpy="0 0 0"/>
  <parent link="RMD-X8-Pro_MIR8_MIR1_2"/>
  <child link="calf-cover_1"/>
</joint>

<joint name="Rigid 66" type="fixed">
  <origin xyz="-0.014023 6.2e-05 -0.047341" rpy="0 0 0"/>
  <parent link="RMD-X8-Pro_MIR8_MIR1_2"/>
  <child link="calf-cover_2"/>
</joint>

<joint name="Revolute 67" type="continuous">
  <origin xyz="-0.03958 0.002669 -0.01402" rpy="0 0 0"/>
  <parent link="RMD-X8-Pro_MIR8_MIR1_2"/>
  <child link="calf-motor-driver-ext_1"/>
  <axis xyz="0.004243 0.999991 5.1e-05"/>
</joint>

<joint name="Rigid 74" type="fixed">
  <origin xyz="-0.037447 0.01516 -0.006869" rpy="0 0 0"/>
  <parent link="calf-cover_2"/>
  <child link="bearing-sensor-adapter_2"/>
</joint>

<joint name="Rigid 75" type="fixed">
  <origin xyz="3.1e-05 0.007499 0.0" rpy="0 0 0"/>
  <parent link="bearing-sensor-adapter_2"/>
  <child link="bearing-sensor-adapter-arm_2"/>
</joint>

<joint name="Rigid 76" type="fixed">
  <origin xyz="-0.037575 -0.014841 -0.006871" rpy="0 0 0"/>
  <parent link="calf-cover_1"/>
  <child link="bearing-sensor-adapter_1"/>
</joint>

<joint name="Rigid 77" type="fixed">
  <origin xyz="-3.2e-05 -0.0075 0.0" rpy="0 0 0"/>
  <parent link="bearing-sensor-adapter_1"/>
  <child link="bearing-sensor-adapter-arm_1"/>
</joint>

<joint name="Rigid 78" type="fixed">
  <origin xyz="0.000723 -2e-06 -0.030034" rpy="0 0 0"/>
  <parent link="calf-cover_1"/>
  <child link="RMD-X8-Pro_MIR8_MIR1_1"/>
</joint>

<joint name="Rigid 79" type="fixed">
  <origin xyz="0.015833 0.034934 -0.020574" rpy="0 0 0"/>
  <parent link="RMD-X8-Pro_MIR8_MIR1_1"/>
  <child link="motor-calf-exal-mount_1"/>
</joint>

<joint name="Rigid 80" type="fixed">
  <origin xyz="0.015714 -6.5e-05 -0.02066" rpy="0 0 0"/>
  <parent link="RMD-X8-Pro_MIR8_MIR1_1"/>
  <child link="motor-calf-exal-mount_2"/>
</joint>

<joint name="Revolute 81" type="continuous">
  <origin xyz="-0.023946 -0.002396 -0.034512" rpy="0 0 0"/>
  <parent link="RMD-X8-Pro_MIR8_MIR1_1"/>
  <child link="calf-motor-driver-ext_2"/>
  <axis xyz="-0.004243 -0.999991 -5.1e-05"/>
</joint>

<joint name="Rigid 82" type="fixed">
  <origin xyz="0.00171 0.034997 -0.067885" rpy="0 0 0"/>
  <parent link="RMD-X8-Pro_MIR8_MIR1_1"/>
  <child link="calf-lower-bracket_left_1"/>
</joint>

<joint name="Rigid 83" type="fixed">
  <origin xyz="0.001491 -3e-06 -0.067941" rpy="0 0 0"/>
  <parent link="RMD-X8-Pro_MIR8_MIR1_1"/>
  <child link="calf-lower-bracket_1"/>
</joint>

<joint name="Rigid 84" type="fixed">
  <origin xyz="0.009624 -2.1e-05 -0.399884" rpy="0 0 0"/>
  <parent link="400mmexal_MIR2_MIR3_1"/>
  <child link="ankle-thick_1"/>
</joint>

<joint name="Rigid 85" type="fixed">
  <origin xyz="0.017378 0.009925 0.027825" rpy="0 0 0"/>
  <parent link="ankle-thick_1"/>
  <child link="ankle-side-bracket_2"/>
</joint>

<joint name="Rigid 86" type="fixed">
  <origin xyz="0.017293 -0.010074 0.027824" rpy="0 0 0"/>
  <parent link="ankle-thick_1"/>
  <child link="ankle-side-bracket_1"/>
</joint>

<joint name="Revolute 87" type="continuous">
  <origin xyz="0.000885 0.009999 -0.034989" rpy="0 0 0"/>
  <parent link="ankle-thick_1"/>
  <child link="basis_left_1"/>
  <axis xyz="0.004243 0.999991 5.1e-05"/>
</joint>

<joint name="Revolute 88" type="continuous">
  <origin xyz="0.02228 -0.010093 -0.038753" rpy="0 0 0"/>
  <parent link="basis_left_1"/>
  <child link="skateboard-bearing_left_2"/>
  <axis xyz="0.998253 -0.004238 0.058936"/>
</joint>

<joint name="Revolute 89" type="continuous">
  <origin xyz="-0.01765 -0.009924 -0.04111" rpy="0 0 0"/>
  <parent link="basis_left_1"/>
  <child link="skateboard-bearing_left_1"/>
  <axis xyz="-0.998253 0.004238 -0.058936"/>
</joint>

<joint name="Rigid 90" type="fixed">
  <origin xyz="0.0 0.0 0.0" rpy="0 0 0"/>
  <parent link="skateboard-bearing_left_2"/>
  <child link="heel-bracket_left_1"/>
</joint>

<joint name="Rigid 91" type="fixed">
  <origin xyz="0.044837 -0.020191 0.002651" rpy="0 0 0"/>
  <parent link="heel-bracket_left_1"/>
  <child link="tie-rod-ankle-brackket_left1_1"/>
</joint>

<joint name="Rigid 92" type="fixed">
  <origin xyz="0.010067 0.019957 0.000591" rpy="0 0 0"/>
  <parent link="heel-bracket_left_1"/>
  <child link="tie-rod-ankle-brackket_left_1"/>
</joint>

<joint name="Rigid 93" type="fixed">
  <origin xyz="-0.035614 -0.019849 0.007919" rpy="0 0 0"/>
  <parent link="tie-rod-ankle-brackket_left1_1"/>
  <child link="foot-imu-strap_1"/>
</joint>

<joint name="Rigid 94" type="fixed">
  <origin xyz="0.027332 -0.000116 0.006623" rpy="0 0 0"/>
  <parent link="foot-imu-strap_1"/>
  <child link="mpu1_1"/>
</joint>

<joint name="Rigid 95" type="fixed">
  <origin xyz="0.010487 -0.020044 -0.009394" rpy="0 0 0"/>
  <parent link="tie-rod-ankle-brackket_left1_1"/>
  <child link="2020_150mm__6__1"/>
</joint>

<joint name="Rigid 97" type="fixed">
  <origin xyz="0.045596 0.019807 -0.00733" rpy="0 0 0"/>
  <parent link="tie-rod-ankle-brackket_left_1"/>
  <child link="2020_150mm__6__2"/>
</joint>

<joint name="Rigid 98" type="fixed">
  <origin xyz="0.061523 0.00924 -0.006387" rpy="0 0 0"/>
  <parent link="tie-rod-ankle-brackket_left_1"/>
  <child link="toes-rotor_1"/>
</joint>

<joint name="Rigid 99" type="fixed">
  <origin xyz="0.030942 -0.001132 0.001827" rpy="0 0 0"/>
  <parent link="toes-rotor_1"/>
  <child link="toes_1"/>
</joint>

<joint name="Rigid 100" type="fixed">
  <origin xyz="0.040214 -0.029672 0.012397" rpy="0 0 0"/>
  <parent link="toes-rotor_1"/>
  <child link="foot-top_1"/>
</joint>

<joint name="Rigid 101" type="fixed">
  <origin xyz="0.0 0.0 0.0" rpy="0 0 0"/>
  <parent link="2020_150mm__6__1"/>
  <child link="wire-clip_1"/>
</joint>

<joint name="Rigid 102" type="fixed">
  <origin xyz="-0.149738 0.000636 -0.00884" rpy="0 0 0"/>
  <parent link="2020_150mm__6__1"/>
  <child link="heel-topleft_1"/>
</joint>

<joint name="Rigid 103" type="fixed">
  <origin xyz="0.009478 0.019959 0.010573" rpy="0 0 0"/>
  <parent link="heel-topleft_1"/>
  <child link="heel-bracketleft_1"/>
</joint>

<joint name="Rigid 104" type="fixed">
  <origin xyz="0.001178 -4e-06 -0.019966" rpy="0 0 0"/>
  <parent link="heel-bracketleft_1"/>
  <child link="ankle-motor-driver-bracketleft_1"/>
</joint>

<joint name="Rigid 105" type="fixed">
  <origin xyz="-0.000842 0.010003 0.014974" rpy="0 0 0"/>
  <parent link="heel-topleft_1"/>
  <child link="new-heel_1"/>
</joint>

<joint name="Rigid 106" type="fixed">
  <origin xyz="-0.026182 0.015112 -0.013569" rpy="0 0 0"/>
  <parent link="new-heel_1"/>
  <child link="heel-connector_1"/>
</joint>

<joint name="Rigid 107" type="fixed">
  <origin xyz="-0.008213 0.015035 -0.012509" rpy="0 0 0"/>
  <parent link="new-heel_1"/>
  <child link="heel-roller_1"/>
</joint>

<joint name="Rigid 108" type="fixed">
  <origin xyz="0.000127 0.029999 1e-06" rpy="0 0 0"/>
  <parent link="heel-connector_1"/>
  <child link="new-heel-opposing_1"/>
</joint>

<joint name="Rigid 109" type="fixed">
  <origin xyz="0.02631 0.014888 0.013571" rpy="0 0 0"/>
  <parent link="new-heel-opposing_1"/>
  <child link="heel-top_MIRleft_1"/>
</joint>

<joint name="Rigid 110" type="fixed">
  <origin xyz="0.028078 0.014882 -0.016377" rpy="0 0 0"/>
  <parent link="new-heel-opposing_1"/>
  <child link="ankle-motor-driver-bracket_left_1"/>
</joint>

<joint name="Revolute 111" type="continuous">
  <origin xyz="0.039873 -0.02717 0.000961" rpy="0 0 0"/>
  <parent link="calf-motor-driver-ext_2"/>
  <child link="210mm-tie-rod_v1_1"/>
  <axis xyz="-0.004243 -0.999991 -5.1e-05"/>
</joint>

<joint name="Revolute 112" type="continuous">
  <origin xyz="0.036763 0.026845 -0.016026" rpy="0 0 0"/>
  <parent link="calf-motor-driver-ext_1"/>
  <child link="290mm-tie-rod_v1_1"/>
  <axis xyz="0.004243 0.999991 5.1e-05"/>
</joint>

<joint name="Revolute 113" type="continuous">
  <origin xyz="0.026403 0.019888 0.016581" rpy="0 0 0"/>
  <parent link="heel-top_MIRleft_1"/>
  <child link="DumX290mm_1"/>
  <axis xyz="0.004243 0.999991 5.1e-05"/>
</joint>

<joint name="Revolute 114" type="continuous">
  <origin xyz="0.025392 -0.01011 0.031553" rpy="0 0 0"/>
  <parent link="heel-topleft_1"/>
  <child link="DumX210mm_1"/>
  <axis xyz="-0.004243 -0.999991 -5.1e-05"/>
</joint>

<joint name="Rigid 117" type="fixed">
  <origin xyz="-0.000125 0.006893 -0.001215" rpy="0 0 0"/>
  <parent link="2020_150mm__1___1__1"/>
  <child link="flank-front_1"/>
</joint>

<joint name="Rigid 118" type="fixed">
  <origin xyz="0.007435 0.052127 -0.295628" rpy="0 0 0"/>
  <parent link="2020_300mm__1__1"/>
  <child link="flank-front-flipped_1"/>
</joint>

<joint name="Rigid 119" type="fixed">
  <origin xyz="0.013421 0.071752 -0.291754" rpy="0 0 0"/>
  <parent link="2020_300mm__1__1"/>
  <child link="flank_1"/>
</joint>

<joint name="Rigid 120" type="fixed">
  <origin xyz="0.007435 0.071823 -0.292156" rpy="0 0 0"/>
  <parent link="2020_300mm__1__1"/>
  <child link="flank__1__1"/>
</joint>

<joint name="Rigid 121" type="fixed">
  <origin xyz="0.003 -0.009844 -0.001757" rpy="0 0 0"/>
  <parent link="2020_300mm__2__1"/>
  <child link="flank-front__1__1"/>
</joint>

</robot>
