<?xml version="1.0" ?>
<robot name="humanoidrightarm" xmlns:xacro="http://www.ros.org/wiki/xacro">

<xacro:include filename="$(find humanoidrightarm_description)/urdf/materials.xacro" />
<xacro:include filename="$(find humanoidrightarm_description)/urdf/humanoidrightarm.trans" />
<link name="base_link">
  <inertial>
    <origin xyz="-0.03492982794614039 -0.2422203941645376 0.12145614744705392" rpy="0 0 0"/>
    <mass value="0.07102512671235825"/>
    <inertia ixx="1e-05" iyy="2e-05" izz="1e-05" ixy="0.0" iyz="0.0" ixz="-0.0"/>
  </inertial>
  <visual>
    <origin xyz="0 0 0" rpy="0 0 0"/>
    <geometry>
      <mesh filename="package://humanoidrightarm_description/meshes/base_link.stl" scale="0.001 0.001 0.001"/>
    </geometry>
    <material name="opaque2550255"/>
  </visual>
  <collision>
    <origin xyz="0 0 0" rpy="0 0 0"/>
    <geometry>
      <mesh filename="package://humanoidrightarm_description/meshes/base_link.stl" scale="0.001 0.001 0.001"/>
    </geometry>
  </collision>
</link>

<link name="2020_100mm__9__1">
  <inertial>
    <origin xyz="1.7205386051988292e-07 -0.05000039416453783 1.474452240163293e-07" rpy="0 0 0"/>
    <mass value="0.05289771810031747"/>
    <inertia ixx="4.6e-05" iyy="4e-06" izz="4.6e-05" ixy="-0.0" iyz="-0.0" ixz="-0.0"/>
  </inertial>
  <visual>
    <origin xyz="0.03493 0.24472 -0.121456" rpy="0 0 0"/>
    <geometry>
      <mesh filename="package://humanoidrightarm_description/meshes/2020_100mm__9__1.stl" scale="0.001 0.001 0.001"/>
    </geometry>
    <material name="opaque727161"/>
  </visual>
  <collision>
    <origin xyz="0.03493 0.24472 -0.121456" rpy="0 0 0"/>
    <geometry>
      <mesh filename="package://humanoidrightarm_description/meshes/2020_100mm__9__1.stl" scale="0.001 0.001 0.001"/>
    </geometry>
  </collision>
</link>

<link name="shoulder-roll-al-mot_MIR1__1__1">
  <inertial>
    <origin xyz="-0.016582124733096316 -0.013349408107747318 -0.0005766221168803654" rpy="0 0 0"/>
    <mass value="0.016359268258045713"/>
    <inertia ixx="3e-06" iyy="2e-06" izz="1e-06" ixy="-0.0" iyz="-0.0" ixz="0.0"/>
  </inertial>
  <visual>
    <origin xyz="0.03493 0.24472 -0.121456" rpy="0 0 0"/>
    <geometry>
      <mesh filename="package://humanoidrightarm_description/meshes/shoulder-roll-al-mot_MIR1__1__1.stl" scale="0.001 0.001 0.001"/>
    </geometry>
    <material name="opaque245245245"/>
  </visual>
  <collision>
    <origin xyz="0.03493 0.24472 -0.121456" rpy="0 0 0"/>
    <geometry>
      <mesh filename="package://humanoidrightarm_description/meshes/shoulder-roll-al-mot_MIR1__1__1.stl" scale="0.001 0.001 0.001"/>
    </geometry>
  </collision>
</link>

<link name="shoulder-roll-al-mot_MIR1__2__1">
  <inertial>
    <origin xyz="0.016582468840815396 -0.013349408107786065 0.0005769170098288284" rpy="0 0 0"/>
    <mass value="0.016359268258045713"/>
    <inertia ixx="3e-06" iyy="2e-06" izz="1e-06" ixy="0.0" iyz="0.0" ixz="0.0"/>
  </inertial>
  <visual>
    <origin xyz="0.03493 0.24472 -0.121456" rpy="0 0 0"/>
    <geometry>
      <mesh filename="package://humanoidrightarm_description/meshes/shoulder-roll-al-mot_MIR1__2__1.stl" scale="0.001 0.001 0.001"/>
    </geometry>
    <material name="opaque245245245"/>
  </visual>
  <collision>
    <origin xyz="0.03493 0.24472 -0.121456" rpy="0 0 0"/>
    <geometry>
      <mesh filename="package://humanoidrightarm_description/meshes/shoulder-roll-al-mot_MIR1__2__1.stl" scale="0.001 0.001 0.001"/>
    </geometry>
  </collision>
</link>

<link name="yaw-cap_1">
  <inertial>
    <origin xyz="1.7205388214841522e-07 0.0065864356936576884 1.4744378110109757e-07" rpy="0 0 0"/>
    <mass value="0.017312584943862036"/>
    <inertia ixx="5e-06" iyy="3e-06" izz="3e-06" ixy="-0.0" iyz="0.0" ixz="0.0"/>
  </inertial>
  <visual>
    <origin xyz="0.03493 0.34472 -0.121456" rpy="0 0 0"/>
    <geometry>
      <mesh filename="package://humanoidrightarm_description/meshes/yaw-cap_1.stl" scale="0.001 0.001 0.001"/>
    </geometry>
    <material name="opaque245245245"/>
  </visual>
  <collision>
    <origin xyz="0.03493 0.34472 -0.121456" rpy="0 0 0"/>
    <geometry>
      <mesh filename="package://humanoidrightarm_description/meshes/yaw-cap_1.stl" scale="0.001 0.001 0.001"/>
    </geometry>
  </collision>
</link>

<link name="yaw-waist-adapter-motor-exal_MIR1_1">
  <inertial>
    <origin xyz="0.007229833032349101 -0.05000039416453406 0.00025165990479709965" rpy="0 0 0"/>
    <mass value="0.043773488134739254"/>
    <inertia ixx="1.7e-05" iyy="1.5e-05" izz="8e-06" ixy="-0.0" iyz="0.0" ixz="0.0"/>
  </inertial>
  <visual>
    <origin xyz="0.03493 0.24472 -0.121456" rpy="0 0 0"/>
    <geometry>
      <mesh filename="package://humanoidrightarm_description/meshes/yaw-waist-adapter-motor-exal_MIR1_1.stl" scale="0.001 0.001 0.001"/>
    </geometry>
    <material name="opaque245245245"/>
  </visual>
  <collision>
    <origin xyz="0.03493 0.24472 -0.121456" rpy="0 0 0"/>
    <geometry>
      <mesh filename="package://humanoidrightarm_description/meshes/yaw-waist-adapter-motor-exal_MIR1_1.stl" scale="0.001 0.001 0.001"/>
    </geometry>
  </collision>
</link>

<link name="front-bearing-adapter-shoulder_1">
  <inertial>
    <origin xyz="0.008139118661219654 0.008999605835450286 -0.015315200672242388" rpy="0 0 0"/>
    <mass value="0.027709236054798532"/>
    <inertia ixx="9e-06" iyy="6e-06" izz="4e-06" ixy="-0.0" iyz="0.0" ixz="0.0"/>
  </inertial>
  <visual>
    <origin xyz="0.015484 0.30372 -0.137731" rpy="0 0 0"/>
    <geometry>
      <mesh filename="package://humanoidrightarm_description/meshes/front-bearing-adapter-shoulder_1.stl" scale="0.001 0.001 0.001"/>
    </geometry>
    <material name="opaque191191191"/>
  </visual>
  <collision>
    <origin xyz="0.015484 0.30372 -0.137731" rpy="0 0 0"/>
    <geometry>
      <mesh filename="package://humanoidrightarm_description/meshes/front-bearing-adapter-shoulder_1.stl" scale="0.001 0.001 0.001"/>
    </geometry>
  </collision>
</link>

<link name="shoulder-ex-al-interface__2__1">
  <inertial>
    <origin xyz="-0.007724869141817199 0.008999605835474767 -0.01586713537077042" rpy="0 0 0"/>
    <mass value="0.03263560284613005"/>
    <inertia ixx="1e-05" iyy="7e-06" izz="5e-06" ixy="-0.0" iyz="0.0" ixz="0.0"/>
  </inertial>
  <visual>
    <origin xyz="0.045466 0.30372 -0.136688" rpy="0 0 0"/>
    <geometry>
      <mesh filename="package://humanoidrightarm_description/meshes/shoulder-ex-al-interface__2__1.stl" scale="0.001 0.001 0.001"/>
    </geometry>
    <material name="opaque22122113"/>
  </visual>
  <collision>
    <origin xyz="0.045466 0.30372 -0.136688" rpy="0 0 0"/>
    <geometry>
      <mesh filename="package://humanoidrightarm_description/meshes/shoulder-ex-al-interface__2__1.stl" scale="0.001 0.001 0.001"/>
    </geometry>
  </collision>
</link>

<link name="RMD-X8-Pro_MIR8_MIR1__1__1">
  <inertial>
    <origin xyz="-0.02186708225234428 -0.00046215486678247153 -0.000763558782195542" rpy="0 0 0"/>
    <mass value="0.7802158461808613"/>
    <inertia ixx="0.001111" iyy="0.000753" izz="0.000765" ixy="-9e-06" iyz="-0.0" ixz="1.2e-05"/>
  </inertial>
  <visual>
    <origin xyz="0.061914 0.29472 -0.120517" rpy="0 0 0"/>
    <geometry>
      <mesh filename="package://humanoidrightarm_description/meshes/RMD-X8-Pro_MIR8_MIR1__1__1.stl" scale="0.001 0.001 0.001"/>
    </geometry>
    <material name="opaque13110895"/>
  </visual>
  <collision>
    <origin xyz="0.061914 0.29472 -0.120517" rpy="0 0 0"/>
    <geometry>
      <mesh filename="package://humanoidrightarm_description/meshes/RMD-X8-Pro_MIR8_MIR1__1__1.stl" scale="0.001 0.001 0.001"/>
    </geometry>
  </collision>
</link>

<link name="shoulder-motor-bicep-rotor-bracket_1">
  <inertial>
    <origin xyz="-0.0051348558429013536 -0.006894979828174386 -0.010579497143825042" rpy="0 0 0"/>
    <mass value="0.0283879289585321"/>
    <inertia ixx="1.2e-05" iyy="5e-06" izz="8e-06" ixy="0.0" iyz="-2e-06" ixz="0.0"/>
  </inertial>
  <visual>
    <origin xyz="0.097931 0.29472 -0.077239" rpy="0 0 0"/>
    <geometry>
      <mesh filename="package://humanoidrightarm_description/meshes/shoulder-motor-bicep-rotor-bracket_1.stl" scale="0.001 0.001 0.001"/>
    </geometry>
    <material name="opaque245245245"/>
  </visual>
  <collision>
    <origin xyz="0.097931 0.29472 -0.077239" rpy="0 0 0"/>
    <geometry>
      <mesh filename="package://humanoidrightarm_description/meshes/shoulder-motor-bicep-rotor-bracket_1.stl" scale="0.001 0.001 0.001"/>
    </geometry>
  </collision>
</link>

<link name="bicep-rear-motor-adapter_1">
  <inertial>
    <origin xyz="0.0160246933266794 -0.015500394162357989 -0.0026280483696228263" rpy="0 0 0"/>
    <mass value="0.03295670352506347"/>
    <inertia ixx="5e-06" iyy="7e-06" izz="8e-06" ixy="0.0" iyz="-0.0" ixz="-1e-06"/>
  </inertial>
  <visual>
    <origin xyz="0.097305 0.29322 -0.05925" rpy="0 0 0"/>
    <geometry>
      <mesh filename="package://humanoidrightarm_description/meshes/bicep-rear-motor-adapter_1.stl" scale="0.001 0.001 0.001"/>
    </geometry>
    <material name="opaque191191191"/>
  </visual>
  <collision>
    <origin xyz="0.097305 0.29322 -0.05925" rpy="0 0 0"/>
    <geometry>
      <mesh filename="package://humanoidrightarm_description/meshes/bicep-rear-motor-adapter_1.stl" scale="0.001 0.001 0.001"/>
    </geometry>
  </collision>
</link>

<link name="bicep-shoulder-bracket-exal__1__1">
  <inertial>
    <origin xyz="-0.007647214079658633 -0.00553554417152996 -0.010272025262039339" rpy="0 0 0"/>
    <mass value="0.013923035092591882"/>
    <inertia ixx="2e-06" iyy="3e-06" izz="1e-06" ixy="-0.0" iyz="0.0" ixz="0.0"/>
  </inertial>
  <visual>
    <origin xyz="0.059328 0.31872 -0.060571" rpy="0 0 0"/>
    <geometry>
      <mesh filename="package://humanoidrightarm_description/meshes/bicep-shoulder-bracket-exal__1__1.stl" scale="0.001 0.001 0.001"/>
    </geometry>
    <material name="opaque245245245"/>
  </visual>
  <collision>
    <origin xyz="0.059328 0.31872 -0.060571" rpy="0 0 0"/>
    <geometry>
      <mesh filename="package://humanoidrightarm_description/meshes/bicep-shoulder-bracket-exal__1__1.stl" scale="0.001 0.001 0.001"/>
    </geometry>
  </collision>
</link>

<link name="bicep-shoulder-bracket-exal__2__1">
  <inertial>
    <origin xyz="-0.0076472140796579255 0.0054644558284697164 -0.010272025260993169" rpy="0 0 0"/>
    <mass value="0.013923035092591882"/>
    <inertia ixx="2e-06" iyy="3e-06" izz="1e-06" ixy="-0.0" iyz="0.0" ixz="0.0"/>
  </inertial>
  <visual>
    <origin xyz="0.059328 0.29872 -0.060571" rpy="0 0 0"/>
    <geometry>
      <mesh filename="package://humanoidrightarm_description/meshes/bicep-shoulder-bracket-exal__2__1.stl" scale="0.001 0.001 0.001"/>
    </geometry>
    <material name="opaque245245245"/>
  </visual>
  <collision>
    <origin xyz="0.059328 0.29872 -0.060571" rpy="0 0 0"/>
    <geometry>
      <mesh filename="package://humanoidrightarm_description/meshes/bicep-shoulder-bracket-exal__2__1.stl" scale="0.001 0.001 0.001"/>
    </geometry>
  </collision>
</link>

<link name="2020_100mm__8___1__1">
  <inertial>
    <origin xyz="0.03962860702311827 0.009999605838134085 0.01138451444386001" rpy="0 0 0"/>
    <mass value="0.05289771810031747"/>
    <inertia ixx="4e-06" iyy="4.6e-05" izz="4.6e-05" ixy="0.0" iyz="0.0" ixz="-1e-06"/>
  </inertial>
  <visual>
    <origin xyz="0.071777 0.31872 -0.03012" rpy="0 0 0"/>
    <geometry>
      <mesh filename="package://humanoidrightarm_description/meshes/2020_100mm__8___1__1.stl" scale="0.001 0.001 0.001"/>
    </geometry>
    <material name="opaque727161"/>
  </visual>
  <collision>
    <origin xyz="0.071777 0.31872 -0.03012" rpy="0 0 0"/>
    <geometry>
      <mesh filename="package://humanoidrightarm_description/meshes/2020_100mm__8___1__1.stl" scale="0.001 0.001 0.001"/>
    </geometry>
  </collision>
</link>

<link name="yaw-waist-adapter-motor-exal_MIR1__5__1">
  <inertial>
    <origin xyz="-0.05022090543640331 -3.9416209246523337e-07 0.0054911754223530285" rpy="0 0 0"/>
    <mass value="0.043773488134739254"/>
    <inertia ixx="1.5e-05" iyy="8e-06" izz="1.7e-05" ixy="0.0" iyz="-0.0" ixz="-0.0"/>
  </inertial>
  <visual>
    <origin xyz="-0.017821 0.30872 -0.043243" rpy="0 0 0"/>
    <geometry>
      <mesh filename="package://humanoidrightarm_description/meshes/yaw-waist-adapter-motor-exal_MIR1__5__1.stl" scale="0.001 0.001 0.001"/>
    </geometry>
    <material name="opaque245245245"/>
  </visual>
  <collision>
    <origin xyz="-0.017821 0.30872 -0.043243" rpy="0 0 0"/>
    <geometry>
      <mesh filename="package://humanoidrightarm_description/meshes/yaw-waist-adapter-motor-exal_MIR1__5__1.stl" scale="0.001 0.001 0.001"/>
    </geometry>
  </collision>
</link>

<link name="bicep-shoulder-bracket-exal_1">
  <inertial>
    <origin xyz="-0.016185930616379095 0.007214455828389255 0.019448962400012086" rpy="0 0 0"/>
    <mass value="0.013923035092591882"/>
    <inertia ixx="2e-06" iyy="3e-06" izz="1e-06" ixy="-0.0" iyz="0.0" ixz="0.0"/>
  </inertial>
  <visual>
    <origin xyz="-0.018169 0.30047 -0.033249" rpy="0 0 0"/>
    <geometry>
      <mesh filename="package://humanoidrightarm_description/meshes/bicep-shoulder-bracket-exal_1.stl" scale="0.001 0.001 0.001"/>
    </geometry>
    <material name="opaque245245245"/>
  </visual>
  <collision>
    <origin xyz="-0.018169 0.30047 -0.033249" rpy="0 0 0"/>
    <geometry>
      <mesh filename="package://humanoidrightarm_description/meshes/bicep-shoulder-bracket-exal_1.stl" scale="0.001 0.001 0.001"/>
    </geometry>
  </collision>
</link>

<link name="shoulder-front_1">
  <inertial>
    <origin xyz="-0.0080926664425204 -0.010000394162910209 0.01008622264997433" rpy="0 0 0"/>
    <mass value="0.03345047019066647"/>
    <inertia ixx="7e-06" iyy="6e-06" izz="6e-06" ixy="0.0" iyz="-0.0" ixz="-0.0"/>
  </inertial>
  <visual>
    <origin xyz="-0.009631 0.29872 -0.06297" rpy="0 0 0"/>
    <geometry>
      <mesh filename="package://humanoidrightarm_description/meshes/shoulder-front_1.stl" scale="0.001 0.001 0.001"/>
    </geometry>
    <material name="opaque191191191"/>
  </visual>
  <collision>
    <origin xyz="-0.009631 0.29872 -0.06297" rpy="0 0 0"/>
    <geometry>
      <mesh filename="package://humanoidrightarm_description/meshes/shoulder-front_1.stl" scale="0.001 0.001 0.001"/>
    </geometry>
  </collision>
</link>

<link name="bicep-shoulder-bracket-exal__3__1">
  <inertial>
    <origin xyz="-0.007647930616378666 -0.005535544171610951 -0.010272037601031923" rpy="0 0 0"/>
    <mass value="0.013923035092591882"/>
    <inertia ixx="2e-06" iyy="3e-06" izz="1e-06" ixy="-0.0" iyz="0.0" ixz="0.0"/>
  </inertial>
  <visual>
    <origin xyz="-0.009631 0.31872 -0.06297" rpy="0 0 0"/>
    <geometry>
      <mesh filename="package://humanoidrightarm_description/meshes/bicep-shoulder-bracket-exal__3__1.stl" scale="0.001 0.001 0.001"/>
    </geometry>
    <material name="opaque245245245"/>
  </visual>
  <collision>
    <origin xyz="-0.009631 0.31872 -0.06297" rpy="0 0 0"/>
    <geometry>
      <mesh filename="package://humanoidrightarm_description/meshes/bicep-shoulder-bracket-exal__3__1.stl" scale="0.001 0.001 0.001"/>
    </geometry>
  </collision>
</link>

<link name="shoulder-cap_1">
  <inertial>
    <origin xyz="0.0036961323845367475 0.025722169752346702 0.035202272710443655" rpy="0 0 0"/>
    <mass value="0.054086383469635936"/>
    <inertia ixx="4.4e-05" iyy="2.6e-05" izz="1.8e-05" ixy="0.0" iyz="-5e-06" ixz="1e-06"/>
  </inertial>
  <visual>
    <origin xyz="-0.0165 0.32372 -0.08122" rpy="0 0 0"/>
    <geometry>
      <mesh filename="package://humanoidrightarm_description/meshes/shoulder-cap_1.stl" scale="0.001 0.001 0.001"/>
    </geometry>
    <material name="opaque245245245"/>
  </visual>
  <collision>
    <origin xyz="-0.0165 0.32372 -0.08122" rpy="0 0 0"/>
    <geometry>
      <mesh filename="package://humanoidrightarm_description/meshes/shoulder-cap_1.stl" scale="0.001 0.001 0.001"/>
    </geometry>
  </collision>
</link>

<link name="shoulder-front-bearing-adapter_1">
  <inertial>
    <origin xyz="-0.007716243690866937 -3.941643723637256e-07 -0.00026889387581741087" rpy="0 0 0"/>
    <mass value="0.06058583892971603"/>
    <inertia ixx="4.1e-05" iyy="2.2e-05" izz="2.2e-05" ixy="-0.0" iyz="-0.0" ixz="1e-06"/>
  </inertial>
  <visual>
    <origin xyz="-0.01504 0.29472 -0.123195" rpy="0 0 0"/>
    <geometry>
      <mesh filename="package://humanoidrightarm_description/meshes/shoulder-front-bearing-adapter_1.stl" scale="0.001 0.001 0.001"/>
    </geometry>
    <material name="opaque22122113"/>
  </visual>
  <collision>
    <origin xyz="-0.01504 0.29472 -0.123195" rpy="0 0 0"/>
    <geometry>
      <mesh filename="package://humanoidrightarm_description/meshes/shoulder-front-bearing-adapter_1.stl" scale="0.001 0.001 0.001"/>
    </geometry>
  </collision>
</link>

<link name="skateboard-bearing__7__1">
  <inertial>
    <origin xyz="-0.0034980537699691302 -3.9416465275055046e-07 -0.00012124999238932732" rpy="0 0 0"/>
    <mass value="0.002701612602454526"/>
    <inertia ixx="0.0" iyy="0.0" izz="0.0" ixy="-0.0" iyz="0.0" ixz="0.0"/>
  </inertial>
  <visual>
    <origin xyz="-0.011214 0.29472 -0.123061" rpy="0 0 0"/>
    <geometry>
      <mesh filename="package://humanoidrightarm_description/meshes/skateboard-bearing__7__1.stl" scale="0.001 0.001 0.001"/>
    </geometry>
    <material name="opaque191191191"/>
  </visual>
  <collision>
    <origin xyz="-0.011214 0.29472 -0.123061" rpy="0 0 0"/>
    <geometry>
      <mesh filename="package://humanoidrightarm_description/meshes/skateboard-bearing__7__1.stl" scale="0.001 0.001 0.001"/>
    </geometry>
  </collision>
</link>

<link name="shoulder-ex-al-interface__1__1">
  <inertial>
    <origin xyz="0.009281889839157377 0.015588605838770031 -0.00795452675181376" rpy="0 0 0"/>
    <mass value="0.03263560284613005"/>
    <inertia ixx="7e-06" iyy="4e-06" izz="1e-05" ixy="0.0" iyz="-0.0" ixz="-0.0"/>
  </inertial>
  <visual>
    <origin xyz="0.040795 0.324309 -0.031198" rpy="0 0 0"/>
    <geometry>
      <mesh filename="package://humanoidrightarm_description/meshes/shoulder-ex-al-interface__1__1.stl" scale="0.001 0.001 0.001"/>
    </geometry>
    <material name="opaque22122113"/>
  </visual>
  <collision>
    <origin xyz="0.040795 0.324309 -0.031198" rpy="0 0 0"/>
    <geometry>
      <mesh filename="package://humanoidrightarm_description/meshes/shoulder-ex-al-interface__1__1.stl" scale="0.001 0.001 0.001"/>
    </geometry>
  </collision>
</link>

<link name="RMD-X8-Pro_MIR8_MIR1__3__1">
  <inertial>
    <origin xyz="0.00075787823421734 0.00046136654329398397 -0.021867963730687574" rpy="0 0 0"/>
    <mass value="0.7802158462059968"/>
    <inertia ixx="0.000765" iyy="0.000753" izz="0.001111" ixy="-0.0" iyz="9e-06" ixz="-1.2e-05"/>
  </inertial>
  <visual>
    <origin xyz="0.03121 0.30872 -0.014521" rpy="0 0 0"/>
    <geometry>
      <mesh filename="package://humanoidrightarm_description/meshes/RMD-X8-Pro_MIR8_MIR1__3__1.stl" scale="0.001 0.001 0.001"/>
    </geometry>
    <material name="opaque13110895"/>
  </visual>
  <collision>
    <origin xyz="0.03121 0.30872 -0.014521" rpy="0 0 0"/>
    <geometry>
      <mesh filename="package://humanoidrightarm_description/meshes/RMD-X8-Pro_MIR8_MIR1__3__1.stl" scale="0.001 0.001 0.001"/>
    </geometry>
  </collision>
</link>

<link name="bicep-rotational-cuff-second-motor-bracket_1">
  <inertial>
    <origin xyz="-0.03339875659389826 -0.011693372512931066 -0.017252446550962922" rpy="0 0 0"/>
    <mass value="0.037531416691209164"/>
    <inertia ixx="6e-06" iyy="4.5e-05" izz="4.3e-05" ixy="-0.0" iyz="0.0" ixz="-1e-06"/>
  </inertial>
  <visual>
    <origin xyz="-0.004052 0.284033 0.021775" rpy="0 0 0"/>
    <geometry>
      <mesh filename="package://humanoidrightarm_description/meshes/bicep-rotational-cuff-second-motor-bracket_1.stl" scale="0.001 0.001 0.001"/>
    </geometry>
    <material name="opaque245245245"/>
  </visual>
  <collision>
    <origin xyz="-0.004052 0.284033 0.021775" rpy="0 0 0"/>
    <geometry>
      <mesh filename="package://humanoidrightarm_description/meshes/bicep-rotational-cuff-second-motor-bracket_1.stl" scale="0.001 0.001 0.001"/>
    </geometry>
  </collision>
</link>

<link name="arm-cuff-bicep-bracket_1">
  <inertial>
    <origin xyz="-0.03336427567932697 -0.010976918024683036 -0.01825527932572601" rpy="0 0 0"/>
    <mass value="0.04634036346407298"/>
    <inertia ixx="7e-06" iyy="2.4e-05" izz="2.2e-05" ixy="0.0" iyz="-0.0" ixz="-1e-06"/>
  </inertial>
  <visual>
    <origin xyz="-0.004052 0.333407 0.021775" rpy="0 0 0"/>
    <geometry>
      <mesh filename="package://humanoidrightarm_description/meshes/arm-cuff-bicep-bracket_1.stl" scale="0.001 0.001 0.001"/>
    </geometry>
    <material name="opaque245245245"/>
  </visual>
  <collision>
    <origin xyz="-0.004052 0.333407 0.021775" rpy="0 0 0"/>
    <geometry>
      <mesh filename="package://humanoidrightarm_description/meshes/arm-cuff-bicep-bracket_1.stl" scale="0.001 0.001 0.001"/>
    </geometry>
  </collision>
</link>

<link name="RMD-X8-Pro_MIR8_MIR1__2__1">
  <inertial>
    <origin xyz="0.0009986934799903723 0.015618686809614701 -0.041987633023328544" rpy="0 0 0"/>
    <mass value="0.7802158462059968"/>
    <inertia ixx="0.000753" iyy="0.001111" izz="0.000765" ixy="-9e-06" iyz="-0.0" ixz="-0.0"/>
  </inertial>
  <visual>
    <origin xyz="0.029141 0.33672 0.044943" rpy="0 0 0"/>
    <geometry>
      <mesh filename="package://humanoidrightarm_description/meshes/RMD-X8-Pro_MIR8_MIR1__2__1.stl" scale="0.001 0.001 0.001"/>
    </geometry>
    <material name="opaque13110895"/>
  </visual>
  <collision>
    <origin xyz="0.029141 0.33672 0.044943" rpy="0 0 0"/>
    <geometry>
      <mesh filename="package://humanoidrightarm_description/meshes/RMD-X8-Pro_MIR8_MIR1__2__1.stl" scale="0.001 0.001 0.001"/>
    </geometry>
  </collision>
</link>

<link name="elbow-hangar_1">
  <inertial>
    <origin xyz="0.005653743038647678 -0.0053457971596576614 -0.011087629439975266" rpy="0 0 0"/>
    <mass value="0.023870437534756973"/>
    <inertia ixx="5e-06" iyy="1.2e-05" izz="7e-06" ixy="-0.0" iyz="0.0" ixz="1e-06"/>
  </inertial>
  <visual>
    <origin xyz="0.02622 0.33672 0.128892" rpy="0 0 0"/>
    <geometry>
      <mesh filename="package://humanoidrightarm_description/meshes/elbow-hangar_1.stl" scale="0.001 0.001 0.001"/>
    </geometry>
    <material name="opaque245245245"/>
  </visual>
  <collision>
    <origin xyz="0.02622 0.33672 0.128892" rpy="0 0 0"/>
    <geometry>
      <mesh filename="package://humanoidrightarm_description/meshes/elbow-hangar_1.stl" scale="0.001 0.001 0.001"/>
    </geometry>
  </collision>
</link>

<link name="elbow-hangar1_1">
  <inertial>
    <origin xyz="0.005776298481889246 0.005352136996232659 -0.011269506187437328" rpy="0 0 0"/>
    <mass value="0.02416670089885775"/>
    <inertia ixx="5e-06" iyy="1.2e-05" izz="8e-06" ixy="0.0" iyz="-0.0" ixz="1e-06"/>
  </inertial>
  <visual>
    <origin xyz="0.026132 0.30172 0.128889" rpy="0 0 0"/>
    <geometry>
      <mesh filename="package://humanoidrightarm_description/meshes/elbow-hangar1_1.stl" scale="0.001 0.001 0.001"/>
    </geometry>
    <material name="opaque191191191"/>
  </visual>
  <collision>
    <origin xyz="0.026132 0.30172 0.128889" rpy="0 0 0"/>
    <geometry>
      <mesh filename="package://humanoidrightarm_description/meshes/elbow-hangar1_1.stl" scale="0.001 0.001 0.001"/>
    </geometry>
  </collision>
</link>

<link name="power-mount-arm_1">
  <inertial>
    <origin xyz="0.0013023006418281247 0.007563796891956687 -0.021151666880450504" rpy="0 0 0"/>
    <mass value="0.010772908797143082"/>
    <inertia ixx="3e-06" iyy="3e-06" izz="0.0" ixy="-0.0" iyz="0.0" ixz="0.0"/>
  </inertial>
  <visual>
    <origin xyz="0.068077 0.30172 0.075421" rpy="0 0 0"/>
    <geometry>
      <mesh filename="package://humanoidrightarm_description/meshes/power-mount-arm_1.stl" scale="0.001 0.001 0.001"/>
    </geometry>
    <material name="opaque191191191"/>
  </visual>
  <collision>
    <origin xyz="0.068077 0.30172 0.075421" rpy="0 0 0"/>
    <geometry>
      <mesh filename="package://humanoidrightarm_description/meshes/power-mount-arm_1.stl" scale="0.001 0.001 0.001"/>
    </geometry>
  </collision>
</link>

<link name="fan-mount_1">
  <inertial>
    <origin xyz="-0.0012959967564077496 -0.0166209746070759 -0.007550121944072924" rpy="0 0 0"/>
    <mass value="0.007535585538418549"/>
    <inertia ixx="5e-06" iyy="3e-06" izz="1e-06" ixy="0.0" iyz="0.0" ixz="0.0"/>
  </inertial>
  <visual>
    <origin xyz="0.076936 0.29522 0.081211" rpy="0 0 0"/>
    <geometry>
      <mesh filename="package://humanoidrightarm_description/meshes/fan-mount_1.stl" scale="0.001 0.001 0.001"/>
    </geometry>
    <material name="opaque191191191"/>
  </visual>
  <collision>
    <origin xyz="0.076936 0.29522 0.081211" rpy="0 0 0"/>
    <geometry>
      <mesh filename="package://humanoidrightarm_description/meshes/fan-mount_1.stl" scale="0.001 0.001 0.001"/>
    </geometry>
  </collision>
</link>

<link name="bicep-motor-mate_1">
  <inertial>
    <origin xyz="0.016580351598812687 0.005357379163028142 -0.008544311715666983" rpy="0 0 0"/>
    <mass value="0.027378314921932972"/>
    <inertia ixx="5e-06" iyy="1.8e-05" izz="1.3e-05" ixy="0.0" iyz="-0.0" ixz="5e-06"/>
  </inertial>
  <visual>
    <origin xyz="0.027681 0.29972 0.086918" rpy="0 0 0"/>
    <geometry>
      <mesh filename="package://humanoidrightarm_description/meshes/bicep-motor-mate_1.stl" scale="0.001 0.001 0.001"/>
    </geometry>
    <material name="opaque22122113"/>
  </visual>
  <collision>
    <origin xyz="0.027681 0.29972 0.086918" rpy="0 0 0"/>
    <geometry>
      <mesh filename="package://humanoidrightarm_description/meshes/bicep-motor-mate_1.stl" scale="0.001 0.001 0.001"/>
    </geometry>
  </collision>
</link>

<link name="6mm-bearing_1">
  <inertial>
    <origin xyz="4.556195958259346e-07 -0.0025003941566675847 4.5396429743105315e-07" rpy="0 0 0"/>
    <mass value="0.008795084983265406"/>
    <inertia ixx="0.0" iyy="0.0" izz="0.0" ixy="-0.0" iyz="0.0" ixz="-0.0"/>
  </inertial>
  <visual>
    <origin xyz="-0.025653 0.30222 0.114404" rpy="0 0 0"/>
    <geometry>
      <mesh filename="package://humanoidrightarm_description/meshes/6mm-bearing_1.stl" scale="0.001 0.001 0.001"/>
    </geometry>
    <material name="opaque244244244"/>
  </visual>
  <collision>
    <origin xyz="-0.025653 0.30222 0.114404" rpy="0 0 0"/>
    <geometry>
      <mesh filename="package://humanoidrightarm_description/meshes/6mm-bearing_1.stl" scale="0.001 0.001 0.001"/>
    </geometry>
  </collision>
</link>

<link name="bicep_1">
  <inertial>
    <origin xyz="-0.003626545307786177 0.002467595179241111 -0.025218625514025234" rpy="0 0 0"/>
    <mass value="0.005289691132623189"/>
    <inertia ixx="2e-06" iyy="2e-06" izz="0.0" ixy="-0.0" iyz="-0.0" ixz="-0.0"/>
  </inertial>
  <visual>
    <origin xyz="-0.025653 0.30722 0.114404" rpy="0 0 0"/>
    <geometry>
      <mesh filename="package://humanoidrightarm_description/meshes/bicep_1.stl" scale="0.001 0.001 0.001"/>
    </geometry>
    <material name="opaque245245245"/>
  </visual>
  <collision>
    <origin xyz="-0.025653 0.30722 0.114404" rpy="0 0 0"/>
    <geometry>
      <mesh filename="package://humanoidrightarm_description/meshes/bicep_1.stl" scale="0.001 0.001 0.001"/>
    </geometry>
  </collision>
</link>

<link name="6mm-bearing__9__1">
  <inertial>
    <origin xyz="3.724534442944849e-07 -0.002500394155012964 -1.7253289574803432e-07" rpy="0 0 0"/>
    <mass value="0.008795084983265406"/>
    <inertia ixx="0.0" iyy="0.0" izz="0.0" ixy="0.0" iyz="0.0" ixz="0.0"/>
  </inertial>
  <visual>
    <origin xyz="-0.021028 0.30222 0.164189" rpy="0 0 0"/>
    <geometry>
      <mesh filename="package://humanoidrightarm_description/meshes/6mm-bearing__9__1.stl" scale="0.001 0.001 0.001"/>
    </geometry>
    <material name="opaque244244244"/>
  </visual>
  <collision>
    <origin xyz="-0.021028 0.30222 0.164189" rpy="0 0 0"/>
    <geometry>
      <mesh filename="package://humanoidrightarm_description/meshes/6mm-bearing__9__1.stl" scale="0.001 0.001 0.001"/>
    </geometry>
  </collision>
</link>

<link name="straight-tendon_1">
  <inertial>
    <origin xyz="-0.033611913559534835 -0.0118711627216051 -0.008024086122747603" rpy="0 0 0"/>
    <mass value="0.03848915304566222"/>
    <inertia ixx="1.4e-05" iyy="3.2e-05" izz="2.1e-05" ixy="-0.0" iyz="-0.0" ixz="-1.2e-05"/>
  </inertial>
  <visual>
    <origin xyz="-0.021028 0.30722 0.164189" rpy="0 0 0"/>
    <geometry>
      <mesh filename="package://humanoidrightarm_description/meshes/straight-tendon_1.stl" scale="0.001 0.001 0.001"/>
    </geometry>
    <material name="opaque191191191"/>
  </visual>
  <collision>
    <origin xyz="-0.021028 0.30722 0.164189" rpy="0 0 0"/>
    <geometry>
      <mesh filename="package://humanoidrightarm_description/meshes/straight-tendon_1.stl" scale="0.001 0.001 0.001"/>
    </geometry>
  </collision>
</link>

<link name="6mm-bearing__1__1">
  <inertial>
    <origin xyz="3.644839753646524e-07 0.002499605844509978 4.997056746447459e-07" rpy="0 0 0"/>
    <mass value="0.008795084983265406"/>
    <inertia ixx="0.0" iyy="0.0" izz="0.0" ixy="-0.0" iyz="0.0" ixz="0.0"/>
  </inertial>
  <visual>
    <origin xyz="-0.002451 0.33622 0.147483" rpy="0 0 0"/>
    <geometry>
      <mesh filename="package://humanoidrightarm_description/meshes/6mm-bearing__1__1.stl" scale="0.001 0.001 0.001"/>
    </geometry>
    <material name="opaque244244244"/>
  </visual>
  <collision>
    <origin xyz="-0.002451 0.33622 0.147483" rpy="0 0 0"/>
    <geometry>
      <mesh filename="package://humanoidrightarm_description/meshes/6mm-bearing__1__1.stl" scale="0.001 0.001 0.001"/>
    </geometry>
  </collision>
</link>

<link name="6mm-bearing__5__1">
  <inertial>
    <origin xyz="1.2294269268907018e-07 -0.002500394155489971 -3.185142330719426e-07" rpy="0 0 0"/>
    <mass value="0.008795084983265406"/>
    <inertia ixx="0.0" iyy="0.0" izz="0.0" ixy="0.0" iyz="0.0" ixz="0.0"/>
  </inertial>
  <visual>
    <origin xyz="-0.00254 0.30222 0.147479" rpy="0 0 0"/>
    <geometry>
      <mesh filename="package://humanoidrightarm_description/meshes/6mm-bearing__5__1.stl" scale="0.001 0.001 0.001"/>
    </geometry>
    <material name="opaque244244244"/>
  </visual>
  <collision>
    <origin xyz="-0.00254 0.30222 0.147479" rpy="0 0 0"/>
    <geometry>
      <mesh filename="package://humanoidrightarm_description/meshes/6mm-bearing__5__1.stl" scale="0.001 0.001 0.001"/>
    </geometry>
  </collision>
</link>

<link name="6mm-bearing__2__1">
  <inertial>
    <origin xyz="4.913427626256073e-07 0.00249960584500436 -3.992802883601154e-07" rpy="0 0 0"/>
    <mass value="0.008795084983265406"/>
    <inertia ixx="0.0" iyy="0.0" izz="0.0" ixy="0.0" iyz="0.0" ixz="0.0"/>
  </inertial>
  <visual>
    <origin xyz="0.023714 0.33622 0.162178" rpy="0 0 0"/>
    <geometry>
      <mesh filename="package://humanoidrightarm_description/meshes/6mm-bearing__2__1.stl" scale="0.001 0.001 0.001"/>
    </geometry>
    <material name="opaque244244244"/>
  </visual>
  <collision>
    <origin xyz="0.023714 0.33622 0.162178" rpy="0 0 0"/>
    <geometry>
      <mesh filename="package://humanoidrightarm_description/meshes/6mm-bearing__2__1.stl" scale="0.001 0.001 0.001"/>
    </geometry>
  </collision>
</link>

<link name="elbow-bridge-rear__1__1">
  <inertial>
    <origin xyz="-0.0006947986424764505 0.01199999049270839 -0.00019379765823154815" rpy="0 0 0"/>
    <mass value="0.0033585279582303566"/>
    <inertia ixx="0.0" iyy="0.0" izz="0.0" ixy="-0.0" iyz="-0.0" ixz="0.0"/>
  </inertial>
  <visual>
    <origin xyz="0.023714 0.33122 0.162178" rpy="0 0 0"/>
    <geometry>
      <mesh filename="package://humanoidrightarm_description/meshes/elbow-bridge-rear__1__1.stl" scale="0.001 0.001 0.001"/>
    </geometry>
    <material name="opaque22122113"/>
  </visual>
  <collision>
    <origin xyz="0.023714 0.33122 0.162178" rpy="0 0 0"/>
    <geometry>
      <mesh filename="package://humanoidrightarm_description/meshes/elbow-bridge-rear__1__1.stl" scale="0.001 0.001 0.001"/>
    </geometry>
  </collision>
</link>

<link name="6mm-bearing__6__1">
  <inertial>
    <origin xyz="2.4980158380358275e-07 -0.0025003941549956443 -2.1750013723398354e-07" rpy="0 0 0"/>
    <mass value="0.008795084983265406"/>
    <inertia ixx="0.0" iyy="0.0" izz="0.0" ixy="-0.0" iyz="0.0" ixz="0.0"/>
  </inertial>
  <visual>
    <origin xyz="0.023625 0.30222 0.162175" rpy="0 0 0"/>
    <geometry>
      <mesh filename="package://humanoidrightarm_description/meshes/6mm-bearing__6__1.stl" scale="0.001 0.001 0.001"/>
    </geometry>
    <material name="opaque244244244"/>
  </visual>
  <collision>
    <origin xyz="0.023625 0.30222 0.162175" rpy="0 0 0"/>
    <geometry>
      <mesh filename="package://humanoidrightarm_description/meshes/6mm-bearing__6__1.stl" scale="0.001 0.001 0.001"/>
    </geometry>
  </collision>
</link>

<link name="elbow-rear-hanger__1__1">
  <inertial>
    <origin xyz="0.0005501855940397635 0.004053279462675974 -0.030685925213460502" rpy="0 0 0"/>
    <mass value="0.010281646529262634"/>
    <inertia ixx="4e-06" iyy="4e-06" izz="1e-06" ixy="-0.0" iyz="-0.0" ixz="1e-06"/>
  </inertial>
  <visual>
    <origin xyz="0.023714 0.33622 0.162178" rpy="0 0 0"/>
    <geometry>
      <mesh filename="package://humanoidrightarm_description/meshes/elbow-rear-hanger__1__1.stl" scale="0.001 0.001 0.001"/>
    </geometry>
    <material name="opaque808080"/>
  </visual>
  <collision>
    <origin xyz="0.023714 0.33622 0.162178" rpy="0 0 0"/>
    <geometry>
      <mesh filename="package://humanoidrightarm_description/meshes/elbow-rear-hanger__1__1.stl" scale="0.001 0.001 0.001"/>
    </geometry>
  </collision>
</link>

<link name="elbow-rear-hanger_1">
  <inertial>
    <origin xyz="0.0005326232565803779 -0.004054067770602521 -0.030687427333655898" rpy="0 0 0"/>
    <mass value="0.010281646529262634"/>
    <inertia ixx="4e-06" iyy="4e-06" izz="1e-06" ixy="0.0" iyz="0.0" ixz="1e-06"/>
  </inertial>
  <visual>
    <origin xyz="0.023625 0.30222 0.162175" rpy="0 0 0"/>
    <geometry>
      <mesh filename="package://humanoidrightarm_description/meshes/elbow-rear-hanger_1.stl" scale="0.001 0.001 0.001"/>
    </geometry>
    <material name="opaque808080"/>
  </visual>
  <collision>
    <origin xyz="0.023625 0.30222 0.162175" rpy="0 0 0"/>
    <geometry>
      <mesh filename="package://humanoidrightarm_description/meshes/elbow-rear-hanger_1.stl" scale="0.001 0.001 0.001"/>
    </geometry>
  </collision>
</link>

<link name="6mm-bearing__7__1">
  <inertial>
    <origin xyz="1.9353859481013869e-07 -0.0025003941538942476 4.826842432970047e-07" rpy="0 0 0"/>
    <mass value="0.008795084983265406"/>
    <inertia ixx="0.0" iyy="0.0" izz="0.0" ixy="0.0" iyz="0.0" ixz="0.0"/>
  </inertial>
  <visual>
    <origin xyz="0.043015 0.30222 0.198064" rpy="0 0 0"/>
    <geometry>
      <mesh filename="package://humanoidrightarm_description/meshes/6mm-bearing__7__1.stl" scale="0.001 0.001 0.001"/>
    </geometry>
    <material name="opaque244244244"/>
  </visual>
  <collision>
    <origin xyz="0.043015 0.30222 0.198064" rpy="0 0 0"/>
    <geometry>
      <mesh filename="package://humanoidrightarm_description/meshes/6mm-bearing__7__1.stl" scale="0.001 0.001 0.001"/>
    </geometry>
  </collision>
</link>

<link name="6mm-bearing__4__1">
  <inertial>
    <origin xyz="1.9353858642795485e-07 0.0024996058461057014 4.826833633064798e-07" rpy="0 0 0"/>
    <mass value="0.008795084983265406"/>
    <inertia ixx="0.0" iyy="0.0" izz="0.0" ixy="-0.0" iyz="0.0" ixz="-0.0"/>
  </inertial>
  <visual>
    <origin xyz="0.043015 0.33622 0.198064" rpy="0 0 0"/>
    <geometry>
      <mesh filename="package://humanoidrightarm_description/meshes/6mm-bearing__4__1.stl" scale="0.001 0.001 0.001"/>
    </geometry>
    <material name="opaque244244244"/>
  </visual>
  <collision>
    <origin xyz="0.043015 0.33622 0.198064" rpy="0 0 0"/>
    <geometry>
      <mesh filename="package://humanoidrightarm_description/meshes/6mm-bearing__4__1.stl" scale="0.001 0.001 0.001"/>
    </geometry>
  </collision>
</link>

<link name="forearm-elbow-motor-bracket-inner2_1">
  <inertial>
    <origin xyz="0.014703235321209224 -0.006000604888838246 -0.016810488146604435" rpy="0 0 0"/>
    <mass value="0.022472125475631318"/>
    <inertia ixx="3e-06" iyy="1e-05" izz="7e-06" ixy="-0.0" iyz="-0.0" ixz="1e-06"/>
  </inertial>
  <visual>
    <origin xyz="0.043015 0.33622 0.198064" rpy="0 0 0"/>
    <geometry>
      <mesh filename="package://humanoidrightarm_description/meshes/forearm-elbow-motor-bracket-inner2_1.stl" scale="0.001 0.001 0.001"/>
    </geometry>
    <material name="opaque22122113"/>
  </visual>
  <collision>
    <origin xyz="0.043015 0.33622 0.198064" rpy="0 0 0"/>
    <geometry>
      <mesh filename="package://humanoidrightarm_description/meshes/forearm-elbow-motor-bracket-inner2_1.stl" scale="0.001 0.001 0.001"/>
    </geometry>
  </collision>
</link>

<link name="6mm-bearing__3__1">
  <inertial>
    <origin xyz="1.5774118777497903e-07 0.002499605846868813 9.103524228892823e-08" rpy="0 0 0"/>
    <mass value="0.008795084983265406"/>
    <inertia ixx="0.0" iyy="0.0" izz="0.0" ixy="0.0" iyz="0.0" ixz="0.0"/>
  </inertial>
  <visual>
    <origin xyz="0.009974 0.33622 0.220609" rpy="0 0 0"/>
    <geometry>
      <mesh filename="package://humanoidrightarm_description/meshes/6mm-bearing__3__1.stl" scale="0.001 0.001 0.001"/>
    </geometry>
    <material name="opaque244244244"/>
  </visual>
  <collision>
    <origin xyz="0.009974 0.33622 0.220609" rpy="0 0 0"/>
    <geometry>
      <mesh filename="package://humanoidrightarm_description/meshes/6mm-bearing__3__1.stl" scale="0.001 0.001 0.001"/>
    </geometry>
  </collision>
</link>

<link name="elbow-bridge-rear_1">
  <inertial>
    <origin xyz="0.0006254344134757027 0.011999990494578616 -0.0003602701433195743" rpy="0 0 0"/>
    <mass value="0.0033585279582303566"/>
    <inertia ixx="0.0" iyy="0.0" izz="0.0" ixy="0.0" iyz="-0.0" ixz="-0.0"/>
  </inertial>
  <visual>
    <origin xyz="0.009974 0.33122 0.220609" rpy="0 0 0"/>
    <geometry>
      <mesh filename="package://humanoidrightarm_description/meshes/elbow-bridge-rear_1.stl" scale="0.001 0.001 0.001"/>
    </geometry>
    <material name="opaque22122113"/>
  </visual>
  <collision>
    <origin xyz="0.009974 0.33122 0.220609" rpy="0 0 0"/>
    <geometry>
      <mesh filename="package://humanoidrightarm_description/meshes/elbow-bridge-rear_1.stl" scale="0.001 0.001 0.001"/>
    </geometry>
  </collision>
</link>

<link name="second-forearm-motor-strap_1">
  <inertial>
    <origin xyz="-0.024064291358898073 -0.0025096514112383783 -0.008399168081682812" rpy="0 0 0"/>
    <mass value="0.015379539400534015"/>
    <inertia ixx="2e-06" iyy="6e-06" izz="4e-06" ixy="-0.0" iyz="0.0" ixz="0.0"/>
  </inertial>
  <visual>
    <origin xyz="-2e-05 0.34772 0.220259" rpy="0 0 0"/>
    <geometry>
      <mesh filename="package://humanoidrightarm_description/meshes/second-forearm-motor-strap_1.stl" scale="0.001 0.001 0.001"/>
    </geometry>
    <material name="opaque245245245"/>
  </visual>
  <collision>
    <origin xyz="-2e-05 0.34772 0.220259" rpy="0 0 0"/>
    <geometry>
      <mesh filename="package://humanoidrightarm_description/meshes/second-forearm-motor-strap_1.stl" scale="0.001 0.001 0.001"/>
    </geometry>
  </collision>
</link>

<link name="RMD-X8-Pro_MIR8_MIR1__4__1">
  <inertial>
    <origin xyz="-0.012430723864937248 0.04040636655174307 -0.016055972196469148" rpy="0 0 0"/>
    <mass value="0.7802158462059968"/>
    <inertia ixx="0.000765" iyy="0.000753" izz="0.001111" ixy="0.0" iyz="-9e-06" ixz="-1.2e-05"/>
  </inertial>
  <visual>
    <origin xyz="0.009196 0.348665 0.245388" rpy="0 0 0"/>
    <geometry>
      <mesh filename="package://humanoidrightarm_description/meshes/RMD-X8-Pro_MIR8_MIR1__4__1.stl" scale="0.001 0.001 0.001"/>
    </geometry>
    <material name="opaque13110895"/>
  </visual>
  <collision>
    <origin xyz="0.009196 0.348665 0.245388" rpy="0 0 0"/>
    <geometry>
      <mesh filename="package://humanoidrightarm_description/meshes/RMD-X8-Pro_MIR8_MIR1__4__1.stl" scale="0.001 0.001 0.001"/>
    </geometry>
  </collision>
</link>

<link name="fore-arm-bicep-motor-attatch_1">
  <inertial>
    <origin xyz="-0.034814625262640564 -0.0003583553759299307 0.02002948756971626" rpy="0 0 0"/>
    <mass value="0.02451696606358365"/>
    <inertia ixx="2e-06" iyy="1.5e-05" izz="1.3e-05" ixy="-0.0" iyz="0.0" ixz="-0.0"/>
  </inertial>
  <visual>
    <origin xyz="-0.011791 0.284033 0.244666" rpy="0 0 0"/>
    <geometry>
      <mesh filename="package://humanoidrightarm_description/meshes/fore-arm-bicep-motor-attatch_1.stl" scale="0.001 0.001 0.001"/>
    </geometry>
    <material name="opaque245245245"/>
  </visual>
  <collision>
    <origin xyz="-0.011791 0.284033 0.244666" rpy="0 0 0"/>
    <geometry>
      <mesh filename="package://humanoidrightarm_description/meshes/fore-arm-bicep-motor-attatch_1.stl" scale="0.001 0.001 0.001"/>
    </geometry>
  </collision>
</link>

<link name="forearm-elbow-motor-bracket-inner_1">
  <inertial>
    <origin xyz="-0.02830459958435828 -0.0054946318588839915 0.0054745666853737995" rpy="0 0 0"/>
    <mass value="0.022768388482805414"/>
    <inertia ixx="3e-06" iyy="1e-05" izz="7e-06" ixy="0.0" iyz="0.0" ixz="1e-06"/>
  </inertial>
  <visual>
    <origin xyz="-1.9e-05 0.29072 0.22026" rpy="0 0 0"/>
    <geometry>
      <mesh filename="package://humanoidrightarm_description/meshes/forearm-elbow-motor-bracket-inner_1.stl" scale="0.001 0.001 0.001"/>
    </geometry>
    <material name="opaque22122113"/>
  </visual>
  <collision>
    <origin xyz="-1.9e-05 0.29072 0.22026" rpy="0 0 0"/>
    <geometry>
      <mesh filename="package://humanoidrightarm_description/meshes/forearm-elbow-motor-bracket-inner_1.stl" scale="0.001 0.001 0.001"/>
    </geometry>
  </collision>
</link>

<link name="6mm-bearing__8__1">
  <inertial>
    <origin xyz="1.8063389747684233e-07 -0.0025003941531995255 7.262245746431084e-08" rpy="0 0 0"/>
    <mass value="0.008795084983265406"/>
    <inertia ixx="0.0" iyy="0.0" izz="0.0" ixy="-0.0" iyz="0.0" ixz="-0.0"/>
  </inertial>
  <visual>
    <origin xyz="0.009975 0.30222 0.220603" rpy="0 0 0"/>
    <geometry>
      <mesh filename="package://humanoidrightarm_description/meshes/6mm-bearing__8__1.stl" scale="0.001 0.001 0.001"/>
    </geometry>
    <material name="opaque244244244"/>
  </visual>
  <collision>
    <origin xyz="0.009975 0.30222 0.220603" rpy="0 0 0"/>
    <geometry>
      <mesh filename="package://humanoidrightarm_description/meshes/6mm-bearing__8__1.stl" scale="0.001 0.001 0.001"/>
    </geometry>
  </collision>
</link>

<link name="shoulder-ex-al-interface_1">
  <inertial>
    <origin xyz="0.0003178039965990309 -3.941507297211544e-07 -0.00922280451928581" rpy="0 0 0"/>
    <mass value="0.03263560284613005"/>
    <inertia ixx="7e-06" iyy="4e-06" izz="1e-05" ixy="-0.0" iyz="-0.0" ixz="-0.0"/>
  </inertial>
  <visual>
    <origin xyz="0.020895 0.30872 0.282812" rpy="0 0 0"/>
    <geometry>
      <mesh filename="package://humanoidrightarm_description/meshes/shoulder-ex-al-interface_1.stl" scale="0.001 0.001 0.001"/>
    </geometry>
    <material name="opaque22122113"/>
  </visual>
  <collision>
    <origin xyz="0.020895 0.30872 0.282812" rpy="0 0 0"/>
    <geometry>
      <mesh filename="package://humanoidrightarm_description/meshes/shoulder-ex-al-interface_1.stl" scale="0.001 0.001 0.001"/>
    </geometry>
  </collision>
</link>

<link name="shoulder-roll-al-mot_MIR1__3__1">
  <inertial>
    <origin xyz="-0.008535681537615544 0.0010039730075763753 -0.013651118826819353" rpy="0 0 0"/>
    <mass value="0.016359268258045713"/>
    <inertia ixx="1e-06" iyy="3e-06" izz="2e-06" ixy="-0.0" iyz="0.0" ixz="-0.0"/>
  </inertial>
  <visual>
    <origin xyz="0.011298 0.293132 0.299992" rpy="0 0 0"/>
    <geometry>
      <mesh filename="package://humanoidrightarm_description/meshes/shoulder-roll-al-mot_MIR1__3__1.stl" scale="0.001 0.001 0.001"/>
    </geometry>
    <material name="opaque245245245"/>
  </visual>
  <collision>
    <origin xyz="0.011298 0.293132 0.299992" rpy="0 0 0"/>
    <geometry>
      <mesh filename="package://humanoidrightarm_description/meshes/shoulder-roll-al-mot_MIR1__3__1.stl" scale="0.001 0.001 0.001"/>
    </geometry>
  </collision>
</link>

<link name="shoulder-roll-al-mot_MIR1_1">
  <inertial>
    <origin xyz="-0.008535458876955103 -0.0010037613075717378 -0.013651111165319862" rpy="0 0 0"/>
    <mass value="0.016359268258045713"/>
    <inertia ixx="1e-06" iyy="3e-06" izz="2e-06" ixy="0.0" iyz="-0.0" ixz="-0.0"/>
  </inertial>
  <visual>
    <origin xyz="0.011298 0.324309 0.299992" rpy="0 0 0"/>
    <geometry>
      <mesh filename="package://humanoidrightarm_description/meshes/shoulder-roll-al-mot_MIR1_1.stl" scale="0.001 0.001 0.001"/>
    </geometry>
    <material name="opaque245245245"/>
  </visual>
  <collision>
    <origin xyz="0.011298 0.324309 0.299992" rpy="0 0 0"/>
    <geometry>
      <mesh filename="package://humanoidrightarm_description/meshes/shoulder-roll-al-mot_MIR1_1.stl" scale="0.001 0.001 0.001"/>
    </geometry>
  </collision>
</link>

<link name="2020_100mm__10__1">
  <inertial>
    <origin xyz="0.0017199861887342814 -3.9414876412680044e-07 -0.049970417153032465" rpy="0 0 0"/>
    <mass value="0.052897718100317556"/>
    <inertia ixx="4.6e-05" iyy="4.6e-05" izz="4e-06" ixy="-0.0" iyz="0.0" ixz="1e-06"/>
  </inertial>
  <visual>
    <origin xyz="0.020293 0.30872 0.300302" rpy="0 0 0"/>
    <geometry>
      <mesh filename="package://humanoidrightarm_description/meshes/2020_100mm__10__1.stl" scale="0.001 0.001 0.001"/>
    </geometry>
    <material name="opaque727161"/>
  </visual>
  <collision>
    <origin xyz="0.020293 0.30872 0.300302" rpy="0 0 0"/>
    <geometry>
      <mesh filename="package://humanoidrightarm_description/meshes/2020_100mm__10__1.stl" scale="0.001 0.001 0.001"/>
    </geometry>
  </collision>
</link>

<link name="top-bracket-servo-strap_1">
  <inertial>
    <origin xyz="0.0012124717127446859 -1.2438355552535363e-05 -0.035833602013349675" rpy="0 0 0"/>
    <mass value="0.02056602380320786"/>
    <inertia ixx="6e-06" iyy="6e-06" izz="1.1e-05" ixy="0.0" iyz="-0.0" ixz="-0.0"/>
  </inertial>
  <visual>
    <origin xyz="0.020293 0.30872 0.300302" rpy="0 0 0"/>
    <geometry>
      <mesh filename="package://humanoidrightarm_description/meshes/top-bracket-servo-strap_1.stl" scale="0.001 0.001 0.001"/>
    </geometry>
    <material name="opaque191191191"/>
  </visual>
  <collision>
    <origin xyz="0.020293 0.30872 0.300302" rpy="0 0 0"/>
    <geometry>
      <mesh filename="package://humanoidrightarm_description/meshes/top-bracket-servo-strap_1.stl" scale="0.001 0.001 0.001"/>
    </geometry>
  </collision>
</link>

<link name="MG995_1">
  <inertial>
    <origin xyz="-0.008237621330081905 0.004849613450828072 -0.02408313789388694" rpy="0 0 0"/>
    <mass value="0.05503731974130738"/>
    <inertia ixx="9e-06" iyy="1.5e-05" izz="9e-06" ixy="-0.0" iyz="0.0" ixz="-0.0"/>
  </inertial>
  <visual>
    <origin xyz="-0.000568 0.29357 0.33659" rpy="0 0 0"/>
    <geometry>
      <mesh filename="package://humanoidrightarm_description/meshes/MG995_1.stl" scale="0.001 0.001 0.001"/>
    </geometry>
    <material name="opaque636363"/>
  </visual>
  <collision>
    <origin xyz="-0.000568 0.29357 0.33659" rpy="0 0 0"/>
    <geometry>
      <mesh filename="package://humanoidrightarm_description/meshes/MG995_1.stl" scale="0.001 0.001 0.001"/>
    </geometry>
  </collision>
</link>

<link name="MG995__4__1">
  <inertial>
    <origin xyz="-0.004028785234231086 -0.009061169853607054 -0.02393848955549216" rpy="0 0 0"/>
    <mass value="0.05503731974130738"/>
    <inertia ixx="1.5e-05" iyy="9e-06" izz="9e-06" ixy="0.0" iyz="-0.0" ixz="0.0"/>
  </inertial>
  <visual>
    <origin xyz="0.034162 0.28912 0.337785" rpy="0 0 0"/>
    <geometry>
      <mesh filename="package://humanoidrightarm_description/meshes/MG995__4__1.stl" scale="0.001 0.001 0.001"/>
    </geometry>
    <material name="opaque636363"/>
  </visual>
  <collision>
    <origin xyz="0.034162 0.28912 0.337785" rpy="0 0 0"/>
    <geometry>
      <mesh filename="package://humanoidrightarm_description/meshes/MG995__4__1.stl" scale="0.001 0.001 0.001"/>
    </geometry>
  </collision>
</link>

<link name="MG995__3__1">
  <inertial>
    <origin xyz="0.009873400767155108 -0.004850401747631128 -0.023460099923427735" rpy="0 0 0"/>
    <mass value="0.05503731974130738"/>
    <inertia ixx="9e-06" iyy="1.5e-05" izz="9e-06" ixy="-0.0" iyz="-0.0" ixz="0.0"/>
  </inertial>
  <visual>
    <origin xyz="0.038609 0.32387 0.337938" rpy="0 0 0"/>
    <geometry>
      <mesh filename="package://humanoidrightarm_description/meshes/MG995__3__1.stl" scale="0.001 0.001 0.001"/>
    </geometry>
    <material name="opaque636363"/>
  </visual>
  <collision>
    <origin xyz="0.038609 0.32387 0.337938" rpy="0 0 0"/>
    <geometry>
      <mesh filename="package://humanoidrightarm_description/meshes/MG995__3__1.stl" scale="0.001 0.001 0.001"/>
    </geometry>
  </collision>
</link>

<link name="MG995__5__1">
  <inertial>
    <origin xyz="0.005665564671305074 0.009060381556803998 -0.023604748261822628" rpy="0 0 0"/>
    <mass value="0.05503731974130738"/>
    <inertia ixx="1.5e-05" iyy="9e-06" izz="9e-06" ixy="-0.0" iyz="0.0" ixz="0.0"/>
  </inertial>
  <visual>
    <origin xyz="0.00388 0.32832 0.336743" rpy="0 0 0"/>
    <geometry>
      <mesh filename="package://humanoidrightarm_description/meshes/MG995__5__1.stl" scale="0.001 0.001 0.001"/>
    </geometry>
    <material name="opaque636363"/>
  </visual>
  <collision>
    <origin xyz="0.00388 0.32832 0.336743" rpy="0 0 0"/>
    <geometry>
      <mesh filename="package://humanoidrightarm_description/meshes/MG995__5__1.stl" scale="0.001 0.001 0.001"/>
    </geometry>
  </collision>
</link>

<link name="2020_100mm__11__1">
  <inertial>
    <origin xyz="0.0034391462504578738 -3.941470814727843e-07 -0.09992584442257174" rpy="0 0 0"/>
    <mass value="0.05289771810031747"/>
    <inertia ixx="4.6e-05" iyy="4.6e-05" izz="4e-06" ixy="-0.0" iyz="0.0" ixz="1e-06"/>
  </inertial>
  <visual>
    <origin xyz="0.020293 0.30872 0.300302" rpy="0 0 0"/>
    <geometry>
      <mesh filename="package://humanoidrightarm_description/meshes/2020_100mm__11__1.stl" scale="0.001 0.001 0.001"/>
    </geometry>
    <material name="opaque727161"/>
  </visual>
  <collision>
    <origin xyz="0.020293 0.30872 0.300302" rpy="0 0 0"/>
    <geometry>
      <mesh filename="package://humanoidrightarm_description/meshes/2020_100mm__11__1.stl" scale="0.001 0.001 0.001"/>
    </geometry>
  </collision>
</link>

<link name="top-bracket-servo-strap__1__1">
  <inertial>
    <origin xyz="-0.00036063200023736877 1.165006058173601e-05 0.009863268920361712" rpy="0 0 0"/>
    <mass value="0.02056602380320786"/>
    <inertia ixx="6e-06" iyy="6e-06" izz="1.1e-05" ixy="-0.0" iyz="-0.0" ixz="-0.0"/>
  </inertial>
  <visual>
    <origin xyz="0.015134 0.30872 0.450198" rpy="0 0 0"/>
    <geometry>
      <mesh filename="package://humanoidrightarm_description/meshes/top-bracket-servo-strap__1__1.stl" scale="0.001 0.001 0.001"/>
    </geometry>
    <material name="opaque191191191"/>
  </visual>
  <collision>
    <origin xyz="0.015134 0.30872 0.450198" rpy="0 0 0"/>
    <geometry>
      <mesh filename="package://humanoidrightarm_description/meshes/top-bracket-servo-strap__1__1.stl" scale="0.001 0.001 0.001"/>
    </geometry>
  </collision>
</link>

<link name="MG995__2__1">
  <inertial>
    <origin xyz="0.0040285988786711215 -0.009061169851821371 0.023938600949056144" rpy="0 0 0"/>
    <mass value="0.05503731974130738"/>
    <inertia ixx="1.5e-05" iyy="9e-06" izz="9e-06" ixy="-0.0" iyz="0.0" ixz="0.0"/>
  </inertial>
  <visual>
    <origin xyz="0.000371 0.28912 0.438684" rpy="0 0 0"/>
    <geometry>
      <mesh filename="package://humanoidrightarm_description/meshes/MG995__2__1.stl" scale="0.001 0.001 0.001"/>
    </geometry>
    <material name="opaque636363"/>
  </visual>
  <collision>
    <origin xyz="0.000371 0.28912 0.438684" rpy="0 0 0"/>
    <geometry>
      <mesh filename="package://humanoidrightarm_description/meshes/MG995__2__1.stl" scale="0.001 0.001 0.001"/>
    </geometry>
  </collision>
</link>

<link name="MG995__6__1">
  <inertial>
    <origin xyz="0.008237434974521635 0.00484961345268492 0.024083249288088304" rpy="0 0 0"/>
    <mass value="0.05503731974130738"/>
    <inertia ixx="9e-06" iyy="1.5e-05" izz="9e-06" ixy="0.0" iyz="-0.0" ixz="-0.0"/>
  </inertial>
  <visual>
    <origin xyz="0.035101 0.29357 0.439879" rpy="0 0 0"/>
    <geometry>
      <mesh filename="package://humanoidrightarm_description/meshes/MG995__6__1.stl" scale="0.001 0.001 0.001"/>
    </geometry>
    <material name="opaque636363"/>
  </visual>
  <collision>
    <origin xyz="0.035101 0.29357 0.439879" rpy="0 0 0"/>
    <geometry>
      <mesh filename="package://humanoidrightarm_description/meshes/MG995__6__1.stl" scale="0.001 0.001 0.001"/>
    </geometry>
  </collision>
</link>

<link name="MG995__1__1">
  <inertial>
    <origin xyz="-0.005664751026866276 0.009060381558682828 0.02360485965396747" rpy="0 0 0"/>
    <mass value="0.05503731974130738"/>
    <inertia ixx="1.5e-05" iyy="9e-06" izz="9e-06" ixy="0.0" iyz="-0.0" ixz="0.0"/>
  </inertial>
  <visual>
    <origin xyz="0.030654 0.32832 0.439726" rpy="0 0 0"/>
    <geometry>
      <mesh filename="package://humanoidrightarm_description/meshes/MG995__1__1.stl" scale="0.001 0.001 0.001"/>
    </geometry>
    <material name="opaque636363"/>
  </visual>
  <collision>
    <origin xyz="0.030654 0.32832 0.439726" rpy="0 0 0"/>
    <geometry>
      <mesh filename="package://humanoidrightarm_description/meshes/MG995__1__1.stl" scale="0.001 0.001 0.001"/>
    </geometry>
  </collision>
</link>

<link name="MG995__7__1">
  <inertial>
    <origin xyz="-0.009873587122716722 -0.004850401745823518 0.02346021131493531" rpy="0 0 0"/>
    <mass value="0.05503731974130738"/>
    <inertia ixx="9e-06" iyy="1.5e-05" izz="9e-06" ixy="0.0" iyz="0.0" ixz="0.0"/>
  </inertial>
  <visual>
    <origin xyz="-0.004076 0.32387 0.438531" rpy="0 0 0"/>
    <geometry>
      <mesh filename="package://humanoidrightarm_description/meshes/MG995__7__1.stl" scale="0.001 0.001 0.001"/>
    </geometry>
    <material name="opaque636363"/>
  </visual>
  <collision>
    <origin xyz="-0.004076 0.32387 0.438531" rpy="0 0 0"/>
    <geometry>
      <mesh filename="package://humanoidrightarm_description/meshes/MG995__7__1.stl" scale="0.001 0.001 0.001"/>
    </geometry>
  </collision>
</link>

<link name="multiplex-stack-flat_1">
  <inertial>
    <origin xyz="0.03330526590425406 -0.007502802815578136 0.001158712351079276" rpy="0 0 0"/>
    <mass value="0.023031674197712796"/>
    <inertia ixx="3e-06" iyy="3.1e-05" izz="2.8e-05" ixy="0.0" iyz="0.0" ixz="-1e-06"/>
  </inertial>
  <visual>
    <origin xyz="0.066975 0.32972 -0.050299" rpy="0 0 0"/>
    <geometry>
      <mesh filename="package://humanoidrightarm_description/meshes/multiplex-stack-flat_1.stl" scale="0.001 0.001 0.001"/>
    </geometry>
    <material name="opaque191191191"/>
  </visual>
  <collision>
    <origin xyz="0.066975 0.32972 -0.050299" rpy="0 0 0"/>
    <geometry>
      <mesh filename="package://humanoidrightarm_description/meshes/multiplex-stack-flat_1.stl" scale="0.001 0.001 0.001"/>
    </geometry>
  </collision>
</link>

<joint name="Rigid 1" type="fixed">
  <origin xyz="-0.03493 -0.24472 0.121456" rpy="0 0 0"/>
  <parent link="base_link"/>
  <child link="2020_100mm__9__1"/>
</joint>

<joint name="Rigid 2" type="fixed">
  <origin xyz="0.0 0.0 0.0" rpy="0 0 0"/>
  <parent link="2020_100mm__9__1"/>
  <child link="shoulder-roll-al-mot_MIR1__1__1"/>
</joint>

<joint name="Rigid 3" type="fixed">
  <origin xyz="0.0 0.0 0.0" rpy="0 0 0"/>
  <parent link="2020_100mm__9__1"/>
  <child link="shoulder-roll-al-mot_MIR1__2__1"/>
</joint>

<joint name="Rigid 4" type="fixed">
  <origin xyz="0.0 -0.1 0.0" rpy="0 0 0"/>
  <parent link="2020_100mm__9__1"/>
  <child link="yaw-cap_1"/>
</joint>

<joint name="Rigid 5" type="fixed">
  <origin xyz="0.0 0.0 0.0" rpy="0 0 0"/>
  <parent link="2020_100mm__9__1"/>
  <child link="yaw-waist-adapter-motor-exal_MIR1_1"/>
</joint>

<joint name="Rigid 6" type="fixed">
  <origin xyz="0.019446 -0.059 0.016275" rpy="0 0 0"/>
  <parent link="yaw-waist-adapter-motor-exal_MIR1_1"/>
  <child link="front-bearing-adapter-shoulder_1"/>
</joint>

<joint name="Rigid 7" type="fixed">
  <origin xyz="-0.010536 -0.059 0.015232" rpy="0 0 0"/>
  <parent link="yaw-waist-adapter-motor-exal_MIR1_1"/>
  <child link="shoulder-ex-al-interface__2__1"/>
</joint>

<joint name="Revolute 8" type="continuous">
  <origin xyz="-0.016448 0.009 -0.016171" rpy="0 0 0"/>
  <parent link="shoulder-ex-al-interface__2__1"/>
  <child link="RMD-X8-Pro_MIR8_MIR1__1__1"/>
  <axis xyz="-0.999395 0.0 -0.034768"/>
</joint>

<joint name="Rigid 9" type="fixed">
  <origin xyz="-0.036017 0.0 -0.043278" rpy="0 0 0"/>
  <parent link="RMD-X8-Pro_MIR8_MIR1__1__1"/>
  <child link="shoulder-motor-bicep-rotor-bracket_1"/>
</joint>

<joint name="Rigid 10" type="fixed">
  <origin xyz="0.000626 0.0015 -0.017989" rpy="0 0 0"/>
  <parent link="shoulder-motor-bicep-rotor-bracket_1"/>
  <child link="bicep-rear-motor-adapter_1"/>
</joint>

<joint name="Rigid 11" type="fixed">
  <origin xyz="0.037977 -0.0255 0.001321" rpy="0 0 0"/>
  <parent link="bicep-rear-motor-adapter_1"/>
  <child link="bicep-shoulder-bracket-exal__1__1"/>
</joint>

<joint name="Rigid 12" type="fixed">
  <origin xyz="0.037977 -0.0055 0.001321" rpy="0 0 0"/>
  <parent link="bicep-rear-motor-adapter_1"/>
  <child link="bicep-shoulder-bracket-exal__2__1"/>
</joint>

<joint name="Rigid 13" type="fixed">
  <origin xyz="-0.012449 0.0 -0.030451" rpy="0 0 0"/>
  <parent link="bicep-shoulder-bracket-exal__1__1"/>
  <child link="2020_100mm__8___1__1"/>
</joint>

<joint name="Rigid 14" type="fixed">
  <origin xyz="0.089598 0.01 0.013123" rpy="0 0 0"/>
  <parent link="2020_100mm__8___1__1"/>
  <child link="yaw-waist-adapter-motor-exal_MIR1__5__1"/>
</joint>

<joint name="Rigid 15" type="fixed">
  <origin xyz="0.089946 0.01825 0.003129" rpy="0 0 0"/>
  <parent link="2020_100mm__8___1__1"/>
  <child link="bicep-shoulder-bracket-exal_1"/>
</joint>

<joint name="Rigid 16" type="fixed">
  <origin xyz="-0.008538 0.00175 0.029721" rpy="0 0 0"/>
  <parent link="bicep-shoulder-bracket-exal_1"/>
  <child link="shoulder-front_1"/>
</joint>

<joint name="Rigid 17" type="fixed">
  <origin xyz="0.0 -0.02 0.0" rpy="0 0 0"/>
  <parent link="shoulder-front_1"/>
  <child link="bicep-shoulder-bracket-exal__3__1"/>
</joint>

<joint name="Rigid 18" type="fixed">
  <origin xyz="0.006869 -0.025 0.01825" rpy="0 0 0"/>
  <parent link="shoulder-front_1"/>
  <child link="shoulder-cap_1"/>
</joint>

<joint name="Rigid 19" type="fixed">
  <origin xyz="-0.00146 0.029 0.041975" rpy="0 0 0"/>
  <parent link="shoulder-cap_1"/>
  <child link="shoulder-front-bearing-adapter_1"/>
</joint>

<joint name="Revolute 20" type="continuous">
  <origin xyz="-0.003826 0.0 -0.000134" rpy="0 0 0"/>
  <parent link="shoulder-front-bearing-adapter_1"/>
  <child link="skateboard-bearing__7__1"/>
  <axis xyz="-0.999395 0.0 -0.034768"/>
</joint>

<joint name="Rigid 21" type="fixed">
  <origin xyz="-0.058616 -0.015589 -0.012045" rpy="0 0 0"/>
  <parent link="yaw-waist-adapter-motor-exal_MIR1__5__1"/>
  <child link="shoulder-ex-al-interface__1__1"/>
</joint>

<joint name="Revolute 22" type="continuous">
  <origin xyz="0.009585 0.015589 -0.016677" rpy="0 0 0"/>
  <parent link="shoulder-ex-al-interface__1__1"/>
  <child link="RMD-X8-Pro_MIR8_MIR1__3__1"/>
  <axis xyz="0.034768 0.0 -0.999395"/>
</joint>

<joint name="Rigid 23" type="fixed">
  <origin xyz="0.035262 0.024687 -0.036296" rpy="0 0 0"/>
  <parent link="RMD-X8-Pro_MIR8_MIR1__3__1"/>
  <child link="bicep-rotational-cuff-second-motor-bracket_1"/>
</joint>

<joint name="Rigid 24" type="fixed">
  <origin xyz="0.035262 -0.024687 -0.036296" rpy="0 0 0"/>
  <parent link="RMD-X8-Pro_MIR8_MIR1__3__1"/>
  <child link="arm-cuff-bicep-bracket_1"/>
</joint>

<joint name="Rigid 25" type="fixed">
  <origin xyz="-0.033193 -0.003313 -0.023168" rpy="0 0 0"/>
  <parent link="arm-cuff-bicep-bracket_1"/>
  <child link="RMD-X8-Pro_MIR8_MIR1__2__1"/>
</joint>

<joint name="Rigid 26" type="fixed">
  <origin xyz="0.002921 0.0 -0.083949" rpy="0 0 0"/>
  <parent link="RMD-X8-Pro_MIR8_MIR1__2__1"/>
  <child link="elbow-hangar_1"/>
</joint>

<joint name="Rigid 27" type="fixed">
  <origin xyz="0.003009 0.035 -0.083946" rpy="0 0 0"/>
  <parent link="RMD-X8-Pro_MIR8_MIR1__2__1"/>
  <child link="elbow-hangar1_1"/>
</joint>

<joint name="Rigid 28" type="fixed">
  <origin xyz="-0.038936 0.035 -0.030478" rpy="0 0 0"/>
  <parent link="RMD-X8-Pro_MIR8_MIR1__2__1"/>
  <child link="power-mount-arm_1"/>
</joint>

<joint name="Rigid 29" type="fixed">
  <origin xyz="-0.008859 0.0065 -0.00579" rpy="0 0 0"/>
  <parent link="power-mount-arm_1"/>
  <child link="fan-mount_1"/>
</joint>

<joint name="Revolute 30" type="continuous">
  <origin xyz="0.00146 0.037 -0.041975" rpy="0 0 0"/>
  <parent link="RMD-X8-Pro_MIR8_MIR1__2__1"/>
  <child link="bicep-motor-mate_1"/>
  <axis xyz="-0.0 1.0 0.0"/>
</joint>

<joint name="Rigid 31" type="fixed">
  <origin xyz="0.053334 -0.0025 -0.027486" rpy="0 0 0"/>
  <parent link="bicep-motor-mate_1"/>
  <child link="6mm-bearing_1"/>
</joint>

<joint name="Revolute 32" type="continuous">
  <origin xyz="0.0 -0.005 0.0" rpy="0 0 0"/>
  <parent link="6mm-bearing_1"/>
  <child link="bicep_1"/>
  <axis xyz="0.0 -1.0 -0.0"/>
</joint>

<joint name="Revolute 33" type="continuous">
  <origin xyz="-0.004625 0.005 -0.049785" rpy="0 0 0"/>
  <parent link="bicep_1"/>
  <child link="6mm-bearing__9__1"/>
  <axis xyz="-0.0 1.0 0.0"/>
</joint>

<joint name="Rigid 34" type="fixed">
  <origin xyz="0.0 -0.005 0.0" rpy="0 0 0"/>
  <parent link="6mm-bearing__9__1"/>
  <child link="straight-tendon_1"/>
</joint>

<joint name="Rigid 35" type="fixed">
  <origin xyz="0.028671 0.0005 -0.018591" rpy="0 0 0"/>
  <parent link="elbow-hangar_1"/>
  <child link="6mm-bearing__1__1"/>
</joint>

<joint name="Rigid 36" type="fixed">
  <origin xyz="0.028672 -0.0005 -0.01859" rpy="0 0 0"/>
  <parent link="elbow-hangar1_1"/>
  <child link="6mm-bearing__5__1"/>
</joint>

<joint name="Rigid 38" type="fixed">
  <origin xyz="0.002506 0.0005 -0.033286" rpy="0 0 0"/>
  <parent link="elbow-hangar_1"/>
  <child link="6mm-bearing__2__1"/>
</joint>

<joint name="Rigid 39" type="fixed">
  <origin xyz="0.0 0.005 0.0" rpy="0 0 0"/>
  <parent link="6mm-bearing__2__1"/>
  <child link="elbow-bridge-rear__1__1"/>
</joint>

<joint name="Rigid 40" type="fixed">
  <origin xyz="0.002507 -0.0005 -0.033286" rpy="0 0 0"/>
  <parent link="elbow-hangar1_1"/>
  <child link="6mm-bearing__6__1"/>
</joint>

<joint name="Revolute 41" type="continuous">
  <origin xyz="0.0 0.0 0.0" rpy="0 0 0"/>
  <parent link="6mm-bearing__2__1"/>
  <child link="elbow-rear-hanger__1__1"/>
  <axis xyz="0.0 -1.0 -0.0"/>
</joint>

<joint name="Revolute 42" type="continuous">
  <origin xyz="0.0 0.0 0.0" rpy="0 0 0"/>
  <parent link="6mm-bearing__6__1"/>
  <child link="elbow-rear-hanger_1"/>
  <axis xyz="-0.0 1.0 0.0"/>
</joint>

<joint name="Revolute 43" type="continuous">
  <origin xyz="-0.064043 0.005 -0.033875" rpy="0 0 0"/>
  <parent link="straight-tendon_1"/>
  <child link="6mm-bearing__7__1"/>
  <axis xyz="-0.0 1.0 0.0"/>
</joint>

<joint name="Revolute 44" type="continuous">
  <origin xyz="-0.064043 -0.029 -0.033875" rpy="0 0 0"/>
  <parent link="straight-tendon_1"/>
  <child link="6mm-bearing__4__1"/>
  <axis xyz="0.0 -1.0 -0.0"/>
</joint>

<joint name="Rigid 45" type="fixed">
  <origin xyz="0.0 0.0 0.0" rpy="0 0 0"/>
  <parent link="6mm-bearing__4__1"/>
  <child link="forearm-elbow-motor-bracket-inner2_1"/>
</joint>

<joint name="Rigid 46" type="fixed">
  <origin xyz="0.033041 0.0 -0.022545" rpy="0 0 0"/>
  <parent link="forearm-elbow-motor-bracket-inner2_1"/>
  <child link="6mm-bearing__3__1"/>
</joint>

<joint name="Rigid 48" type="fixed">
  <origin xyz="0.0 0.005 0.0" rpy="0 0 0"/>
  <parent link="6mm-bearing__3__1"/>
  <child link="elbow-bridge-rear_1"/>
</joint>

<joint name="Rigid 49" type="fixed">
  <origin xyz="0.043035 -0.0115 -0.022195" rpy="0 0 0"/>
  <parent link="forearm-elbow-motor-bracket-inner2_1"/>
  <child link="second-forearm-motor-strap_1"/>
</joint>

<joint name="Rigid 50" type="fixed">
  <origin xyz="-0.009216 -0.000945 -0.025129" rpy="0 0 0"/>
  <parent link="second-forearm-motor-strap_1"/>
  <child link="RMD-X8-Pro_MIR8_MIR1__4__1"/>
</joint>

<joint name="Rigid 51" type="fixed">
  <origin xyz="0.020987 0.064632 0.000722" rpy="0 0 0"/>
  <parent link="RMD-X8-Pro_MIR8_MIR1__4__1"/>
  <child link="fore-arm-bicep-motor-attatch_1"/>
</joint>

<joint name="Rigid 52" type="fixed">
  <origin xyz="-0.011772 -0.006687 0.024406" rpy="0 0 0"/>
  <parent link="fore-arm-bicep-motor-attatch_1"/>
  <child link="forearm-elbow-motor-bracket-inner_1"/>
</joint>

<joint name="Rigid 53" type="fixed">
  <origin xyz="-0.009994 -0.0115 -0.000343" rpy="0 0 0"/>
  <parent link="forearm-elbow-motor-bracket-inner_1"/>
  <child link="6mm-bearing__8__1"/>
</joint>

<joint name="Revolute 55" type="continuous">
  <origin xyz="-0.011699 0.039945 -0.037424" rpy="0 0 0"/>
  <parent link="RMD-X8-Pro_MIR8_MIR1__4__1"/>
  <child link="shoulder-ex-al-interface_1"/>
  <axis xyz="0.034394 0.0 -0.999408"/>
</joint>

<joint name="Rigid 56" type="fixed">
  <origin xyz="0.009597 0.015588 -0.01718" rpy="0 0 0"/>
  <parent link="shoulder-ex-al-interface_1"/>
  <child link="shoulder-roll-al-mot_MIR1__3__1"/>
</joint>

<joint name="Rigid 57" type="fixed">
  <origin xyz="0.009597 -0.015589 -0.01718" rpy="0 0 0"/>
  <parent link="shoulder-ex-al-interface_1"/>
  <child link="shoulder-roll-al-mot_MIR1_1"/>
</joint>

<joint name="Rigid 58" type="fixed">
  <origin xyz="0.000602 0.0 -0.01749" rpy="0 0 0"/>
  <parent link="shoulder-ex-al-interface_1"/>
  <child link="2020_100mm__10__1"/>
</joint>

<joint name="Rigid 59" type="fixed">
  <origin xyz="0.0 0.0 0.0" rpy="0 0 0"/>
  <parent link="2020_100mm__10__1"/>
  <child link="top-bracket-servo-strap_1"/>
</joint>

<joint name="Rigid 60" type="fixed">
  <origin xyz="0.020861 0.01515 -0.036288" rpy="0 0 0"/>
  <parent link="top-bracket-servo-strap_1"/>
  <child link="MG995_1"/>
</joint>

<joint name="Rigid 61" type="fixed">
  <origin xyz="-0.013869 0.0196 -0.037483" rpy="0 0 0"/>
  <parent link="top-bracket-servo-strap_1"/>
  <child link="MG995__4__1"/>
</joint>

<joint name="Rigid 62" type="fixed">
  <origin xyz="-0.018316 -0.01515 -0.037636" rpy="0 0 0"/>
  <parent link="top-bracket-servo-strap_1"/>
  <child link="MG995__3__1"/>
</joint>

<joint name="Rigid 63" type="fixed">
  <origin xyz="0.016413 -0.0196 -0.036441" rpy="0 0 0"/>
  <parent link="top-bracket-servo-strap_1"/>
  <child link="MG995__5__1"/>
</joint>

<joint name="Rigid 64" type="fixed">
  <origin xyz="0.0 0.0 0.0" rpy="0 0 0"/>
  <parent link="2020_100mm__10__1"/>
  <child link="2020_100mm__11__1"/>
</joint>

<joint name="Rigid 65" type="fixed">
  <origin xyz="0.005159 0.0 -0.149896" rpy="0 0 0"/>
  <parent link="2020_100mm__11__1"/>
  <child link="top-bracket-servo-strap__1__1"/>
</joint>

<joint name="Rigid 66" type="fixed">
  <origin xyz="0.014763 0.0196 0.011514" rpy="0 0 0"/>
  <parent link="top-bracket-servo-strap__1__1"/>
  <child link="MG995__2__1"/>
</joint>

<joint name="Rigid 67" type="fixed">
  <origin xyz="-0.019967 0.01515 0.010319" rpy="0 0 0"/>
  <parent link="top-bracket-servo-strap__1__1"/>
  <child link="MG995__6__1"/>
</joint>

<joint name="Rigid 68" type="fixed">
  <origin xyz="-0.01552 -0.0196 0.010472" rpy="0 0 0"/>
  <parent link="top-bracket-servo-strap__1__1"/>
  <child link="MG995__1__1"/>
</joint>

<joint name="Rigid 69" type="fixed">
  <origin xyz="0.01921 -0.01515 0.011667" rpy="0 0 0"/>
  <parent link="top-bracket-servo-strap__1__1"/>
  <child link="MG995__7__1"/>
</joint>

<joint name="Rigid 70" type="fixed">
  <origin xyz="-0.007647 -0.011 -0.010272" rpy="0 0 0"/>
  <parent link="bicep-shoulder-bracket-exal__1__1"/>
  <child link="multiplex-stack-flat_1"/>
</joint>

</robot>
