<?xml version='1.0' encoding='utf-8'?>
<robot xmlns:xacro="http://www.ros.org/wiki/xacro" name="humanoidrightarm">

  <xacro:macro name="arm_macro" params="prefix folder parent sign *origin">
    
    <link name="${prefix}_2020_100mm__9__1">
      <inertial>
        <origin xyz="1.4980442800229068e-14 5.199887469533773e-15 ${sign*0.049999999999999795}" rpy="0 0 0"/>
        <mass value="0.05289771810031747"/>
        <inertia ixx="4.6e-05" iyy="4e-06" izz="4.6e-05" ixy="-0.0" iyz="-0.0" ixz="-0.0"/>
      </inertial>
      <visual>
        <origin xyz="0.03493 0.24472 ${sign*-0.0021}" rpy="0 0 0"/>
        <geometry>
          <mesh filename="package://dropbear_right_arm/meshes/${folder}/2020_100mm__9__1.stl" scale="0.001 0.001 0.001"/>
        </geometry>
        <material name="opaque727161"/>
      </visual>
      <collision>
        <origin xyz="0.03493 0.24472 ${sign*-0.0021}" rpy="0 0 0"/>
        <geometry>
          <mesh filename="package://dropbear_right_arm/meshes/${folder}/2020_100mm__9__1.stl" scale="0.001 0.001 0.001"/>
        </geometry>
      </collision>
    </link>
    
    <link name="${prefix}_shoulder-roll-al-mot_MIR1__1__1">
      <inertial>
        <origin xyz="0.005127204279605231 -0.01578027268886943 ${sign*0.013349013943228552}" rpy="0 0 0"/>
        <mass value="0.016359268258045713"/>
        <inertia ixx="3e-06" iyy="2e-06" izz="1e-06" ixy="-0.0" iyz="-0.0" ixz="0.0"/>
      </inertial>
      <visual>
        <origin xyz="0.03493 0.24472 ${sign*-0.0021}" rpy="0 0 0"/>
        <geometry>
          <mesh filename="package://dropbear_right_arm/meshes/${folder}/shoulder-roll-al-mot_MIR1__1__1.stl" scale="0.001 0.001 0.001"/>
        </geometry>
        <material name="opaque245245245"/>
      </visual>
      <collision>
        <origin xyz="0.03493 0.24472 ${sign*-0.0021}" rpy="0 0 0"/>
        <geometry>
          <mesh filename="package://dropbear_right_arm/meshes/${folder}/shoulder-roll-al-mot_MIR1__1__1.stl" scale="0.001 0.001 0.001"/>
        </geometry>
      </collision>
    </link>
    
    <link name="${prefix}_shoulder-roll-al-mot_MIR1__2__1">
      <inertial>
        <origin xyz="-0.005127204279607458 0.015780272688869185 ${sign*0.013349013943228556}" rpy="0 0 0"/>
        <mass value="0.016359268258045713"/>
        <inertia ixx="3e-06" iyy="2e-06" izz="1e-06" ixy="0.0" iyz="0.0" ixz="0.0"/>
      </inertial>
      <visual>
        <origin xyz="0.03493 0.24472 ${sign*-0.0021}" rpy="0 0 0"/>
        <geometry>
          <mesh filename="package://dropbear_right_arm/meshes/${folder}/shoulder-roll-al-mot_MIR1__2__1.stl" scale="0.001 0.001 0.001"/>
        </geometry>
        <material name="opaque245245245"/>
      </visual>
      <collision>
        <origin xyz="0.03493 0.24472 ${sign*-0.0021}" rpy="0 0 0"/>
        <geometry>
          <mesh filename="package://dropbear_right_arm/meshes/${folder}/shoulder-roll-al-mot_MIR1__2__1.stl" scale="0.001 0.001 0.001"/>
        </geometry>
      </collision>
    </link>
    
    <link name="${prefix}_yaw-cap_1">
      <inertial>
        <origin xyz="-8.404754804490673e-15 2.1068804545096473e-14 ${sign*-0.006586829858195878}" rpy="0 0 0"/>
        <mass value="0.017312584943862036"/>
        <inertia ixx="5e-06" iyy="3e-06" izz="3e-06" ixy="-0.0" iyz="0.0" ixz="0.0"/>
      </inertial>
      <visual>
        <origin xyz="0.03493 0.34472 ${sign*-0.1021}" rpy="0 0 0"/>
        <geometry>
          <mesh filename="package://dropbear_right_arm/meshes/${folder}/yaw-cap_1.stl" scale="0.001 0.001 0.001"/>
        </geometry>
        <material name="opaque245245245"/>
      </visual>
      <collision>
        <origin xyz="0.03493 0.34472 ${sign*-0.1021}" rpy="0 0 0"/>
        <geometry>
          <mesh filename="package://dropbear_right_arm/meshes/${folder}/yaw-cap_1.stl" scale="0.001 0.001 0.001"/>
        </geometry>
      </collision>
    </link>
    
    <link name="${prefix}_yaw-waist-adapter-motor-exal_MIR1_1">
      <inertial>
        <origin xyz="-0.0022354396247523025 0.006879975731446575 ${sign*0.049999999999987436}" rpy="0 0 0"/>
        <mass value="0.043773488134739254"/>
        <inertia ixx="1.7e-05" iyy="1.5e-05" izz="8e-06" ixy="-0.0" iyz="0.0" ixz="0.0"/>
      </inertial>
      <visual>
        <origin xyz="0.03493 0.24472 ${sign*-0.0021}" rpy="0 0 0"/>
        <geometry>
          <mesh filename="package://dropbear_right_arm/meshes/${folder}/yaw-waist-adapter-motor-exal_MIR1_1.stl" scale="0.001 0.001 0.001"/>
        </geometry>
        <material name="opaque245245245"/>
      </visual>
      <collision>
        <origin xyz="0.03493 0.24472 ${sign*-0.0021}" rpy="0 0 0"/>
        <geometry>
          <mesh filename="package://dropbear_right_arm/meshes/${folder}/yaw-waist-adapter-motor-exal_MIR1_1.stl" scale="0.001 0.001 0.001"/>
        </geometry>
      </collision>
    </link>
    
    <link name="${prefix}_front-bearing-adapter-shoulder_1">
      <inertial>
        <origin xyz="0.012476625956564928 0.01204671407588206 ${sign*-0.00900000000002072}" rpy="0 0 0"/>
        <mass value="0.027709236054798532"/>
        <inertia ixx="9e-06" iyy="6e-06" izz="4e-06" ixy="-0.0" iyz="0.0" ixz="0.0"/>
      </inertial>
      <visual>
        <origin xyz="0.015484 0.30372 ${sign*-0.0611}" rpy="0 0 0"/>
        <geometry>
          <mesh filename="package://dropbear_right_arm/meshes/${folder}/front-bearing-adapter-shoulder_1.stl" scale="0.001 0.001 0.001"/>
        </geometry>
        <material name="opaque191191191"/>
      </visual>
      <collision>
        <origin xyz="0.015484 0.30372 ${sign*-0.0611}" rpy="0 0 0"/>
        <geometry>
          <mesh filename="package://dropbear_right_arm/meshes/${folder}/front-bearing-adapter-shoulder_1.stl" scale="0.001 0.001 0.001"/>
        </geometry>
      </collision>
    </link>
    
    <link name="${prefix}_shoulder-ex-al-interface__2__1">
      <inertial>
        <origin xyz="0.01738138579865837 -0.0030497886170603797 ${sign*-0.008999999999991598}" rpy="0 0 0"/>
        <mass value="0.03263560284613005"/>
        <inertia ixx="1e-05" iyy="7e-06" izz="5e-06" ixy="-0.0" iyz="0.0" ixz="0.0"/>
      </inertial>
      <visual>
        <origin xyz="0.045466 0.30372 ${sign*-0.0611}" rpy="0 0 0"/>
        <geometry>
          <mesh filename="package://dropbear_right_arm/meshes/${folder}/shoulder-ex-al-interface__2__1.stl" scale="0.001 0.001 0.001"/>
        </geometry>
        <material name="opaque22122113"/>
      </visual>
      <collision>
        <origin xyz="0.045466 0.30372 ${sign*-0.0611}" rpy="0 0 0"/>
        <geometry>
          <mesh filename="package://dropbear_right_arm/meshes/${folder}/shoulder-ex-al-interface__2__1.stl" scale="0.001 0.001 0.001"/>
        </geometry>
      </collision>
    </link>
    
    <link name="${prefix}_RMD-X8-Pro_MIR8_MIR1__1__1">
      <inertial>
        <origin xyz="0.0067650965649745445 -0.020808521702550438 ${sign*0.00046176070349858434}" rpy="0 0 0"/>
        <mass value="0.7802158461808613"/>
        <inertia ixx="0.001111" iyy="0.000753" izz="0.000765" ixy="-9e-06" iyz="-0.0" ixz="1.2e-05"/>
      </inertial>
      <visual>
        <origin xyz="0.061914 0.29472 ${sign*-0.0521}" rpy="0 0 0"/>
        <geometry>
          <mesh filename="package://dropbear_right_arm/meshes/${folder}/RMD-X8-Pro_MIR8_MIR1__1__1.stl" scale="0.001 0.001 0.001"/>
        </geometry>
        <material name="opaque13110895"/>
      </visual>
      <collision>
        <origin xyz="0.061914 0.29472 ${sign*-0.0521}" rpy="0 0 0"/>
        <geometry>
          <mesh filename="package://dropbear_right_arm/meshes/${folder}/RMD-X8-Pro_MIR8_MIR1__1__1.stl" scale="0.001 0.001 0.001"/>
        </geometry>
      </collision>
    </link>
    
    <link name="${prefix}_shoulder-motor-bicep-rotor-bracket_1">
      <inertial>
        <origin xyz="0.011585383104448774 -0.002019144805998477 ${sign*0.006894585665480131}" rpy="0 0 0"/>
        <mass value="0.0283879289585321"/>
        <inertia ixx="1.2e-05" iyy="5e-06" izz="8e-06" ixy="0.0" iyz="-2e-06" ixz="0.0"/>
      </inertial>
      <visual>
        <origin xyz="0.097931 0.29472 ${sign*-0.0521}" rpy="0 0 0"/>
        <geometry>
          <mesh filename="package://dropbear_right_arm/meshes/${folder}/shoulder-motor-bicep-rotor-bracket_1.stl" scale="0.001 0.001 0.001"/>
        </geometry>
        <material name="opaque245245245"/>
      </visual>
      <collision>
        <origin xyz="0.097931 0.29472 ${sign*-0.0521}" rpy="0 0 0"/>
        <geometry>
          <mesh filename="package://dropbear_right_arm/meshes/${folder}/shoulder-motor-bicep-rotor-bracket_1.stl" scale="0.001 0.001 0.001"/>
        </geometry>
      </collision>
    </link>
    
    <link name="${prefix}_bicep-rear-motor-adapter_1">
      <inertial>
        <origin xyz="-0.0018929355342764131 0.016127672677199507 ${sign*0.015500000000001603}" rpy="0 0 0"/>
        <mass value="0.03295670352506347"/>
        <inertia ixx="5e-06" iyy="7e-06" izz="8e-06" ixy="0.0" iyz="-0.0" ixz="-1e-06"/>
      </inertial>
      <visual>
        <origin xyz="0.097305 0.29322 ${sign*-0.0506}" rpy="0 0 0"/>
        <geometry>
          <mesh filename="package://dropbear_right_arm/meshes/${folder}/bicep-rear-motor-adapter_1.stl" scale="0.001 0.001 0.001"/>
        </geometry>
        <material name="opaque191191191"/>
      </visual>
      <collision>
        <origin xyz="0.097305 0.29322 ${sign*-0.0506}" rpy="0 0 0"/>
        <geometry>
          <mesh filename="package://dropbear_right_arm/meshes/${folder}/bicep-rear-motor-adapter_1.stl" scale="0.001 0.001 0.001"/>
        </geometry>
      </collision>
    </link>
    
    <link name="${prefix}_bicep-shoulder-bracket-exal__1__1">
      <inertial>
        <origin xyz="0.011983042446585573 -0.004518260205938709 ${sign*0.005535150009386286}" rpy="0 0 0"/>
        <mass value="0.013923035092591882"/>
        <inertia ixx="2e-06" iyy="3e-06" izz="1e-06" ixy="-0.0" iyz="0.0" ixz="0.0"/>
      </inertial>
      <visual>
        <origin xyz="0.059328 0.31872 ${sign*-0.0761}" rpy="0 0 0"/>
        <geometry>
          <mesh filename="package://dropbear_right_arm/meshes/${folder}/bicep-shoulder-bracket-exal__1__1.stl" scale="0.001 0.001 0.001"/>
        </geometry>
        <material name="opaque245245245"/>
      </visual>
      <collision>
        <origin xyz="0.059328 0.31872 ${sign*-0.0761}" rpy="0 0 0"/>
        <geometry>
          <mesh filename="package://dropbear_right_arm/meshes/${folder}/bicep-shoulder-bracket-exal__1__1.stl" scale="0.001 0.001 0.001"/>
        </geometry>
      </collision>
    </link>
    
    <link name="${prefix}_bicep-shoulder-bracket-exal__2__1">
      <inertial>
        <origin xyz="0.011983042446582756 -0.004518260205939313 ${sign*-0.0054648499906134115}" rpy="0 0 0"/>
        <mass value="0.013923035092591882"/>
        <inertia ixx="2e-06" iyy="3e-06" izz="1e-06" ixy="-0.0" iyz="0.0" ixz="0.0"/>
      </inertial>
      <visual>
        <origin xyz="0.059328 0.29872 ${sign*-0.0561}" rpy="0 0 0"/>
        <geometry>
          <mesh filename="package://dropbear_right_arm/meshes/${folder}/bicep-shoulder-bracket-exal__2__1.stl" scale="0.001 0.001 0.001"/>
        </geometry>
        <material name="opaque245245245"/>
      </visual>
      <collision>
        <origin xyz="0.059328 0.29872 ${sign*-0.0561}" rpy="0 0 0"/>
        <geometry>
          <mesh filename="package://dropbear_right_arm/meshes/${folder}/bicep-shoulder-bracket-exal__2__1.stl" scale="0.001 0.001 0.001"/>
        </geometry>
      </collision>
    </link>
    
    <link name="${prefix}_2020_100mm__8__1">
      <inertial>
        <origin xyz="-0.02187147869637933 0.034952359549973555 ${sign*-0.009999999999981746}" rpy="0 0 0"/>
        <mass value="0.01959174744456203"/>
        <inertia ixx="1.6e-05" iyy="3e-06" izz="1.7e-05" ixy="5e-06" iyz="0.0" ixz="0.0"/>
      </inertial>
      <visual>
        <origin xyz="-0.097956 0.010231 ${sign*-0.0761}" rpy="0 0 0"/>
        <geometry>
          <mesh filename="package://dropbear_right_arm/meshes/${folder}/2020_100mm__8__1.stl" scale="0.001 0.001 0.001"/>
        </geometry>
        <material name="opaque727161"/>
      </visual>
      <collision>
        <origin xyz="-0.097956 0.010231 ${sign*-0.0761}" rpy="0 0 0"/>
        <geometry>
          <mesh filename="package://dropbear_right_arm/meshes/${folder}/2020_100mm__8__1.stl" scale="0.001 0.001 0.001"/>
        </geometry>
      </collision>
    </link>
    
    <link name="${prefix}_yaw-waist-adapter-motor-exal_MIR1__5__1">
      <inertial>
        <origin xyz="0.008570545572160838 -0.049788080074744674 ${sign*1.457167719820518e-15}" rpy="0 0 0"/>
        <mass value="0.043773488134739254"/>
        <inertia ixx="1.5e-05" iyy="8e-06" izz="1.7e-05" ixy="0.0" iyz="-0.0" ixz="-0.0"/>
      </inertial>
      <visual>
        <origin xyz="-0.017821 0.30872 ${sign*-0.0661}" rpy="0 0 0"/>
        <geometry>
          <mesh filename="package://dropbear_right_arm/meshes/${folder}/yaw-waist-adapter-motor-exal_MIR1__5__1.stl" scale="0.001 0.001 0.001"/>
        </geometry>
        <material name="opaque245245245"/>
      </visual>
      <collision>
        <origin xyz="-0.017821 0.30872 ${sign*-0.0661}" rpy="0 0 0"/>
        <geometry>
          <mesh filename="package://dropbear_right_arm/meshes/${folder}/yaw-waist-adapter-motor-exal_MIR1__5__1.stl" scale="0.001 0.001 0.001"/>
        </geometry>
      </collision>
    </link>
    
    <link name="${prefix}_bicep-shoulder-bracket-exal_1">
      <inertial>
        <origin xyz="-0.014231130165287431 -0.020921360581575885 ${sign*-0.007214849990613441}" rpy="0 0 0"/>
        <mass value="0.013923035092591882"/>
        <inertia ixx="2e-06" iyy="3e-06" izz="1e-06" ixy="-0.0" iyz="0.0" ixz="0.0"/>
      </inertial>
      <visual>
        <origin xyz="-0.018169 0.30047 ${sign*-0.05785}" rpy="0 0 0"/>
        <geometry>
          <mesh filename="package://dropbear_right_arm/meshes/${folder}/bicep-shoulder-bracket-exal_1.stl" scale="0.001 0.001 0.001"/>
        </geometry>
        <material name="opaque245245245"/>
      </visual>
      <collision>
        <origin xyz="-0.018169 0.30047 ${sign*-0.05785}" rpy="0 0 0"/>
        <geometry>
          <mesh filename="package://dropbear_right_arm/meshes/${folder}/bicep-shoulder-bracket-exal_1.stl" scale="0.001 0.001 0.001"/>
        </geometry>
      </collision>
    </link>
    
    <link name="${prefix}_shoulder-front_1">
      <inertial>
        <origin xyz="-0.007463364992977992 -0.010559925065031256 ${sign*0.010000000000000855}" rpy="0 0 0"/>
        <mass value="0.03345047019066647"/>
        <inertia ixx="7e-06" iyy="6e-06" izz="6e-06" ixy="0.0" iyz="-0.0" ixz="-0.0"/>
      </inertial>
      <visual>
        <origin xyz="-0.009631 0.29872 ${sign*-0.0561}" rpy="0 0 0"/>
        <geometry>
          <mesh filename="package://dropbear_right_arm/meshes/${folder}/shoulder-front_1.stl" scale="0.001 0.001 0.001"/>
        </geometry>
        <material name="opaque191191191"/>
      </visual>
      <collision>
        <origin xyz="-0.009631 0.29872 ${sign*-0.0561}" rpy="0 0 0"/>
        <geometry>
          <mesh filename="package://dropbear_right_arm/meshes/${folder}/shoulder-front_1.stl" scale="0.001 0.001 0.001"/>
        </geometry>
      </collision>
    </link>
    
    <link name="${prefix}_bicep-shoulder-bracket-exal__3__1">
      <inertial>
        <origin xyz="0.011982869834713333 -0.00451836058157562 ${sign*0.0055351500093866746}" rpy="0 0 0"/>
        <mass value="0.013923035092591882"/>
        <inertia ixx="2e-06" iyy="3e-06" izz="1e-06" ixy="-0.0" iyz="0.0" ixz="0.0"/>
      </inertial>
      <visual>
        <origin xyz="-0.009631 0.31872 ${sign*-0.0761}" rpy="0 0 0"/>
        <geometry>
          <mesh filename="package://dropbear_right_arm/meshes/${folder}/bicep-shoulder-bracket-exal__3__1.stl" scale="0.001 0.001 0.001"/>
        </geometry>
        <material name="opaque245245245"/>
      </visual>
      <collision>
        <origin xyz="-0.009631 0.31872 ${sign*-0.0761}" rpy="0 0 0"/>
        <geometry>
          <mesh filename="package://dropbear_right_arm/meshes/${folder}/bicep-shoulder-bracket-exal__3__1.stl" scale="0.001 0.001 0.001"/>
        </geometry>
      </collision>
    </link>
    
    <link name="${prefix}_shoulder-cap_1">
      <inertial>
        <origin xyz="-0.034857061179216664 -0.006155365677712535 ${sign*-0.02572256391671531}" rpy="0 0 0"/>
        <mass value="0.054086383469635936"/>
        <inertia ixx="4.4e-05" iyy="2.6e-05" izz="1.8e-05" ixy="0.0" iyz="-5e-06" ixz="1e-06"/>
      </inertial>
      <visual>
        <origin xyz="-0.0165 0.32372 ${sign*-0.0811}" rpy="0 0 0"/>
        <geometry>
          <mesh filename="package://dropbear_right_arm/meshes/${folder}/shoulder-cap_1.stl" scale="0.001 0.001 0.001"/>
        </geometry>
        <material name="opaque245245245"/>
      </visual>
      <collision>
        <origin xyz="-0.0165 0.32372 ${sign*-0.0811}" rpy="0 0 0"/>
        <geometry>
          <mesh filename="package://dropbear_right_arm/meshes/${folder}/shoulder-cap_1.stl" scale="0.001 0.001 0.001"/>
        </geometry>
      </collision>
    </link>
    
    <link name="${prefix}_shoulder-front-bearing-adapter_1">
      <inertial>
        <origin xyz="0.002386025471724852 -0.007343142980721001 ${sign*-2.1516816106625924e-13}" rpy="0 0 0"/>
        <mass value="0.06058583892971603"/>
        <inertia ixx="4.1e-05" iyy="2.2e-05" izz="2.2e-05" ixy="-0.0" iyz="-0.0" ixz="1e-06"/>
      </inertial>
      <visual>
        <origin xyz="-0.01504 0.29472 ${sign*-0.0521}" rpy="0 0 0"/>
        <geometry>
          <mesh filename="package://dropbear_right_arm/meshes/${folder}/shoulder-front-bearing-adapter_1.stl" scale="0.001 0.001 0.001"/>
        </geometry>
        <material name="opaque22122113"/>
      </visual>
      <collision>
        <origin xyz="-0.01504 0.29472 ${sign*-0.0521}" rpy="0 0 0"/>
        <geometry>
          <mesh filename="package://dropbear_right_arm/meshes/${folder}/shoulder-front-bearing-adapter_1.stl" scale="0.001 0.001 0.001"/>
        </geometry>
      </collision>
    </link>
    
    <link name="${prefix}_skateboard-bearing__7__1">
      <inertial>
        <origin xyz="0.0010817588048354296 -0.0033289225564277353 ${sign*6.462885782099193e-14}" rpy="0 0 0"/>
        <mass value="0.002701612602454526"/>
        <inertia ixx="0.0" iyy="0.0" izz="0.0" ixy="-0.0" iyz="0.0" ixz="0.0"/>
      </inertial>
      <visual>
        <origin xyz="-0.011214 0.29472 ${sign*-0.0521}" rpy="0 0 0"/>
        <geometry>
          <mesh filename="package://dropbear_right_arm/meshes/${folder}/skateboard-bearing__7__1.stl" scale="0.001 0.001 0.001"/>
        </geometry>
        <material name="opaque191191191"/>
      </visual>
      <collision>
        <origin xyz="-0.011214 0.29472 ${sign*-0.0521}" rpy="0 0 0"/>
        <geometry>
          <mesh filename="package://dropbear_right_arm/meshes/${folder}/skateboard-bearing__7__1.stl" scale="0.001 0.001 0.001"/>
        </geometry>
      </collision>
    </link>
    
    <link name="${prefix}_shoulder-ex-al-interface__1__1">
      <inertial>
        <origin xyz="0.005086309920670065 0.011115745348658862 ${sign*-0.015588000000003085}" rpy="0 0 0"/>
        <mass value="0.03263560284613005"/>
        <inertia ixx="7e-06" iyy="4e-06" izz="1e-05" ixy="0.0" iyz="-0.0" ixz="-0.0"/>
      </inertial>
      <visual>
        <origin xyz="0.040795 0.324309 ${sign*-0.081688}" rpy="0 0 0"/>
        <geometry>
          <mesh filename="package://dropbear_right_arm/meshes/${folder}/shoulder-ex-al-interface__1__1.stl" scale="0.001 0.001 0.001"/>
        </geometry>
        <material name="opaque22122113"/>
      </visual>
      <collision>
        <origin xyz="0.040795 0.324309 ${sign*-0.081688}" rpy="0 0 0"/>
        <geometry>
          <mesh filename="package://dropbear_right_arm/meshes/${folder}/shoulder-ex-al-interface__1__1.stl" scale="0.001 0.001 0.001"/>
        </geometry>
      </collision>
    </link>
    
    <link name="${prefix}_RMD-X8-Pro_MIR8_MIR1__3__1">
      <inertial>
        <origin xyz="0.020811032738451224 0.006758332348657088 ${sign*-0.0004617607034976129}" rpy="0 0 0"/>
        <mass value="0.7802158462059968"/>
        <inertia ixx="0.000765" iyy="0.000753" izz="0.001111" ixy="-0.0" iyz="9e-06" ixz="-1.2e-05"/>
      </inertial>
      <visual>
        <origin xyz="0.03121 0.30872 ${sign*-0.0661}" rpy="0 0 0"/>
        <geometry>
          <mesh filename="package://dropbear_right_arm/meshes/${folder}/RMD-X8-Pro_MIR8_MIR1__3__1.stl" scale="0.001 0.001 0.001"/>
        </geometry>
        <material name="opaque13110895"/>
      </visual>
      <collision>
        <origin xyz="0.03121 0.30872 ${sign*-0.0661}" rpy="0 0 0"/>
        <geometry>
          <mesh filename="package://dropbear_right_arm/meshes/${folder}/RMD-X8-Pro_MIR8_MIR1__3__1.stl" scale="0.001 0.001 0.001"/>
        </geometry>
      </collision>
    </link>
    
    <link name="${prefix}_bicep-rotational-cuff-second-motor-bracket_1">
      <inertial>
        <origin xyz="0.02579329779689743 -0.027346829280827607 ${sign*0.011692978353793584}" rpy="0 0 0"/>
        <mass value="0.037531416691209164"/>
        <inertia ixx="6e-06" iyy="4.5e-05" izz="4.3e-05" ixy="-0.0" iyz="0.0" ixz="-1e-06"/>
      </inertial>
      <visual>
        <origin xyz="-0.004052 0.284033 ${sign*-0.041413}" rpy="0 0 0"/>
        <geometry>
          <mesh filename="package://dropbear_right_arm/meshes/${folder}/bicep-rotational-cuff-second-motor-bracket_1.stl" scale="0.001 0.001 0.001"/>
        </geometry>
        <material name="opaque245245245"/>
      </visual>
      <collision>
        <origin xyz="-0.004052 0.284033 ${sign*-0.041413}" rpy="0 0 0"/>
        <geometry>
          <mesh filename="package://dropbear_right_arm/meshes/${folder}/bicep-rotational-cuff-second-motor-bracket_1.stl" scale="0.001 0.001 0.001"/>
        </geometry>
      </collision>
    </link>
    
    <link name="${prefix}_arm-cuff-bicep-bracket_1">
      <inertial>
        <origin xyz="0.026747737541988198 -0.027037140279867637 ${sign*0.010976523865579235}" rpy="0 0 0"/>
        <mass value="0.04634036346407298"/>
        <inertia ixx="7e-06" iyy="2.4e-05" izz="2.2e-05" ixy="0.0" iyz="-0.0" ixz="-1e-06"/>
      </inertial>
      <visual>
        <origin xyz="-0.004052 0.333407 ${sign*-0.090787}" rpy="0 0 0"/>
        <geometry>
          <mesh filename="package://dropbear_right_arm/meshes/${folder}/arm-cuff-bicep-bracket_1.stl" scale="0.001 0.001 0.001"/>
        </geometry>
        <material name="opaque245245245"/>
      </visual>
      <collision>
        <origin xyz="-0.004052 0.333407 ${sign*-0.090787}" rpy="0 0 0"/>
        <geometry>
          <mesh filename="package://dropbear_right_arm/meshes/${folder}/arm-cuff-bicep-bracket_1.stl" scale="0.001 0.001 0.001"/>
        </geometry>
      </collision>
    </link>
    
    <link name="${prefix}_RMD-X8-Pro_MIR8_MIR1__2__1">
      <inertial>
        <origin xyz="0.04008391366910127 0.012538887934983922 ${sign*-0.01561908096714007}" rpy="0 0 0"/>
        <mass value="0.7802158462059968"/>
        <inertia ixx="0.000753" iyy="0.001111" izz="0.000765" ixy="-9e-06" iyz="-0.0" ixz="-0.0"/>
      </inertial>
      <visual>
        <origin xyz="0.029141 0.33672 ${sign*-0.0941}" rpy="0 0 0"/>
        <geometry>
          <mesh filename="package://dropbear_right_arm/meshes/${folder}/RMD-X8-Pro_MIR8_MIR1__2__1.stl" scale="0.001 0.001 0.001"/>
        </geometry>
        <material name="opaque13110895"/>
      </visual>
      <collision>
        <origin xyz="0.029141 0.33672 ${sign*-0.0941}" rpy="0 0 0"/>
        <geometry>
          <mesh filename="package://dropbear_right_arm/meshes/${folder}/RMD-X8-Pro_MIR8_MIR1__2__1.stl" scale="0.001 0.001 0.001"/>
        </geometry>
      </collision>
    </link>
    
    <link name="${prefix}_elbow-hangar_1">
      <inertial>
        <origin xyz="0.009097755696947596 0.008492177017401778 ${sign*0.0053454030039173095}" rpy="0 0 0"/>
        <mass value="0.023870437534756973"/>
        <inertia ixx="5e-06" iyy="1.2e-05" izz="7e-06" ixy="-0.0" iyz="0.0" ixz="1e-06"/>
      </inertial>
      <visual>
        <origin xyz="0.02622 0.33672 ${sign*-0.0941}" rpy="0 0 0"/>
        <geometry>
          <mesh filename="package://dropbear_right_arm/meshes/${folder}/elbow-hangar_1.stl" scale="0.001 0.001 0.001"/>
        </geometry>
        <material name="opaque245245245"/>
      </visual>
      <collision>
        <origin xyz="0.02622 0.33672 ${sign*-0.0941}" rpy="0 0 0"/>
        <geometry>
          <mesh filename="package://dropbear_right_arm/meshes/${folder}/elbow-hangar_1.stl" scale="0.001 0.001 0.001"/>
        </geometry>
      </collision>
    </link>
    
    <link name="${prefix}_elbow-hangar1_1">
      <inertial>
        <origin xyz="0.009239632983326695 0.008659896006840764 ${sign*-0.005352531151966877}" rpy="0 0 0"/>
        <mass value="0.02416670089885775"/>
        <inertia ixx="5e-06" iyy="1.2e-05" izz="8e-06" ixy="0.0" iyz="-0.0" ixz="1e-06"/>
      </inertial>
      <visual>
        <origin xyz="0.026132 0.30172 ${sign*-0.0591}" rpy="0 0 0"/>
        <geometry>
          <mesh filename="package://dropbear_right_arm/meshes/${folder}/elbow-hangar1_1.stl" scale="0.001 0.001 0.001"/>
        </geometry>
        <material name="opaque191191191"/>
      </visual>
      <collision>
        <origin xyz="0.026132 0.30172 ${sign*-0.0591}" rpy="0 0 0"/>
        <geometry>
          <mesh filename="package://dropbear_right_arm/meshes/${folder}/elbow-hangar1_1.stl" scale="0.001 0.001 0.001"/>
        </geometry>
      </collision>
    </link>
    
    <link name="${prefix}_power-mount-arm_1">
      <inertial>
        <origin xyz="0.0199725006095543 0.007084375363081735 ${sign*-0.007564191049157856}" rpy="0 0 0"/>
        <mass value="0.010772908797143082"/>
        <inertia ixx="3e-06" iyy="3e-06" izz="0.0" ixy="-0.0" iyz="0.0" ixz="0.0"/>
      </inertial>
      <visual>
        <origin xyz="0.068077 0.30172 ${sign*-0.0591}" rpy="0 0 0"/>
        <geometry>
          <mesh filename="package://dropbear_right_arm/meshes/${folder}/power-mount-arm_1.stl" scale="0.001 0.001 0.001"/>
        </geometry>
        <material name="opaque191191191"/>
      </visual>
      <collision>
        <origin xyz="0.068077 0.30172 ${sign*-0.0591}" rpy="0 0 0"/>
        <geometry>
          <mesh filename="package://dropbear_right_arm/meshes/${folder}/power-mount-arm_1.stl" scale="0.001 0.001 0.001"/>
        </geometry>
      </collision>
    </link>
    
    <link name="${prefix}_fan-mount_1">
      <inertial>
        <origin xyz="0.007614354119151734 0.000836188010462844 ${sign*0.01662058044961192}" rpy="0 0 0"/>
        <mass value="0.007535585538418549"/>
        <inertia ixx="5e-06" iyy="3e-06" izz="1e-06" ixy="0.0" iyz="0.0" ixz="0.0"/>
      </inertial>
      <visual>
        <origin xyz="0.076936 0.29522 ${sign*-0.0526}" rpy="0 0 0"/>
        <geometry>
          <mesh filename="package://dropbear_right_arm/meshes/${folder}/fan-mount_1.stl" scale="0.001 0.001 0.001"/>
        </geometry>
        <material name="opaque191191191"/>
      </visual>
      <collision>
        <origin xyz="0.076936 0.29522 ${sign*-0.0526}" rpy="0 0 0"/>
        <geometry>
          <mesh filename="package://dropbear_right_arm/meshes/${folder}/fan-mount_1.stl" scale="0.001 0.001 0.001"/>
        </geometry>
      </collision>
    </link>
    
    <link name="${prefix}_bicep-motor-mate_1">
      <inertial>
        <origin xyz="0.0036413059649408053 0.01829349155933041 ${sign*-0.005357773320266546}" rpy="0 0 0"/>
        <mass value="0.027378314921932972"/>
        <inertia ixx="5e-06" iyy="1.8e-05" izz="1.3e-05" ixy="0.0" iyz="-0.0" ixz="5e-06"/>
      </inertial>
      <visual>
        <origin xyz="0.027681 0.29972 ${sign*-0.0571}" rpy="0 0 0"/>
        <geometry>
          <mesh filename="package://dropbear_right_arm/meshes/${folder}/bicep-motor-mate_1.stl" scale="0.001 0.001 0.001"/>
        </geometry>
        <material name="opaque22122113"/>
      </visual>
      <collision>
        <origin xyz="0.027681 0.29972 ${sign*-0.0571}" rpy="0 0 0"/>
        <geometry>
          <mesh filename="package://dropbear_right_arm/meshes/${folder}/bicep-motor-mate_1.stl" scale="0.001 0.001 0.001"/>
        </geometry>
      </collision>
    </link>
    
    <link name="${prefix}_6mm-bearing_1">
      <inertial>
        <origin xyz="-3.5326930772350273e-07 -2.214747430728803e-07 ${sign*0.0025000000000666572}" rpy="0 0 0"/>
        <mass value="0.008795084983265406"/>
        <inertia ixx="0.0" iyy="0.0" izz="0.0" ixy="-0.0" iyz="0.0" ixz="-0.0"/>
      </inertial>
      <visual>
        <origin xyz="-0.025653 0.30222 ${sign*-0.0596}" rpy="0 0 0"/>
        <geometry>
          <mesh filename="package://dropbear_right_arm/meshes/${folder}/6mm-bearing_1.stl" scale="0.001 0.001 0.001"/>
        </geometry>
        <material name="opaque244244244"/>
      </visual>
      <collision>
        <origin xyz="-0.025653 0.30222 ${sign*-0.0596}" rpy="0 0 0"/>
        <geometry>
          <mesh filename="package://dropbear_right_arm/meshes/${folder}/6mm-bearing_1.stl" scale="0.001 0.001 0.001"/>
        </geometry>
      </collision>
    </link>
    
    <link name="${prefix}_bicep_1">
      <inertial>
        <origin xyz="0.025241062458964486 0.003467924642948428 ${sign*-0.0024679893349933285}" rpy="0 0 0"/>
        <mass value="0.005289691132623189"/>
        <inertia ixx="2e-06" iyy="2e-06" izz="0.0" ixy="-0.0" iyz="-0.0" ixz="-0.0"/>
      </inertial>
      <visual>
        <origin xyz="-0.025653 0.30722 ${sign*-0.0646}" rpy="0 0 0"/>
        <geometry>
          <mesh filename="package://dropbear_right_arm/meshes/${folder}/bicep_1.stl" scale="0.001 0.001 0.001"/>
        </geometry>
        <material name="opaque245245245"/>
      </visual>
      <collision>
        <origin xyz="-0.025653 0.30722 ${sign*-0.0646}" rpy="0 0 0"/>
        <geometry>
          <mesh filename="package://dropbear_right_arm/meshes/${folder}/bicep_1.stl" scale="0.001 0.001 0.001"/>
        </geometry>
      </collision>
    </link>
    
    <link name="${prefix}_6mm-bearing__9__1">
      <inertial>
        <origin xyz="2.865579871724755e-07 1.0929456925601322e-07 ${sign*0.00250000000008746}" rpy="0 0 0"/>
        <mass value="0.008795084983265406"/>
        <inertia ixx="0.0" iyy="0.0" izz="0.0" ixy="0.0" iyz="0.0" ixz="0.0"/>
      </inertial>
      <visual>
        <origin xyz="-0.021028 0.30222 ${sign*-0.0596}" rpy="0 0 0"/>
        <geometry>
          <mesh filename="package://dropbear_right_arm/meshes/${folder}/6mm-bearing__9__1.stl" scale="0.001 0.001 0.001"/>
        </geometry>
        <material name="opaque244244244"/>
      </visual>
      <collision>
        <origin xyz="-0.021028 0.30222 ${sign*-0.0596}" rpy="0 0 0"/>
        <geometry>
          <mesh filename="package://dropbear_right_arm/meshes/${folder}/6mm-bearing__9__1.stl" scale="0.001 0.001 0.001"/>
        </geometry>
      </collision>
    </link>
    
    <link name="${prefix}_straight-tendon_1">
      <inertial>
        <origin xyz="0.016982130987867106 -0.03009616821723135 ${sign*0.011870768566949505}" rpy="0 0 0"/>
        <mass value="0.03848915304566222"/>
        <inertia ixx="1.4e-05" iyy="3.2e-05" izz="2.1e-05" ixy="-0.0" iyz="-0.0" ixz="-1.2e-05"/>
      </inertial>
      <visual>
        <origin xyz="-0.021028 0.30722 ${sign*-0.0646}" rpy="0 0 0"/>
        <geometry>
          <mesh filename="package://dropbear_right_arm/meshes/${folder}/straight-tendon_1.stl" scale="0.001 0.001 0.001"/>
        </geometry>
        <material name="opaque191191191"/>
      </visual>
      <collision>
        <origin xyz="-0.021028 0.30722 ${sign*-0.0646}" rpy="0 0 0"/>
        <geometry>
          <mesh filename="package://dropbear_right_arm/meshes/${folder}/straight-tendon_1.stl" scale="0.001 0.001 0.001"/>
        </geometry>
      </collision>
    </link>
    
    <link name="${prefix}_6mm-bearing__1__1">
      <inertial>
        <origin xyz="2.7684984724163364e-07 3.2034255134649747e-07 ${sign*-0.002499999999997768}" rpy="0 0 0"/>
        <mass value="0.008795084983265406"/>
        <inertia ixx="0.0" iyy="0.0" izz="0.0" ixy="-0.0" iyz="0.0" ixz="0.0"/>
      </inertial>
      <visual>
        <origin xyz="-0.002451 0.33622 ${sign*-0.0936}" rpy="0 0 0"/>
        <geometry>
          <mesh filename="package://dropbear_right_arm/meshes/${folder}/6mm-bearing__1__1.stl" scale="0.001 0.001 0.001"/>
        </geometry>
        <material name="opaque244244244"/>
      </visual>
      <collision>
        <origin xyz="-0.002451 0.33622 ${sign*-0.0936}" rpy="0 0 0"/>
        <geometry>
          <mesh filename="package://dropbear_right_arm/meshes/${folder}/6mm-bearing__1__1.stl" scale="0.001 0.001 0.001"/>
        </geometry>
      </collision>
    </link>
    
    <link name="${prefix}_6mm-bearing__5__1">
      <inertial>
        <origin xyz="-2.579352154363779e-07 -2.4019200871305824e-07 ${sign*0.0025000000000022435}" rpy="0 0 0"/>
        <mass value="0.008795084983265406"/>
        <inertia ixx="0.0" iyy="0.0" izz="0.0" ixy="0.0" iyz="0.0" ixz="0.0"/>
      </inertial>
      <visual>
        <origin xyz="-0.00254 0.30222 ${sign*-0.0596}" rpy="0 0 0"/>
        <geometry>
          <mesh filename="package://dropbear_right_arm/meshes/${folder}/6mm-bearing__5__1.stl" scale="0.001 0.001 0.001"/>
        </geometry>
        <material name="opaque244244244"/>
      </visual>
      <collision>
        <origin xyz="-0.00254 0.30222 ${sign*-0.0596}" rpy="0 0 0"/>
        <geometry>
          <mesh filename="package://dropbear_right_arm/meshes/${folder}/6mm-bearing__5__1.stl" scale="0.001 0.001 0.001"/>
        </geometry>
      </collision>
    </link>
    
    <link name="${prefix}_6mm-bearing__2__1">
      <inertial>
        <origin xyz="-3.244389845113993e-07 -4.2206160963398354e-07 ${sign*-0.002499999999997643}" rpy="0 0 0"/>
        <mass value="0.008795084983265406"/>
        <inertia ixx="0.0" iyy="0.0" izz="0.0" ixy="0.0" iyz="0.0" ixz="0.0"/>
      </inertial>
      <visual>
        <origin xyz="0.023714 0.33622 ${sign*-0.0936}" rpy="0 0 0"/>
        <geometry>
          <mesh filename="package://dropbear_right_arm/meshes/${folder}/6mm-bearing__2__1.stl" scale="0.001 0.001 0.001"/>
        </geometry>
        <material name="opaque244244244"/>
      </visual>
      <collision>
        <origin xyz="0.023714 0.33622 ${sign*-0.0936}" rpy="0 0 0"/>
        <geometry>
          <mesh filename="package://dropbear_right_arm/meshes/${folder}/6mm-bearing__2__1.stl" scale="0.001 0.001 0.001"/>
        </geometry>
      </collision>
    </link>
    
    <link name="${prefix}_elbow-bridge-rear__1__1">
      <inertial>
        <origin xyz="0.00037731086861581 -0.0006154201679538229 ${sign*-0.012000384647695192}" rpy="0 0 0"/>
        <mass value="0.0033585279582303566"/>
        <inertia ixx="0.0" iyy="0.0" izz="0.0" ixy="-0.0" iyz="-0.0" ixz="0.0"/>
      </inertial>
      <visual>
        <origin xyz="0.023714 0.33122 ${sign*-0.0886}" rpy="0 0 0"/>
        <geometry>
          <mesh filename="package://dropbear_right_arm/meshes/${folder}/elbow-bridge-rear__1__1.stl" scale="0.001 0.001 0.001"/>
        </geometry>
        <material name="opaque22122113"/>
      </visual>
      <collision>
        <origin xyz="0.023714 0.33122 ${sign*-0.0886}" rpy="0 0 0"/>
        <geometry>
          <mesh filename="package://dropbear_right_arm/meshes/${folder}/elbow-bridge-rear__1__1.stl" scale="0.001 0.001 0.001"/>
        </geometry>
      </collision>
    </link>
    
    <link name="${prefix}_6mm-bearing__6__1">
      <inertial>
        <origin xyz="1.4077586790728347e-07 1.740391428195487e-08 ${sign*0.0025000000000023684}" rpy="0 0 0"/>
        <mass value="0.008795084983265406"/>
        <inertia ixx="0.0" iyy="0.0" izz="0.0" ixy="-0.0" iyz="0.0" ixz="0.0"/>
      </inertial>
      <visual>
        <origin xyz="0.023625 0.30222 ${sign*-0.0596}" rpy="0 0 0"/>
        <geometry>
          <mesh filename="package://dropbear_right_arm/meshes/${folder}/6mm-bearing__6__1.stl" scale="0.001 0.001 0.001"/>
        </geometry>
        <material name="opaque244244244"/>
      </visual>
      <collision>
        <origin xyz="0.023625 0.30222 ${sign*-0.0596}" rpy="0 0 0"/>
        <geometry>
          <mesh filename="package://dropbear_right_arm/meshes/${folder}/6mm-bearing__6__1.stl" scale="0.001 0.001 0.001"/>
        </geometry>
      </collision>
    </link>
    
    <link name="${prefix}_elbow-rear-hanger__1__1">
      <inertial>
        <origin xyz="0.02934379676100346 0.008989918119322815 ${sign*-0.004053673616636819}" rpy="0 0 0"/>
        <mass value="0.010281646529262634"/>
        <inertia ixx="4e-06" iyy="4e-06" izz="1e-06" ixy="-0.0" iyz="-0.0" ixz="1e-06"/>
      </inertial>
      <visual>
        <origin xyz="0.023714 0.33622 ${sign*-0.0936}" rpy="0 0 0"/>
        <geometry>
          <mesh filename="package://dropbear_right_arm/meshes/${folder}/elbow-rear-hanger__1__1.stl" scale="0.001 0.001 0.001"/>
        </geometry>
        <material name="opaque808080"/>
      </visual>
      <collision>
        <origin xyz="0.023714 0.33622 ${sign*-0.0936}" rpy="0 0 0"/>
        <geometry>
          <mesh filename="package://dropbear_right_arm/meshes/${folder}/elbow-rear-hanger__1__1.stl" scale="0.001 0.001 0.001"/>
        </geometry>
      </collision>
    </link>
    
    <link name="${prefix}_elbow-rear-hanger_1">
      <inertial>
        <origin xyz="0.029350657033763494 0.008974172754350793 ${sign*0.004053673616641912}" rpy="0 0 0"/>
        <mass value="0.010281646529262634"/>
        <inertia ixx="4e-06" iyy="4e-06" izz="1e-06" ixy="0.0" iyz="0.0" ixz="1e-06"/>
      </inertial>
      <visual>
        <origin xyz="0.023625 0.30222 ${sign*-0.0596}" rpy="0 0 0"/>
        <geometry>
          <mesh filename="package://dropbear_right_arm/meshes/${folder}/elbow-rear-hanger_1.stl" scale="0.001 0.001 0.001"/>
        </geometry>
        <material name="opaque808080"/>
      </visual>
      <collision>
        <origin xyz="0.023625 0.30222 ${sign*-0.0596}" rpy="0 0 0"/>
        <geometry>
          <mesh filename="package://dropbear_right_arm/meshes/${folder}/elbow-rear-hanger_1.stl" scale="0.001 0.001 0.001"/>
        </geometry>
      </collision>
    </link>
    
    <!-- <link name="${prefix}_6mm-bearing__7__1">
      <inertial>
        <origin xyz="-3.636756962244192e-08 -4.999536466626653e-07 ${sign*0.002500000000108589}" rpy="0 0 0"/>
        <mass value="0.0007422012644105828"/>
        <inertia ixx="0.0" iyy="0.0" izz="0.0" ixy="0.0" iyz="0.0" ixz="0.0"/>
      </inertial>
      <visual>
        <origin xyz="-0.30936 -0.080341 ${sign*-0.0596}" rpy="0 0 0"/>
        <geometry>
          <mesh filename="package://dropbear_right_arm/meshes/${folder}/6mm-bearing__7__1.stl" scale="0.001 0.001 0.001"/>
        </geometry>
        <material name="opaque244244244"/>
      </visual>
      <collision>
        <origin xyz="-0.30936 -0.080341 ${sign*-0.0596}" rpy="0 0 0"/>
        <geometry>
          <mesh filename="package://dropbear_right_arm/meshes/${folder}/6mm-bearing__7__1.stl" scale="0.001 0.001 0.001"/>
        </geometry>
      </collision>
    </link> -->
    
    <link name="${prefix}_6mm-bearing__4__1">
      <inertial>
        <origin xyz="-3.636765966152922e-08 -4.999536816763239e-07 ${sign*-0.00249999999989145}" rpy="0 0 0"/>
        <mass value="0.008795084983265406"/>
        <inertia ixx="0.0" iyy="0.0" izz="0.0" ixy="-0.0" iyz="0.0" ixz="-0.0"/>
      </inertial>
      <visual>
        <origin xyz="0.043015 0.33622 ${sign*-0.0936}" rpy="0 0 0"/>
        <geometry>
          <mesh filename="package://dropbear_right_arm/meshes/${folder}/6mm-bearing__4__1.stl" scale="0.001 0.001 0.001"/>
        </geometry>
        <material name="opaque244244244"/>
      </visual>
      <collision>
        <origin xyz="0.043015 0.33622 ${sign*-0.0936}" rpy="0 0 0"/>
        <geometry>
          <mesh filename="package://dropbear_right_arm/meshes/${folder}/6mm-bearing__4__1.stl" scale="0.001 0.001 0.001"/>
        </geometry>
      </collision>
    </link>
    
    <link name="${prefix}_forearm-elbow-motor-bracket-inner2_1">
      <inertial>
        <origin xyz="0.01210452779343929 0.018768296075041158 ${sign*0.006000210735618364}" rpy="0 0 0"/>
        <mass value="0.022472125475631318"/>
        <inertia ixx="3e-06" iyy="1e-05" izz="7e-06" ixy="-0.0" iyz="-0.0" ixz="1e-06"/>
      </inertial>
      <visual>
        <origin xyz="0.043015 0.33622 ${sign*-0.0936}" rpy="0 0 0"/>
        <geometry>
          <mesh filename="package://dropbear_right_arm/meshes/${folder}/forearm-elbow-motor-bracket-inner2_1.stl" scale="0.001 0.001 0.001"/>
        </geometry>
        <material name="opaque22122113"/>
      </visual>
      <collision>
        <origin xyz="0.043015 0.33622 ${sign*-0.0936}" rpy="0 0 0"/>
        <geometry>
          <mesh filename="package://dropbear_right_arm/meshes/${folder}/forearm-elbow-motor-bracket-inner2_1.stl" scale="0.001 0.001 0.001"/>
        </geometry>
      </collision>
    </link>
    
    <link name="${prefix}_6mm-bearing__3__1">
      <inertial>
        <origin xyz="-3.3812888700079924e-07 -4.80847968137299e-07 ${sign*-0.0024999999998957523}" rpy="0 0 0"/>
        <mass value="0.008795084983265406"/>
        <inertia ixx="0.0" iyy="0.0" izz="0.0" ixy="0.0" iyz="0.0" ixz="0.0"/>
      </inertial>
      <visual>
        <origin xyz="0.009974 0.33622 ${sign*-0.0936}" rpy="0 0 0"/>
        <geometry>
          <mesh filename="package://dropbear_right_arm/meshes/${folder}/6mm-bearing__3__1.stl" scale="0.001 0.001 0.001"/>
        </geometry>
        <material name="opaque244244244"/>
      </visual>
      <collision>
        <origin xyz="0.009974 0.33622 ${sign*-0.0936}" rpy="0 0 0"/>
        <geometry>
          <mesh filename="package://dropbear_right_arm/meshes/${folder}/6mm-bearing__3__1.stl" scale="0.001 0.001 0.001"/>
        </geometry>
      </collision>
    </link>
    
    <link name="${prefix}_elbow-bridge-rear_1">
      <inertial>
        <origin xyz="0.00017362146100646791 0.0006999255750166633 ${sign*-0.012000384647593357}" rpy="0 0 0"/>
        <mass value="0.0033585279582303566"/>
        <inertia ixx="0.0" iyy="0.0" izz="0.0" ixy="0.0" iyz="-0.0" ixz="-0.0"/>
      </inertial>
      <visual>
        <origin xyz="0.009974 0.33122 ${sign*-0.0886}" rpy="0 0 0"/>
        <geometry>
          <mesh filename="package://dropbear_right_arm/meshes/${folder}/elbow-bridge-rear_1.stl" scale="0.001 0.001 0.001"/>
        </geometry>
        <material name="opaque22122113"/>
      </visual>
      <collision>
        <origin xyz="0.009974 0.33122 ${sign*-0.0886}" rpy="0 0 0"/>
        <geometry>
          <mesh filename="package://dropbear_right_arm/meshes/${folder}/elbow-bridge-rear_1.stl" scale="0.001 0.001 0.001"/>
        </geometry>
      </collision>
    </link>
    
    <link name="${prefix}_second-forearm-motor-strap_1">
      <inertial>
        <origin xyz="0.014708936033833275 -0.02081565891948628 ${sign*0.002509257258482181}" rpy="0 0 0"/>
        <mass value="0.015379539400534015"/>
        <inertia ixx="2e-06" iyy="6e-06" izz="4e-06" ixy="-0.0" iyz="0.0" ixz="0.0"/>
      </inertial>
      <visual>
        <origin xyz="-2e-05 0.34772 ${sign*-0.1051}" rpy="0 0 0"/>
        <geometry>
          <mesh filename="package://dropbear_right_arm/meshes/${folder}/second-forearm-motor-strap_1.stl" scale="0.001 0.001 0.001"/>
        </geometry>
        <material name="opaque245245245"/>
      </visual>
      <collision>
        <origin xyz="-2e-05 0.34772 ${sign*-0.1051}" rpy="0 0 0"/>
        <geometry>
          <mesh filename="package://dropbear_right_arm/meshes/${folder}/second-forearm-motor-strap_1.stl" scale="0.001 0.001 0.001"/>
        </geometry>
      </collision>
    </link>
    
    <link name="${prefix}_RMD-X8-Pro_MIR8_MIR1__4__1">
      <inertial>
        <origin xyz="0.018861805978547308 -0.007520690639387845 ${sign*-0.04040576070339569}" rpy="0 0 0"/>
        <mass value="0.7802158462059968"/>
        <inertia ixx="0.000765" iyy="0.000753" izz="0.001111" ixy="0.0" iyz="-9e-06" ixz="-1.2e-05"/>
      </inertial>
      <visual>
        <origin xyz="0.009196 0.348665 ${sign*-0.106044}" rpy="0 0 0"/>
        <geometry>
          <mesh filename="package://dropbear_right_arm/meshes/${folder}/RMD-X8-Pro_MIR8_MIR1__4__1.stl" scale="0.001 0.001 0.001"/>
        </geometry>
        <material name="opaque13110895"/>
      </visual>
      <collision>
        <origin xyz="0.009196 0.348665 ${sign*-0.106044}" rpy="0 0 0"/>
        <geometry>
          <mesh filename="package://dropbear_right_arm/meshes/${folder}/RMD-X8-Pro_MIR8_MIR1__4__1.stl" scale="0.001 0.001 0.001"/>
        </geometry>
      </collision>
    </link>
    
    <link name="${prefix}_fore-arm-bicep-motor-attatch_1">
      <inertial>
        <origin xyz="-0.009651244394266734 -0.03898859615972326 ${sign*0.00035796122303864003}" rpy="0 0 0"/>
        <mass value="0.02451696606358365"/>
        <inertia ixx="2e-06" iyy="1.5e-05" izz="1.3e-05" ixy="-0.0" iyz="0.0" ixz="-0.0"/>
      </inertial>
      <visual>
        <origin xyz="-0.011791 0.284033 ${sign*-0.041413}" rpy="0 0 0"/>
        <geometry>
          <mesh filename="package://dropbear_right_arm/meshes/${folder}/fore-arm-bicep-motor-attatch_1.stl" scale="0.001 0.001 0.001"/>
        </geometry>
        <material name="opaque245245245"/>
      </visual>
      <collision>
        <origin xyz="-0.011791 0.284033 ${sign*-0.041413}" rpy="0 0 0"/>
        <geometry>
          <mesh filename="package://dropbear_right_arm/meshes/${folder}/fore-arm-bicep-motor-attatch_1.stl" scale="0.001 0.001 0.001"/>
        </geometry>
      </collision>
    </link>
    
    <link name="${prefix}_forearm-elbow-motor-bracket-inner_1">
      <inertial>
        <origin xyz="0.002543710639871688 -0.02871711147828905 ${sign*0.005494237705661112}" rpy="0 0 0"/>
        <mass value="0.022768388482805414"/>
        <inertia ixx="3e-06" iyy="1e-05" izz="7e-06" ixy="0.0" iyz="0.0" ixz="1e-06"/>
      </inertial>
      <visual>
        <origin xyz="-1.9e-05 0.29072 ${sign*-0.0481}" rpy="0 0 0"/>
        <geometry>
          <mesh filename="package://dropbear_right_arm/meshes/${folder}/forearm-elbow-motor-bracket-inner_1.stl" scale="0.001 0.001 0.001"/>
        </geometry>
        <material name="opaque22122113"/>
      </visual>
      <collision>
        <origin xyz="-1.9e-05 0.29072 ${sign*-0.0481}" rpy="0 0 0"/>
        <geometry>
          <mesh filename="package://dropbear_right_arm/meshes/${folder}/forearm-elbow-motor-bracket-inner_1.stl" scale="0.001 0.001 0.001"/>
        </geometry>
      </collision>
    </link>
    
    <link name="${prefix}_6mm-bearing__8__1">
      <inertial>
        <origin xyz="1.8166938153818535e-07 -6.957382656103128e-08 ${sign*0.0025000000001725795}" rpy="0 0 0"/>
        <mass value="0.008795084983265406"/>
        <inertia ixx="0.0" iyy="0.0" izz="0.0" ixy="-0.0" iyz="0.0" ixz="-0.0"/>
      </inertial>
      <visual>
        <origin xyz="0.009975 0.30222 ${sign*-0.0596}" rpy="0 0 0"/>
        <geometry>
          <mesh filename="package://dropbear_right_arm/meshes/${folder}/6mm-bearing__8__1.stl" scale="0.001 0.001 0.001"/>
        </geometry>
        <material name="opaque244244244"/>
      </visual>
      <collision>
        <origin xyz="0.009975 0.30222 ${sign*-0.0596}" rpy="0 0 0"/>
        <geometry>
          <mesh filename="package://dropbear_right_arm/meshes/${folder}/6mm-bearing__8__1.stl" scale="0.001 0.001 0.001"/>
        </geometry>
      </collision>
    </link>
    
    <link name="${prefix}_shoulder-ex-al-interface_1">
      <inertial>
        <origin xyz="0.008777069212284438 0.002847989226232972 ${sign*1.0648426584936033e-13}" rpy="0 0 0"/>
        <mass value="0.03263560284613005"/>
        <inertia ixx="7e-06" iyy="4e-06" izz="1e-05" ixy="-0.0" iyz="-0.0" ixz="-0.0"/>
      </inertial>
      <visual>
        <origin xyz="0.020895 0.30872 ${sign*-0.0661}" rpy="0 0 0"/>
        <geometry>
          <mesh filename="package://dropbear_right_arm/meshes/${folder}/shoulder-ex-al-interface_1.stl" scale="0.001 0.001 0.001"/>
        </geometry>
        <material name="opaque22122113"/>
      </visual>
      <collision>
        <origin xyz="0.020895 0.30872 ${sign*-0.0661}" rpy="0 0 0"/>
        <geometry>
          <mesh filename="package://dropbear_right_arm/meshes/${folder}/shoulder-ex-al-interface_1.stl" scale="0.001 0.001 0.001"/>
        </geometry>
      </collision>
    </link>
    
    <link name="${prefix}_shoulder-roll-al-mot_MIR1__3__1">
      <inertial>
        <origin xyz="0.015475495394150607 -0.0044405328981518 ${sign*-0.0010043671574723606}" rpy="0 0 0"/>
        <mass value="0.016359268258045713"/>
        <inertia ixx="1e-06" iyy="3e-06" izz="2e-06" ixy="-0.0" iyz="0.0" ixz="-0.0"/>
      </inertial>
      <visual>
        <origin xyz="0.011298 0.293132 ${sign*-0.050512}" rpy="0 0 0"/>
        <geometry>
          <mesh filename="package://dropbear_right_arm/meshes/${folder}/shoulder-roll-al-mot_MIR1__3__1.stl" scale="0.001 0.001 0.001"/>
        </geometry>
        <material name="opaque245245245"/>
      </visual>
      <collision>
        <origin xyz="0.011298 0.293132 ${sign*-0.050512}" rpy="0 0 0"/>
        <geometry>
          <mesh filename="package://dropbear_right_arm/meshes/${folder}/shoulder-roll-al-mot_MIR1__3__1.stl" scale="0.001 0.001 0.001"/>
        </geometry>
      </collision>
    </link>
    
    <link name="${prefix}_shoulder-roll-al-mot_MIR1_1">
      <inertial>
        <origin xyz="0.015475426626878619 -0.004440320984141877 ${sign*0.0010033671576757525}" rpy="0 0 0"/>
        <mass value="0.016359268258045713"/>
        <inertia ixx="1e-06" iyy="3e-06" izz="2e-06" ixy="0.0" iyz="-0.0" ixz="-0.0"/>
      </inertial>
      <visual>
        <origin xyz="0.011298 0.324309 ${sign*-0.081689}" rpy="0 0 0"/>
        <geometry>
          <mesh filename="package://dropbear_right_arm/meshes/${folder}/shoulder-roll-al-mot_MIR1_1.stl" scale="0.001 0.001 0.001"/>
        </geometry>
        <material name="opaque245245245"/>
      </visual>
      <collision>
        <origin xyz="0.011298 0.324309 ${sign*-0.081689}" rpy="0 0 0"/>
        <geometry>
          <mesh filename="package://dropbear_right_arm/meshes/${folder}/shoulder-roll-al-mot_MIR1_1.stl" scale="0.001 0.001 0.001"/>
        </geometry>
      </collision>
    </link>
    
    <link name="${prefix}_2020_100mm__10__1">
      <inertial>
        <origin xyz="0.04755886079292104 0.015433290864262622 ${sign*1.0068335054569388e-13}" rpy="0 0 0"/>
        <mass value="0.052897718100317556"/>
        <inertia ixx="4.6e-05" iyy="4.6e-05" izz="4e-06" ixy="-0.0" iyz="0.0" ixz="1e-06"/>
      </inertial>
      <visual>
        <origin xyz="0.020293 0.30872 ${sign*-0.0661}" rpy="0 0 0"/>
        <geometry>
          <mesh filename="package://dropbear_right_arm/meshes/${folder}/2020_100mm__10__1.stl" scale="0.001 0.001 0.001"/>
        </geometry>
        <material name="opaque727161"/>
      </visual>
      <collision>
        <origin xyz="0.020293 0.30872 ${sign*-0.0661}" rpy="0 0 0"/>
        <geometry>
          <mesh filename="package://dropbear_right_arm/meshes/${folder}/2020_100mm__10__1.stl" scale="0.001 0.001 0.001"/>
        </geometry>
      </collision>
    </link>
    
    <link name="${prefix}_top-bracket-servo-strap_1">
      <inertial>
        <origin xyz="0.03411014913308452 0.011047031874247631 ${sign*1.204420641340298e-05}" rpy="0 0 0"/>
        <mass value="0.02056602380320786"/>
        <inertia ixx="6e-06" iyy="6e-06" izz="1.1e-05" ixy="0.0" iyz="-0.0" ixz="-0.0"/>
      </inertial>
      <visual>
        <origin xyz="0.020293 0.30872 ${sign*-0.0661}" rpy="0 0 0"/>
        <geometry>
          <mesh filename="package://dropbear_right_arm/meshes/${folder}/top-bracket-servo-strap_1.stl" scale="0.001 0.001 0.001"/>
        </geometry>
        <material name="opaque191191191"/>
      </visual>
      <collision>
        <origin xyz="0.020293 0.30872 ${sign*-0.0661}" rpy="0 0 0"/>
        <geometry>
          <mesh filename="package://dropbear_right_arm/meshes/${folder}/top-bracket-servo-strap_1.stl" scale="0.001 0.001 0.001"/>
        </geometry>
      </collision>
    </link>
    
    <link name="${prefix}_MG995_1">
      <inertial>
        <origin xyz="0.02542053581561582 -0.001276948059540317 ${sign*-0.004850007599141448}" rpy="0 0 0"/>
        <mass value="0.05503731974130738"/>
        <inertia ixx="9e-06" iyy="1.5e-05" izz="9e-06" ixy="-0.0" iyz="0.0" ixz="-0.0"/>
      </inertial>
      <visual>
        <origin xyz="-0.000568 0.29357 ${sign*-0.05095}" rpy="0 0 0"/>
        <geometry>
          <mesh filename="package://dropbear_right_arm/meshes/${folder}/MG995_1.stl" scale="0.001 0.001 0.001"/>
        </geometry>
        <material name="opaque636363"/>
      </visual>
      <collision>
        <origin xyz="-0.000568 0.29357 ${sign*-0.05095}" rpy="0 0 0"/>
        <geometry>
          <mesh filename="package://dropbear_right_arm/meshes/${folder}/MG995_1.stl" scale="0.001 0.001 0.001"/>
        </geometry>
      </collision>
    </link>
    
    <link name="${prefix}_MG995__4__1">
      <inertial>
        <origin xyz="0.02412079550410856 0.002727982934733808 ${sign*0.009060775705328955}" rpy="0 0 0"/>
        <mass value="0.05503731974130738"/>
        <inertia ixx="1.5e-05" iyy="9e-06" izz="9e-06" ixy="0.0" iyz="-0.0" ixz="0.0"/>
      </inertial>
      <visual>
        <origin xyz="0.034162 0.28912 ${sign*-0.0465}" rpy="0 0 0"/>
        <geometry>
          <mesh filename="package://dropbear_right_arm/meshes/${folder}/MG995__4__1.stl" scale="0.001 0.001 0.001"/>
        </geometry>
        <material name="opaque636363"/>
      </visual>
      <collision>
        <origin xyz="0.034162 0.28912 ${sign*-0.0465}" rpy="0 0 0"/>
        <geometry>
          <mesh filename="package://dropbear_right_arm/meshes/${folder}/MG995__4__1.stl" scale="0.001 0.001 0.001"/>
        </geometry>
      </collision>
    </link>
    
    <link name="${prefix}_MG995__3__1">
      <inertial>
        <origin xyz="0.019827623818259865 0.015959817195865075 ${sign*0.004850007599342093}" rpy="0 0 0"/>
        <mass value="0.05503731974130738"/>
        <inertia ixx="9e-06" iyy="1.5e-05" izz="9e-06" ixy="-0.0" iyz="-0.0" ixz="0.0"/>
      </inertial>
      <visual>
        <origin xyz="0.038609 0.32387 ${sign*-0.08125}" rpy="0 0 0"/>
        <geometry>
          <mesh filename="package://dropbear_right_arm/meshes/${folder}/MG995__3__1.stl" scale="0.001 0.001 0.001"/>
        </geometry>
        <material name="opaque636363"/>
      </visual>
      <collision>
        <origin xyz="0.038609 0.32387 ${sign*-0.08125}" rpy="0 0 0"/>
        <geometry>
          <mesh filename="package://dropbear_right_arm/meshes/${folder}/MG995__3__1.stl" scale="0.001 0.001 0.001"/>
        </geometry>
      </collision>
    </link>
    
    <link name="${prefix}_MG995__5__1">
      <inertial>
        <origin xyz="0.021127364129767012 0.011954886201590936 ${sign*-0.009060775705128143}" rpy="0 0 0"/>
        <mass value="0.05503731974130738"/>
        <inertia ixx="1.5e-05" iyy="9e-06" izz="9e-06" ixy="-0.0" iyz="0.0" ixz="0.0"/>
      </inertial>
      <visual>
        <origin xyz="0.00388 0.32832 ${sign*-0.0857}" rpy="0 0 0"/>
        <geometry>
          <mesh filename="package://dropbear_right_arm/meshes/${folder}/MG995__5__1.stl" scale="0.001 0.001 0.001"/>
        </geometry>
        <material name="opaque636363"/>
      </visual>
      <collision>
        <origin xyz="0.00388 0.32832 ${sign*-0.0857}" rpy="0 0 0"/>
        <geometry>
          <mesh filename="package://dropbear_right_arm/meshes/${folder}/MG995__5__1.stl" scale="0.001 0.001 0.001"/>
        </geometry>
      </collision>
    </link>
    
    <link name="${prefix}_2020_100mm__11__1">
      <inertial>
        <origin xyz="0.09510320422272961 0.030861694308185278 ${sign*9.919842725025774e-14}" rpy="0 0 0"/>
        <mass value="0.05289771810031747"/>
        <inertia ixx="4.6e-05" iyy="4.6e-05" izz="4e-06" ixy="-0.0" iyz="0.0" ixz="1e-06"/>
      </inertial>
      <visual>
        <origin xyz="0.020293 0.30872 ${sign*-0.0661}" rpy="0 0 0"/>
        <geometry>
          <mesh filename="package://dropbear_right_arm/meshes/${folder}/2020_100mm__11__1.stl" scale="0.001 0.001 0.001"/>
        </geometry>
        <material name="opaque727161"/>
      </visual>
      <collision>
        <origin xyz="0.020293 0.30872 ${sign*-0.0661}" rpy="0 0 0"/>
        <geometry>
          <mesh filename="package://dropbear_right_arm/meshes/${folder}/2020_100mm__11__1.stl" scale="0.001 0.001 0.001"/>
        </geometry>
      </collision>
    </link>
    
    <link name="${prefix}_top-bracket-servo-strap__1__1">
      <inertial>
        <origin xyz="-0.009381861774768185 -0.0030667560010047834 ${sign*-1.2044206214339992e-05}" rpy="0 0 0"/>
        <mass value="0.02056602380320786"/>
        <inertia ixx="6e-06" iyy="6e-06" izz="1.1e-05" ixy="-0.0" iyz="-0.0" ixz="-0.0"/>
      </inertial>
      <visual>
        <origin xyz="0.015134 0.30872 ${sign*-0.0661}" rpy="0 0 0"/>
        <geometry>
          <mesh filename="package://dropbear_right_arm/meshes/${folder}/top-bracket-servo-strap__1__1.stl" scale="0.001 0.001 0.001"/>
        </geometry>
        <material name="opaque191191191"/>
      </visual>
      <collision>
        <origin xyz="0.015134 0.30872 ${sign*-0.0661}" rpy="0 0 0"/>
        <geometry>
          <mesh filename="package://dropbear_right_arm/meshes/${folder}/top-bracket-servo-strap__1__1.stl" scale="0.001 0.001 0.001"/>
        </geometry>
      </collision>
    </link>
    
    <link name="${prefix}_MG995__2__1">
      <inertial>
        <origin xyz="-0.024121471517170034 -0.0027287589888995434 ${sign*0.009060775705327699}" rpy="0 0 0"/>
        <mass value="0.05503731974130738"/>
        <inertia ixx="1.5e-05" iyy="9e-06" izz="9e-06" ixy="-0.0" iyz="0.0" ixz="0.0"/>
      </inertial>
      <visual>
        <origin xyz="0.000371 0.28912 ${sign*-0.0465}" rpy="0 0 0"/>
        <geometry>
          <mesh filename="package://dropbear_right_arm/meshes/${folder}/MG995__2__1.stl" scale="0.001 0.001 0.001"/>
        </geometry>
        <material name="opaque636363"/>
      </visual>
      <collision>
        <origin xyz="0.000371 0.28912 ${sign*-0.0465}" rpy="0 0 0"/>
        <geometry>
          <mesh filename="package://dropbear_right_arm/meshes/${folder}/MG995__2__1.stl" scale="0.001 0.001 0.001"/>
        </geometry>
      </collision>
    </link>
    
    <link name="${prefix}_MG995__6__1">
      <inertial>
        <origin xyz="-0.025421211828677737 0.0012771720053743607 ${sign*-0.00485000759914328}" rpy="0 0 0"/>
        <mass value="0.05503731974130738"/>
        <inertia ixx="9e-06" iyy="1.5e-05" izz="9e-06" ixy="0.0" iyz="-0.0" ixz="-0.0"/>
      </inertial>
      <visual>
        <origin xyz="0.035101 0.29357 ${sign*-0.05095}" rpy="0 0 0"/>
        <geometry>
          <mesh filename="package://dropbear_right_arm/meshes/${folder}/MG995__6__1.stl" scale="0.001 0.001 0.001"/>
        </geometry>
        <material name="opaque636363"/>
      </visual>
      <collision>
        <origin xyz="0.035101 0.29357 ${sign*-0.05095}" rpy="0 0 0"/>
        <geometry>
          <mesh filename="package://dropbear_right_arm/meshes/${folder}/MG995__6__1.stl" scale="0.001 0.001 0.001"/>
        </geometry>
      </collision>
    </link>
    
    <link name="${prefix}_MG995__1__1">
      <inertial>
        <origin xyz="-0.02112704014282696 -0.011954662255756893 ${sign*-0.009060775705130197}" rpy="0 0 0"/>
        <mass value="0.05503731974130738"/>
        <inertia ixx="1.5e-05" iyy="9e-06" izz="9e-06" ixy="0.0" iyz="-0.0" ixz="0.0"/>
      </inertial>
      <visual>
        <origin xyz="0.030654 0.32832 ${sign*-0.0857}" rpy="0 0 0"/>
        <geometry>
          <mesh filename="package://dropbear_right_arm/meshes/${folder}/MG995__1__1.stl" scale="0.001 0.001 0.001"/>
        </geometry>
        <material name="opaque636363"/>
      </visual>
      <collision>
        <origin xyz="0.030654 0.32832 ${sign*-0.0857}" rpy="0 0 0"/>
        <geometry>
          <mesh filename="package://dropbear_right_arm/meshes/${folder}/MG995__1__1.stl" scale="0.001 0.001 0.001"/>
        </geometry>
      </collision>
    </link>
    
    <link name="${prefix}_MG995__7__1">
      <inertial>
        <origin xyz="-0.019827299831319145 -0.0159595932500311 ${sign*0.004850007599340733}" rpy="0 0 0"/>
        <mass value="0.05503731974130738"/>
        <inertia ixx="9e-06" iyy="1.5e-05" izz="9e-06" ixy="0.0" iyz="0.0" ixz="0.0"/>
      </inertial>
      <visual>
        <origin xyz="-0.004076 0.32387 ${sign*-0.08125}" rpy="0 0 0"/>
        <geometry>
          <mesh filename="package://dropbear_right_arm/meshes/${folder}/MG995__7__1.stl" scale="0.001 0.001 0.001"/>
        </geometry>
        <material name="opaque636363"/>
      </visual>
      <collision>
        <origin xyz="-0.004076 0.32387 ${sign*-0.08125}" rpy="0 0 0"/>
        <geometry>
          <mesh filename="package://dropbear_right_arm/meshes/${folder}/MG995__7__1.stl" scale="0.001 0.001 0.001"/>
        </geometry>
      </collision>
    </link>
    
    <link name="${prefix}_multiplex-stack-flat_1">
      <inertial>
        <origin xyz="-0.010298214415190743 0.0316942752130374 ${sign*0.007502408653395604}" rpy="0 0 0"/>
        <mass value="0.023031674197712796"/>
        <inertia ixx="3e-06" iyy="3.1e-05" izz="2.8e-05" ixy="0.0" iyz="0.0" ixz="-1e-06"/>
      </inertial>
      <visual>
        <origin xyz="0.066975 0.32972 ${sign*-0.0871}" rpy="0 0 0"/>
        <geometry>
          <mesh filename="package://dropbear_right_arm/meshes/${folder}/multiplex-stack-flat_1.stl" scale="0.001 0.001 0.001"/>
        </geometry>
        <material name="opaque191191191"/>
      </visual>
      <collision>
        <origin xyz="0.066975 0.32972 ${sign*-0.0871}" rpy="0 0 0"/>
        <geometry>
          <mesh filename="package://dropbear_right_arm/meshes/${folder}/multiplex-stack-flat_1.stl" scale="0.001 0.001 0.001"/>
        </geometry>
      </collision>
    </link>
    
    <joint name="${prefix}_torso_connection" type="fixed">
      <xacro:insert_block name="origin"/>
      <parent link="${parent}"/>
      <child link="${prefix}_2020_100mm__9__1"/>
    </joint>

    <joint name="${prefix}_Rigid2" type="fixed">
      <origin xyz="0.0 0.0 ${sign*0.0}" rpy="0 0 0"/>
      <parent link="${prefix}_2020_100mm__9__1"/>
      <child link="${prefix}_shoulder-roll-al-mot_MIR1__1__1"/>
    </joint>
    
    <joint name="${prefix}_Rigid3" type="fixed">
      <origin xyz="0.0 0.0 ${sign*0.0}" rpy="0 0 0"/>
      <parent link="${prefix}_2020_100mm__9__1"/>
      <child link="${prefix}_shoulder-roll-al-mot_MIR1__2__1"/>
    </joint>
    
    <joint name="${prefix}_Rigid4" type="fixed">
      <origin xyz="0.0 -0.1 ${sign*0.1}" rpy="0 0 0"/>
      <parent link="${prefix}_2020_100mm__9__1"/>
      <child link="${prefix}_yaw-cap_1"/>
    </joint>
    
    <joint name="${prefix}_Rigid5" type="fixed">
      <origin xyz="0.0 0.0 ${sign*0.0}" rpy="0 0 0"/>
      <parent link="${prefix}_2020_100mm__9__1"/>
      <child link="${prefix}_yaw-waist-adapter-motor-exal_MIR1_1"/>
    </joint>
    
    <joint name="${prefix}_Rigid6" type="fixed">
      <origin xyz="0.019446 -0.059 ${sign*0.059}" rpy="0 0 0"/>
      <parent link="${prefix}_yaw-waist-adapter-motor-exal_MIR1_1"/>
      <child link="${prefix}_front-bearing-adapter-shoulder_1"/>
    </joint>
    
    <joint name="${prefix}_Rigid7" type="fixed">
      <origin xyz="-0.010536 -0.059 ${sign*0.059}" rpy="0 0 0"/>
      <parent link="${prefix}_yaw-waist-adapter-motor-exal_MIR1_1"/>
      <child link="${prefix}_shoulder-ex-al-interface__2__1"/>
    </joint>
    
    <joint name="${prefix}_pitch" type="revolute">
      <origin xyz="-0.016448 0.009 ${sign*-0.009}" rpy="0 0 0"/>
      <parent link="${prefix}_shoulder-ex-al-interface__2__1"/>
      <child link="${prefix}_RMD-X8-Pro_MIR8_MIR1__1__1"/>
      <axis xyz="0.309017 -0.951057 0.0"/>
      <limit upper="${PI}" lower="${-PI}" velocity="10.0" effort="10.0"/>
    </joint>
    
    <joint name="${prefix}_Rigid9" type="fixed">
      <origin xyz="-0.036017 0.0 ${sign*0.0}" rpy="0 0 0"/>
      <parent link="${prefix}_RMD-X8-Pro_MIR8_MIR1__1__1"/>
      <child link="${prefix}_shoulder-motor-bicep-rotor-bracket_1"/>
    </joint>
    
    <joint name="${prefix}_Rigid10" type="fixed">
      <origin xyz="0.000626 0.0015 ${sign*-0.0015}" rpy="0 0 0"/>
      <parent link="${prefix}_shoulder-motor-bicep-rotor-bracket_1"/>
      <child link="${prefix}_bicep-rear-motor-adapter_1"/>
    </joint>
    
    <joint name="${prefix}_Rigid11" type="fixed">
      <origin xyz="0.037977 -0.0255 ${sign*0.0255}" rpy="0 0 0"/>
      <parent link="${prefix}_bicep-rear-motor-adapter_1"/>
      <child link="${prefix}_bicep-shoulder-bracket-exal__1__1"/>
    </joint>
    
    <joint name="${prefix}_Rigid12" type="fixed">
      <origin xyz="0.037977 -0.0055 ${sign*0.0055}" rpy="0 0 0"/>
      <parent link="${prefix}_bicep-rear-motor-adapter_1"/>
      <child link="${prefix}_bicep-shoulder-bracket-exal__2__1"/>
    </joint>
    
    <joint name="${prefix}_Rigid13" type="fixed">
      <origin xyz="0.032704 -0.003569 ${sign*0.0}" rpy="0 0 0"/>
      <parent link="${prefix}_bicep-shoulder-bracket-exal__1__1"/>
      <child link="${prefix}_2020_100mm__8__1"/>
    </joint>
    
    <joint name="${prefix}_Rigid14" type="fixed">
      <origin xyz="-0.037322 0.082505 ${sign*-0.01}" rpy="0 0 0"/>
      <parent link="${prefix}_2020_100mm__8__1"/>
      <child link="${prefix}_yaw-waist-adapter-motor-exal_MIR1__5__1"/>
    </joint>
    
    <joint name="${prefix}_Rigid15" type="fixed">
      <origin xyz="-0.027812 0.085595 ${sign*-0.01825}" rpy="0 0 0"/>
      <parent link="${prefix}_2020_100mm__8__1"/>
      <child link="${prefix}_bicep-shoulder-bracket-exal_1"/>
    </joint>
    
    <joint name="${prefix}_Rigid16" type="fixed">
      <origin xyz="-0.008538 0.00175 ${sign*-0.00175}" rpy="0 0 0"/>
      <parent link="${prefix}_bicep-shoulder-bracket-exal_1"/>
      <child link="${prefix}_shoulder-front_1"/>
    </joint>
    
    <joint name="${prefix}_Rigid17" type="fixed">
      <origin xyz="0.0 -0.02 ${sign*0.02}" rpy="0 0 0"/>
      <parent link="${prefix}_shoulder-front_1"/>
      <child link="${prefix}_bicep-shoulder-bracket-exal__3__1"/>
    </joint>
    
    <joint name="${prefix}_Rigid18" type="fixed">
      <origin xyz="0.006869 -0.025 ${sign*0.025}" rpy="0 0 0"/>
      <parent link="${prefix}_shoulder-front_1"/>
      <child link="${prefix}_shoulder-cap_1"/>
    </joint>
    
    <joint name="${prefix}_Rigid19" type="fixed">
      <origin xyz="-0.00146 0.029 ${sign*-0.029}" rpy="0 0 0"/>
      <parent link="${prefix}_shoulder-cap_1"/>
      <child link="${prefix}_shoulder-front-bearing-adapter_1"/>
    </joint>
    
    <joint name="${prefix}_Rigid20" type="fixed">
      <origin xyz="-0.003826 0.0 ${sign*0.0}" rpy="0 0 0"/>
      <parent link="${prefix}_shoulder-front-bearing-adapter_1"/>
      <child link="${prefix}_skateboard-bearing__7__1"/>
    </joint>
    
    <joint name="${prefix}_Rigid21" type="fixed">
      <origin xyz="-0.058616 -0.015589 ${sign*0.015588}" rpy="0 0 0"/>
      <parent link="${prefix}_yaw-waist-adapter-motor-exal_MIR1__5__1"/>
      <child link="${prefix}_shoulder-ex-al-interface__1__1"/>
    </joint>
    
    <joint name="${prefix}_roll" type="revolute">
      <origin xyz="0.009585 0.015589 ${sign*-0.015588}" rpy="0 0 0"/>
      <parent link="${prefix}_shoulder-ex-al-interface__1__1"/>
      <child link="${prefix}_RMD-X8-Pro_MIR8_MIR1__3__1"/>
      <axis xyz="0.951057 0.309017 0.0"/>
      <limit upper="${PI}" lower="${-PI}" velocity="10.0" effort="10.0"/>
    </joint>
    
    <joint name="${prefix}_Rigid23" type="fixed">
      <origin xyz="0.035262 0.024687 ${sign*-0.024687}" rpy="0 0 0"/>
      <parent link="${prefix}_RMD-X8-Pro_MIR8_MIR1__3__1"/>
      <child link="${prefix}_bicep-rotational-cuff-second-motor-bracket_1"/>
    </joint>
    
    <joint name="${prefix}_Rigid24" type="fixed">
      <origin xyz="0.035262 -0.024687 ${sign*0.024687}" rpy="0 0 0"/>
      <parent link="${prefix}_RMD-X8-Pro_MIR8_MIR1__3__1"/>
      <child link="${prefix}_arm-cuff-bicep-bracket_1"/>
    </joint>
    
    <joint name="${prefix}_Rigid25" type="fixed">
      <origin xyz="-0.033193 -0.003313 ${sign*0.003313}" rpy="0 0 0"/>
      <parent link="${prefix}_arm-cuff-bicep-bracket_1"/>
      <child link="${prefix}_RMD-X8-Pro_MIR8_MIR1__2__1"/>
    </joint>
    
    <joint name="${prefix}_Rigid26" type="fixed">
      <origin xyz="0.002921 0.0 ${sign*0.0}" rpy="0 0 0"/>
      <parent link="${prefix}_RMD-X8-Pro_MIR8_MIR1__2__1"/>
      <child link="${prefix}_elbow-hangar_1"/>
    </joint>
    
    <joint name="${prefix}_Rigid27" type="fixed">
      <origin xyz="0.003009 0.035 ${sign*-0.035}" rpy="0 0 0"/>
      <parent link="${prefix}_RMD-X8-Pro_MIR8_MIR1__2__1"/>
      <child link="${prefix}_elbow-hangar1_1"/>
    </joint>
    
    <joint name="${prefix}_Rigid28" type="fixed">
      <origin xyz="-0.038936 0.035 ${sign*-0.035}" rpy="0 0 0"/>
      <parent link="${prefix}_RMD-X8-Pro_MIR8_MIR1__2__1"/>
      <child link="${prefix}_power-mount-arm_1"/>
    </joint>
    
    <joint name="${prefix}_Rigid29" type="fixed">
      <origin xyz="-0.008859 0.0065 ${sign*-0.0065}" rpy="0 0 0"/>
      <parent link="${prefix}_power-mount-arm_1"/>
      <child link="${prefix}_fan-mount_1"/>
    </joint>
    
    <joint name="${prefix}_elbow_joint" type="revolute">
      <origin xyz="0.00146 0.037 ${sign*-0.037}" rpy="0 0 0"/>
      <parent link="${prefix}_RMD-X8-Pro_MIR8_MIR1__2__1"/>
      <child link="${prefix}_bicep-motor-mate_1"/>
      <axis xyz="0.0 0.0 -1.0"/>
      <limit upper="${PI}" lower="${-PI}" velocity="10.0" effort="10.0"/>
    </joint>
    
    <joint name="${prefix}_Rigid31" type="fixed">
      <origin xyz="0.053334 -0.0025 ${sign*0.0025}" rpy="0 0 0"/>
      <parent link="${prefix}_bicep-motor-mate_1"/>
      <child link="${prefix}_6mm-bearing_1"/>
    </joint>
    
    <joint name="${prefix}_Revolute32" type="revolute">
      <origin xyz="0.0 -0.005 ${sign*0.005}" rpy="0 0 0"/>
      <parent link="${prefix}_6mm-bearing_1"/>
      <child link="${prefix}_bicep_1"/>
      <axis xyz="0.0 0.0 1.0"/>
      <limit upper="${PI}" lower="${-PI}" velocity="10.0" effort="10.0"/>
    </joint>
    
    <joint name="${prefix}_Revolute33" type="revolute">
      <origin xyz="-0.004625 0.005 ${sign*-0.005}" rpy="0 0 0"/>
      <parent link="${prefix}_bicep_1"/>
      <child link="${prefix}_6mm-bearing__9__1"/>
      <axis xyz="0.0 0.0 -1.0"/>
      <limit upper="${PI}" lower="${-PI}" velocity="10.0" effort="10.0"/>
    </joint>
    
    <joint name="${prefix}_Rigid34" type="fixed">
      <origin xyz="0.0 -0.005 ${sign*0.005}" rpy="0 0 0"/>
      <parent link="${prefix}_6mm-bearing__9__1"/>
      <child link="${prefix}_straight-tendon_1"/>
    </joint>
    
    <joint name="${prefix}_Rigid35" type="fixed">
      <origin xyz="0.028671 0.0005 ${sign*-0.0005}" rpy="0 0 0"/>
      <parent link="${prefix}_elbow-hangar_1"/>
      <child link="${prefix}_6mm-bearing__1__1"/>
    </joint>
    
    <joint name="${prefix}_Rigid36" type="fixed">
      <origin xyz="0.028672 -0.0005 ${sign*0.0005}" rpy="0 0 0"/>
      <parent link="${prefix}_elbow-hangar1_1"/>
      <child link="${prefix}_6mm-bearing__5__1"/>
    </joint>
    
    <!-- <joint name="${prefix}_Revolute37" type="revolute">
      <origin xyz="0.009963 0.032687 ${sign*0.0005}" rpy="0 0 0"/>
      <parent link="${prefix}_straight-tendon_1"/>
      <child link="${prefix}_6mm-bearing__5__1"/>
      <axis xyz="0.0 0.0 -1.0"/>
      <limit upper="${PI}" lower="${-PI}" velocity="10.0" effort="10.0"/>
    </joint> -->

    <gazebo>
      <plugin name="gazebo_ros" filename="libgazebo_ros_api_plugin.so"/>
      <joint name="${prefix}_Revolute 37 gz" type="revolute">
        <pose relative_to="${prefix}_straight-tendon_1">0.146 0.077 ${sign*-0.0065} 0 0 0</pose>
        <parent>${prefix}_straight-tendon_1</parent>
        <child>${prefix}_6mm-bearing__5__1</child>
  
        <axis>
          <xyz> 0 0 -1</xyz>
        </axis>
        <limit>
          <lower>${-PI}</lower>
          <upper>${PI}</upper>
          <effort>10.0</effort>
          <velocity>10.0</velocity>
        </limit>
        <dynamics>
          <damping>0.0</damping>
          <friction>0.0</friction>
        </dynamics>
  
      </joint>
    </gazebo>
    
    <joint name="${prefix}_Rigid38" type="fixed">
      <origin xyz="0.002506 0.0005 ${sign*-0.0005}" rpy="0 0 0"/>
      <parent link="${prefix}_elbow-hangar_1"/>
      <child link="${prefix}_6mm-bearing__2__1"/>
    </joint>
    
    <joint name="${prefix}_Rigid39" type="fixed">
      <origin xyz="0.0 0.005 ${sign*-0.005}" rpy="0 0 0"/>
      <parent link="${prefix}_6mm-bearing__2__1"/>
      <child link="${prefix}_elbow-bridge-rear__1__1"/>
    </joint>
    
    <joint name="${prefix}_Rigid40" type="fixed">
      <origin xyz="0.002507 -0.0005 ${sign*0.0005}" rpy="0 0 0"/>
      <parent link="${prefix}_elbow-hangar1_1"/>
      <child link="${prefix}_6mm-bearing__6__1"/>
    </joint>
    
    <joint name="${prefix}_Revolute41" type="revolute">
      <origin xyz="0.0 0.0 ${sign*0.0}" rpy="0 0 0"/>
      <parent link="${prefix}_6mm-bearing__2__1"/>
      <child link="${prefix}_elbow-rear-hanger__1__1"/>
      <axis xyz="0.0 0.0 1.0"/>
      <limit upper="${PI}" lower="${-PI}" velocity="10.0" effort="10.0"/>
    </joint>
    
    <joint name="${prefix}_Revolute42" type="revolute">
      <origin xyz="0.0 0.0 ${sign*0.0}" rpy="0 0 0"/>
      <parent link="${prefix}_6mm-bearing__6__1"/>
      <child link="${prefix}_elbow-rear-hanger_1"/>
      <axis xyz="0.0 0.0 -1.0"/>
      <limit upper="${PI}" lower="${-PI}" velocity="10.0" effort="10.0"/>
    </joint>
    
    <joint name="${prefix}_Revolute44" type="revolute">
      <origin xyz="-0.064043 -0.029 ${sign*0.029}" rpy="0 0 0"/>
      <parent link="${prefix}_straight-tendon_1"/>
      <child link="${prefix}_6mm-bearing__4__1"/>
      <axis xyz="0.0 0.0 1.0"/>
      <limit upper="${PI}" lower="${-PI}" velocity="10.0" effort="10.0"/>
    </joint>
    
    <joint name="${prefix}_Rigid45" type="fixed">
      <origin xyz="0.0 0.0 ${sign*0.0}" rpy="0 0 0"/>
      <parent link="${prefix}_6mm-bearing__4__1"/>
      <child link="${prefix}_forearm-elbow-motor-bracket-inner2_1"/>
    </joint>
    
    <joint name="${prefix}_Rigid46" type="fixed">
      <origin xyz="0.033041 0.0 ${sign*0.0}" rpy="0 0 0"/>
      <parent link="${prefix}_forearm-elbow-motor-bracket-inner2_1"/>
      <child link="${prefix}_6mm-bearing__3__1"/>
    </joint>

    <gazebo>
      <plugin name="gazebo_ros" filename="libgazebo_ros_api_plugin.so"/>
      <joint name="${prefix}_Revolute 47 gz" type="revolute">
        <pose relative_to="${prefix}_elbow-rear-hanger__1__1">0.052 0.029 0 0 0 0</pose>
        <parent>${prefix}_elbow-rear-hanger__1__1</parent>
        <child>${prefix}_6mm-bearing__3__1</child>
  
        <axis>
          <xyz> 0 0 1</xyz>
        </axis>
        <limit>
          <lower>${-PI}</lower>
          <upper>${PI}</upper>
          <effort>10.0</effort>
          <velocity>10.0</velocity>
        </limit>
        <dynamics>
          <damping>0.0</damping>
          <friction>0.0</friction>
        </dynamics>
  
      </joint>
    </gazebo>
    
    <joint name="${prefix}_Rigid48" type="fixed">
      <origin xyz="0.0 0.005 ${sign*-0.005}" rpy="0 0 0"/>
      <parent link="${prefix}_6mm-bearing__3__1"/>
      <child link="${prefix}_elbow-bridge-rear_1"/>
    </joint>
    
    <joint name="${prefix}_Rigid49" type="fixed">
      <origin xyz="0.043035 -0.0115 ${sign*0.0115}" rpy="0 0 0"/>
      <parent link="${prefix}_forearm-elbow-motor-bracket-inner2_1"/>
      <child link="${prefix}_second-forearm-motor-strap_1"/>
    </joint>
    
    <joint name="${prefix}_Rigid50" type="fixed">
      <origin xyz="-0.009216 -0.000945 ${sign*0.000944}" rpy="0 0 0"/>
      <parent link="${prefix}_second-forearm-motor-strap_1"/>
      <child link="${prefix}_RMD-X8-Pro_MIR8_MIR1__4__1"/>
    </joint>
    
    <joint name="${prefix}_Rigid51" type="fixed">
      <origin xyz="0.020987 0.064632 ${sign*-0.064631}" rpy="0 0 0"/>
      <parent link="${prefix}_RMD-X8-Pro_MIR8_MIR1__4__1"/>
      <child link="${prefix}_fore-arm-bicep-motor-attatch_1"/>
    </joint>
    
    <joint name="${prefix}_Rigid52" type="fixed">
      <origin xyz="-0.011772 -0.006687 ${sign*0.006687}" rpy="0 0 0"/>
      <parent link="${prefix}_fore-arm-bicep-motor-attatch_1"/>
      <child link="${prefix}_forearm-elbow-motor-bracket-inner_1"/>
    </joint>
    
    <joint name="${prefix}_Rigid53" type="fixed">
      <origin xyz="-0.009994 -0.0115 ${sign*0.0115}" rpy="0 0 0"/>
      <parent link="${prefix}_forearm-elbow-motor-bracket-inner_1"/>
      <child link="${prefix}_6mm-bearing__8__1"/>
    </joint>

    <gazebo>
      <plugin name="gazebo_ros" filename="libgazebo_ros_api_plugin.so"/>
      <joint name="${prefix}_Revolute 54 gz" type="revolute">
        <pose relative_to="${prefix}_elbow-rear-hanger_1">0.052 0.029 0 0 0 0</pose>
        <parent>${prefix}_elbow-rear-hanger_1</parent>
        <child>${prefix}_6mm-bearing__8__1</child>
  
        <axis>
          <xyz> 0 0 1</xyz>
        </axis>
        <limit>
          <lower>${-PI}</lower>
          <upper>${PI}</upper>
          <effort>10.0</effort>
          <velocity>10.0</velocity>
        </limit>
        <dynamics>
          <damping>0.0</damping>
          <friction>0.0</friction>
        </dynamics>
  
      </joint>
    </gazebo>
    
    <joint name="${prefix}_wrist_roll" type="revolute">
      <origin xyz="-0.011699 0.039945 ${sign*-0.039944}" rpy="0 0 0"/>
      <parent link="${prefix}_RMD-X8-Pro_MIR8_MIR1__4__1"/>
      <child link="${prefix}_shoulder-ex-al-interface_1"/>
      <axis xyz="0.951172 0.308661 0.0"/>
      <limit upper="${PI}" lower="${-PI}" velocity="10.0" effort="10.0"/>
    </joint>
    
    <joint name="${prefix}_Rigid56" type="fixed">
      <origin xyz="0.009597 0.015588 ${sign*-0.015588}" rpy="0 0 0"/>
      <parent link="${prefix}_shoulder-ex-al-interface_1"/>
      <child link="${prefix}_shoulder-roll-al-mot_MIR1__3__1"/>
    </joint>
    
    <joint name="${prefix}_Rigid57" type="fixed">
      <origin xyz="0.009597 -0.015589 ${sign*0.015589}" rpy="0 0 0"/>
      <parent link="${prefix}_shoulder-ex-al-interface_1"/>
      <child link="${prefix}_shoulder-roll-al-mot_MIR1_1"/>
    </joint>
    
    <joint name="${prefix}_Rigid58" type="fixed">
      <origin xyz="0.000602 0.0 ${sign*0.0}" rpy="0 0 0"/>
      <parent link="${prefix}_shoulder-ex-al-interface_1"/>
      <child link="${prefix}_2020_100mm__10__1"/>
    </joint>
    
    <joint name="${prefix}_Rigid59" type="fixed">
      <origin xyz="0.0 0.0 ${sign*0.0}" rpy="0 0 0"/>
      <parent link="${prefix}_2020_100mm__10__1"/>
      <child link="${prefix}_top-bracket-servo-strap_1"/>
    </joint>
    
    <joint name="${prefix}_Rigid60" type="fixed">
      <origin xyz="0.020861 0.01515 ${sign*-0.01515}" rpy="0 0 0"/>
      <parent link="${prefix}_top-bracket-servo-strap_1"/>
      <child link="${prefix}_MG995_1"/>
    </joint>
    
    <joint name="${prefix}_Rigid61" type="fixed">
      <origin xyz="-0.013869 0.0196 ${sign*-0.0196}" rpy="0 0 0"/>
      <parent link="${prefix}_top-bracket-servo-strap_1"/>
      <child link="${prefix}_MG995__4__1"/>
    </joint>
    
    <joint name="${prefix}_Rigid62" type="fixed">
      <origin xyz="-0.018316 -0.01515 ${sign*0.01515}" rpy="0 0 0"/>
      <parent link="${prefix}_top-bracket-servo-strap_1"/>
      <child link="${prefix}_MG995__3__1"/>
    </joint>
    
    <joint name="${prefix}_Rigid63" type="fixed">
      <origin xyz="0.016413 -0.0196 ${sign*0.0196}" rpy="0 0 0"/>
      <parent link="${prefix}_top-bracket-servo-strap_1"/>
      <child link="${prefix}_MG995__5__1"/>
    </joint>
    
    <joint name="${prefix}_Rigid64" type="fixed">
      <origin xyz="0.0 0.0 ${sign*0.0}" rpy="0 0 0"/>
      <parent link="${prefix}_2020_100mm__10__1"/>
      <child link="${prefix}_2020_100mm__11__1"/>
    </joint>
    
    <joint name="${prefix}_Rigid65" type="fixed">
      <origin xyz="0.005159 0.0 ${sign*0.0}" rpy="0 0 0"/>
      <parent link="${prefix}_2020_100mm__11__1"/>
      <child link="${prefix}_top-bracket-servo-strap__1__1"/>
    </joint>
    
    <joint name="${prefix}_Rigid66" type="fixed">
      <origin xyz="0.014763 0.0196 ${sign*-0.0196}" rpy="0 0 0"/>
      <parent link="${prefix}_top-bracket-servo-strap__1__1"/>
      <child link="${prefix}_MG995__2__1"/>
    </joint>
    
    <joint name="${prefix}_Rigid67" type="fixed">
      <origin xyz="-0.019967 0.01515 ${sign*-0.01515}" rpy="0 0 0"/>
      <parent link="${prefix}_top-bracket-servo-strap__1__1"/>
      <child link="${prefix}_MG995__6__1"/>
    </joint>
    
    <joint name="${prefix}_Rigid68" type="fixed">
      <origin xyz="-0.01552 -0.0196 ${sign*0.0196}" rpy="0 0 0"/>
      <parent link="${prefix}_top-bracket-servo-strap__1__1"/>
      <child link="${prefix}_MG995__1__1"/>
    </joint>
    
    <joint name="${prefix}_Rigid69" type="fixed">
      <origin xyz="0.01921 -0.01515 ${sign*0.01515}" rpy="0 0 0"/>
      <parent link="${prefix}_top-bracket-servo-strap__1__1"/>
      <child link="${prefix}_MG995__7__1"/>
    </joint>
    
    <joint name="${prefix}_Rigid70" type="fixed">
      <origin xyz="-0.007647 -0.011 ${sign*0.011}" rpy="0 0 0"/>
      <parent link="${prefix}_bicep-shoulder-bracket-exal__1__1"/>
      <child link="${prefix}_multiplex-stack-flat_1"/>
    </joint>
    
  </xacro:macro>

</robot>
